Workbook

Sheet DUOS Ex GST
A1: Schedule of Distribution Use of System (DUOS) Tariffs: 1 January 2015 (GST Exclusive)
D3: Network Tariff Component | O3: Eligibility (consumption/ category) | Q3: Minimum Chargeable Rolling Demand | R3: Minimum Chargeable Demand
A4: Description | B4: Tariff Code | C4: PFIT (F) TFIT (T) | D4: Standing Charge (c/day) | E4: Summer Peak Energy (c/kWh) | F4: Non Summer Peak Energy Block 1 (c/kWh) | G4: Non Summer Peak Energy Block 2 (c/kWh) | H4: Summer Shoulder Energy (c/kWh) | I4: Non Summer Shoulder Energy (c/kWh) | J4: Off Peak Energy (c/kWh) | K4: Rolling Peak Demand c/kVA/day | L4: Summer Demand Incentive Charge c/kW/day or c/kVA/day | M4: Summer Demand Max KW c/KW/day | N4: Non-summer Demand Max KW c/KW/day | O4: kVA | P4: MWh pa | Q4: kVA | R4: KW
A5: Low voltage small 1 rate | B5: LVS1R | C5: F,T | D5: 6.682 | E5: 8.24 | F5: 5.304 | G5: 0 | H5: 0 | I5: 0 | J5: 0 | K5: 0 | L5: 0 | M5: 0 | N5: 0 | O5: NA | P5: <20
A6: Low voltage small 2 rate* | B6: LVS2R* | D6: 13.831 | E6: 9.926 | F6: 7.529 | G6: 0 | H6: 0 | I6: 0 | J6: 1.721 | K6: 0 | L6: 0 | M6: 0 | N6: 0
A7: Dedicated circuit | B7: LVDed | D7: 0 | E7: 0 | F7: 0 | G7: 0 | H7: 0 | I7: 0 | J7: 1.593 | K7: 0 | L7: 0 | M7: 0 | N7: 0 | O7: NA | P7: <20 (on LVS1R)
A8: Unmetered supplies | B8: UnMet | D8: 0 | E8: 8.344 | F8: 6.104 | G8: 0 | H8: 0 | I8: 0 | J8: 1.505 | K8: 0 | L8: 0 | M8: 0 | N8: 0
A9: Winter Energy Tariff* | B9: WET2Step* | D9: 8.721 | E9: 6.504 | F9: 4.819 | G9: 1.806 | H9: 0 | I9: 0 | J9: 0 | K9: 0 | L9: 0 | M9: 0 | N9: 0
A10: Reverse cycle airconditioning time of use* | B10: RCACkWTOU* | D10: 0 | E10: 5.652 | F10: 1.421 | G10: 0 | H10: 0 | I10: 0 | J10: 1.396 | K10: 0 | L10: 71.021 | M10: 0 | N10: 0
A11: Low voltage medium 1 rate | B11: LVM1R | C11: F,T | D11: 12.945 | E11: 11.379 | F11: 7.099 | G11: 0 | H11: 0 | I11: 0 | J11: 0 | K11: 0 | L11: 0 | M11: 0 | N11: 0 | O11: NA | P11: >20 & <400
A12: Low voltage medium 2 rate 5 day* | B12: LVM2R5D* | D12: 18.587 | E12: 9.026 | F12: 6.764 | G12: 0 | H12: 0 | I12: 0 | J12: 1.685 | K12: 0 | L12: 0 | M12: 0 | N12: 0
A13: Low voltage medium 2 rate 7 day* | B13: LVM2R7D* | D13: 19.963 | E13: 8.667 | F13: 6.711 | G13: 0 | H13: 0 | I13: 0 | J13: 1.581 | K13: 0 | L13: 0 | M13: 0 | N13: 0
A14: Low voltage KW time of use* | B14: LVkWTOU* | D14: 0 | E14: 8.318 | F14: 4.874 | G14: 0 | H14: 0 | I14: 0 | J14: 1.937 | K14: 0 | L14: 39.829 | M14: 0 | N14: 0
A15: Low voltage KW time of use - HOT | B15: LVkWTOUH* | D15: 0 | E15: 7.448 | F15: 5.726 | G15: 0 | H15: 0 | I15: 0 | J15: 1.683 | K15: 0 | L15: 65.545 | M15: 0 | N15: 0
A16: Low voltage large 1 rate* | B16: LVL1R* | D16: 12.884 | E16: 5.9 | F16: 4.655 | G16: 0 | H16: 0 | I16: 0 | J16: 0 | K16: 0 | L16: 0 | M16: 0 | N16: 0
A17: Low voltage large 2 rate* | B17: LVL2R* | D17: 18.584 | E17: 9.236 | F17: 7.343 | G17: 0 | H17: 0 | I17: 0 | J17: 1.758 | K17: 0 | L17: 0 | M17: 0 | N17: 0
A18: Low voltage large KVA time of use | B18: LVkVATOU | D18: 0 | E18: 1.329 | F18: 1.126 | G18: 0 | H18: 0 | I18: 0 | J18: 1.114 | K18: 13.408 | L18: 20.001 | M18: 0 | N18: 0 | O18: >150 | P18: >400 | Q18: 150
A19: Low voltage large KVA time of use - HOT* | B19: LVkVATOUH* | D19: 0 | E19: 1.159 | F19: 0.959 | G19: 0 | H19: 0 | I19: 0 | J19: 0.952 | K19: 13.341 | L19: 31.47 | M19: 0 | N19: 0 | Q19: 150
A20: High voltage KVA time of use | B20: HVkVATOU | D20: 0 | E20: 0.8 | F20: 0.707 | G20: 0 | H20: 0 | I20: 0 | J20: 0.695 | K20: 8.156 | L20: 11.2 | M20: 0 | N20: 0 | O20: >150 | P20: >400 | Q20: 1150
A21: High voltage KVA time of use - HOT* | B21: HVkVATOUH* | D21: 0 | E21: 0.828 | F21: 0.685 | G21: 0 | H21: 0 | I21: 0 | J21: 0.677 | K21: 9.406 | L21: 22.777 | M21: 0 | N21: 0 | Q21: 1150
A22: Subtransmission KVA time of use* | B22: SubTkVATOU* | D22: 0 | E22: 0.456 | F22: 0.355 | G22: 0 | H22: 0 | I22: 0 | J22: 0.308 | K22: 0.798 | L22: 1.17 | M22: 0 | N22: 0 | Q22: 11100
A23: Time of Day | B23: TOD | C23: F,T | D23: 6.442 | E23: 15.485 | F23: 9.126 | G23: 0 | H23: 4.364 | I23: 3.215 | J23: 2.986 | K23: 0 | L23: 0 | M23: 0 | N23: 0 | O23: NA | P23: <20
A24: Time of Use | B24: TOU | C24: F,T | D24: 0 | E24: 8.538 | F24: 5.187 | G24: 0 | H24: 0 | I24: 0 | J24: 2.505 | K24: 0 | L24: 37.077 | M24: 0 | N24: 0 | O24: NA | P24: >20 & <400
A25: Time of Day 9pm off-peak | B25: TOD9 | C25: F, T | D25: 6.682 | E25: 17.46 | F25: 10.851 | G25: 0 | H25: 5.412 | I25: 4.348 | J25: 4.136 | K25: 0 | L25: 0 | M25: 0 | N25: 0 | O25: NA | P25: <20
A26: Time of Day Flexible | B26: TODFLEX | C26: F,T | D26: 6.682 | E26: 15.948 | F26: 9.155 | G26: 0 | H26: 4.331 | I26: 4.331 | J26: 3.672 | K26: 0 | L26: 0 | M26: 0 | N26: 0 | O26: Residential Customer
A27: Sesonal Demand TOU RES** | B27: LVKWTOURES** | C27: F,T | D27: 0 | E27: 2.5 | F27: 2.5 | G27: 0 | H27: 2.5 | I27: 2.5 | J27: 2.5 | K27: 0 | L27: 0 | M27: 23.34 | N27: 9.21 | O27: Residential Customer | Q27: 1.5 | R27: 1.5
A29: * Tariff closed to premises not already taking supply under this tariff and new connections.
A30: ** LVKWTOURES available from 1st July 2015
A31: Summer peak energy rates apply for period 1st November to 31st March (except TODFLEX which follows daylight savings periods) & LVKWTOURES which apply 1st December to 31st March.
A32: Non-summer peak energy rates apply for period 1st April to 31st October (except TODFLEX which follows non daylight savings periods) & LVKWTOURES which apply from 1st April to 30th November
A33: PFIT (Premium Feed-In Tariff) is defined by an “F” added to the front of an existing distribution tariff ie. FTOD. The PFIT tariffs are closed to new connections.
A34: TFIT (Transitional Feed-In Tariff) is defined by an “T” added to the front of an existing distribution tariff ie. TTOD. The TFIT tariffs are open to new connections that meet the solar criteria.

Sheet TUOS Ex GST
A1: Schedule of Distribution Use of System (TUOS) Tariffs: 1 January 2015 (GST Exclusive)
D3: Network Tariff Component | O3: Eligibility (consumption/ category) | Q3: Minimum Chargeable Rolling Demand | R3: Minimum Chargeable Demand
A4: Description | B4: Tariff Code | C4: PFIT (F) TFIT (T) | D4: Standing Charge (c/day) | E4: Summer Peak Energy (c/kWh) | F4: Non Summer Peak Energy Block 1 (c/kWh) | G4: Non Summer Peak Energy Block 2 (c/kWh) | H4: Summer Shoulder Energy (c/kWh) | I4: Non Summer Shoulder Energy (c/kWh) | J4: Off Peak Energy (c/kWh) | K4: Rolling Peak Demand c/kVA/day | L4: Summer Demand Incentive Charge c/kW/day or c/kVA/day | M4: Summer Demand Max KW c/KW/day | N4: Non-summer Demand Max KW c/KW/day | O4: kVA | P4: MWh pa | Q4: kVA | R4: KW
A5: Low voltage small 1 rate | B5: LVS1R | C5: F,T | D5: 0 | E5: 2.132 | F5: 1.782 | G5: 0 | H5: 0 | I5: 0 | J5: 0 | K5: 0 | L5: 0 | M5: 0 | N5: 0 | O5: NA | P5: <20
A6: Low voltage small 2 rate* | B6: LVS2R* | D6: 0 | E6: 3.58 | F6: 2.865 | G6: 0 | H6: 0 | I6: 0 | J6: 0 | K6: 0 | L6: 0 | M6: 0 | N6: 0
A7: Dedicated circuit | B7: LVDed | D7: 0 | E7: 0 | F7: 0 | G7: 0 | H7: 0 | I7: 0 | J7: 0 | K7: 0 | L7: 0 | M7: 0 | N7: 0 | O7: NA | P7: <20 (on LVS1R)
A8: Unmetered supplies | B8: UnMet | D8: 0 | E8: 3.355 | F8: 2.681 | G8: 0 | H8: 0 | I8: 0 | J8: 0 | K8: 0 | L8: 0 | M8: 0 | N8: 0
A9: Winter Energy Tariff* | B9: WET2Step* | D9: 0 | E9: 2.385 | F9: 1.908 | G9: 1.908 | H9: 0 | I9: 0 | J9: 0 | K9: 0 | L9: 0 | M9: 0 | N9: 0
A10: Reverse cycle airconditioning time of use* | B10: RCACkWTOU* | D10: 0 | E10: 16.163 | F10: 3.599 | G10: 0 | H10: 0 | I10: 0 | J10: 0 | K10: 0 | L10: 10.249 | M10: 0 | N10: 0
A11: Low voltage medium 1 rate | B11: LVM1R | C11: F,T | D11: 0 | E11: 2.53 | F11: 2.021 | G11: 0 | H11: 0 | I11: 0 | J11: 0 | K11: 0 | L11: 0 | M11: 0 | N11: 0 | O11: NA | P11: >20 & <400
A12: Low voltage medium 2 rate 5 day* | B12: LVM2R5D* | D12: 0 | E12: 1.886 | F12: 1.508 | G12: 0 | H12: 0 | I12: 0 | J12: 0 | K12: 0 | L12: 0 | M12: 0 | N12: 0
A13: Low voltage medium 2 rate 7 day* | B13: LVM2R7D* | D13: 0 | E13: 2.506 | F13: 2.007 | G13: 0 | H13: 0 | I13: 0 | J13: 0 | K13: 0 | L13: 0 | M13: 0 | N13: 0
A14: Low voltage KW time of use* | B14: LVkWTOU* | D14: 0 | E14: 1.747 | F14: 1.397 | G14: 0 | H14: 0 | I14: 0 | J14: 0 | K14: 0 | L14: 8.149 | M14: 0 | N14: 0
A15: Low voltage KW time of use - HOT | B15: LVkWTOUH* | D15: 0 | E15: 1.099 | F15: 0.878 | G15: 0 | H15: 0 | I15: 0 | J15: 0 | K15: 0 | L15: 9.849 | M15: 0 | N15: 0
A16: Low voltage large 1 rate* | B16: LVL1R* | D16: 0 | E16: 2.498 | F16: 1.996 | G16: 0 | H16: 0 | I16: 0 | J16: 0 | K16: 0 | L16: 0 | M16: 0 | N16: 0
A17: Low voltage large 2 rate* | B17: LVL2R* | D17: 0 | E17: 1.92 | F17: 1.538 | G17: 0 | H17: 0 | I17: 0 | J17: 0 | K17: 0 | L17: 0 | M17: 0 | N17: 0
A18: Low voltage large KVA time of use | B18: LVkVATOU | D18: 0 | E18: 1.094 | F18: 0.878 | G18: 0 | H18: 0 | I18: 0 | J18: 0 | K18: 4.469 | L18: 6.108 | M18: 0 | N18: 0 | O18: >150 | P18: >400 | Q18: 150
A19: Low voltage large KVA time of use - HOT* | B19: LVkVATOUH* | D19: 0 | E19: 0.691 | F19: 0.554 | G19: 0 | H19: 0 | I19: 0 | J19: 0 | K19: 2.82 | L19: 7.415 | M19: 0 | N19: 0 | Q19: 150
A20: High voltage KVA time of use | B20: HVkVATOU | D20: 0 | E20: 0.769 | F20: 0.616 | G20: 0 | H20: 0 | I20: 0 | J20: 0 | K20: 5.117 | L20: 5.372 | M20: 0 | N20: 0 | O20: >150 | P20: >400 | Q20: 1150
A21: High voltage KVA time of use - HOT* | B21: HVkVATOUH* | D21: 0 | E21: 0.442 | F21: 0.352 | G21: 0 | H21: 0 | I21: 0 | J21: 0 | K21: 2.934 | L21: 5.923 | M21: 0 | N21: 0 | Q21: 1150
A22: Subtransmission KVA time of use* | B22: SubTkVATOU* | D22: 0 | E22: 0.519 | F22: 0.418 | G22: 0 | H22: 0 | I22: 0 | J22: 0 | K22: 3.679 | L22: 4.463 | M22: 0 | N22: 0 | Q22: 11100
A23: Time of Day | B23: TOD | C23: F,T | D23: 0 | E23: 2.193 | F23: 1.862 | G23: 0 | H23: 1.862 | I23: 1.644 | J23: 0 | K23: 0 | L23: 0 | M23: 0 | N23: 0 | O23: NA | P23: <20
A24: Time of Use | B24: TOU | C24: F,T | D24: 0 | E24: 2.231 | F24: 1.025 | G24: 0 | H24: 0 | I24: 0 | J24: 0 | K24: 0 | L24: 5.845 | M24: 0 | N24: 0 | O24: NA | P24: >20 & <400
A25: Time of Day 9pm off-peak | B25: TOD9 | C25: F, T | D25: 0 | E25: 4.634 | F25: 4.308 | G25: 0 | H25: 4.308 | I25: 4.094 | J25: 0 | K25: 0 | L25: 0 | M25: 0 | N25: 0 | O25: NA | P25: <20
A26: Time of Day Flexible | B26: TODFLEX | C26: F,T | D26: 0 | E26: 3.918 | F26: 3.655 | G26: 0 | H26: 1.958 | I26: 1.728 | J26: 0 | K26: 0 | L26: 0 | M26: 0 | N26: 0 | O26: Residential Customer
A27: Sesonal Demand TOU RES** | B27: LVKWTOURES | C27: F,T | D27: 0 | E27: 1.5 | F27: 1.5 | G27: 0 | H27: 0 | I27: 0 | J27: 0 | K27: 0 | L27: 0 | M27: 7.0821496 | N27: 7.038 | O27: Residential Customer | Q27: 1.5 | R27: 1.5
A29: * Tariff closed to premises not already taking supply under this tariff and new connections.
A30: ** LVKWTOURES available from 1st July 2015
A31: Summer peak energy rates apply for period 1st November to 31st March (except TODFLEX which follows daylight savings periods) & LVKWTOURES which apply 1st December to 31st March.
A32: Non-summer peak energy rates apply for period 1st April to 31st October (except TODFLEX which follows non daylight savings periods) & LVKWTOURES which apply from 1st April to 30th November
A33: PFIT (Premium Feed-In Tariff) is defined by an “F” added to the front of an existing distribution tariff ie. FTOD. The PFIT tariffs are closed to new connections.
A34: TFIT (Transitional Feed-In Tariff) is defined by an “T” added to the front of an existing distribution tariff ie. TTOD. The TFIT tariffs are open to new connections that meet the solar criteria.

Sheet NUOS Ex GST
A1: Schedule of Distribution Use of System (NUOS) Tariffs: 1 January 2015 (GST Exclusive)
D3: Network Tariff Component | O3: Eligibility (consumption/ category) | Q3: Minimum Chargeable Rolling Demand | R3: Minimum Chargeable Demand
A4: Description | B4: Tariff Code | C4: PFIT (F) TFIT (T) | D4: Standing Charge (c/day) | E4: Summer Peak Energy (c/kWh) | F4: Non Summer Peak Energy Block 1 (c/kWh) | G4: Non Summer Peak Energy Block 2 (c/kWh) | H4: Summer Shoulder Energy (c/kWh) | I4: Non Summer Shoulder Energy (c/kWh) | J4: Off Peak Energy (c/kWh) | K4: Rolling Peak Demand c/kVA/day | L4: Summer Demand Incentive Charge c/kW/day or c/kVA/day | M4: Summer Demand Max KW c/KW/day | N4: Non-summer Demand Max KW c/KW/day | O4: kVA | P4: MWh pa | Q4: kVA | R4: KW
A5: Low voltage small 1 rate | B5: LVS1R | C5: F,T | D5: =ROUND(+'DUOS Ex GST'!D5+'TUOS Ex GST'!D5,3) -> 6.682 | E5: =ROUND(+'DUOS Ex GST'!E5+'TUOS Ex GST'!E5,3) -> 10.372 | F5: =ROUND(+'DUOS Ex GST'!F5+'TUOS Ex GST'!F5,3) -> 7.086 | G5: =ROUND(+'DUOS Ex GST'!G5+'TUOS Ex GST'!G5,3) -> 0 | H5: =ROUND(+'DUOS Ex GST'!H5+'TUOS Ex GST'!H5,3) -> 0 | I5: =ROUND(+'DUOS Ex GST'!I5+'TUOS Ex GST'!I5,3) -> 0 | J5: =ROUND(+'DUOS Ex GST'!J5+'TUOS Ex GST'!J5,3) -> 0 | K5: =ROUND(+'DUOS Ex GST'!K5+'TUOS Ex GST'!K5,3) -> 0 | L5: =ROUND(+'DUOS Ex GST'!L5+'TUOS Ex GST'!L5,3) -> 0 | O5: NA | P5: <20
A6: Low voltage small 2 rate* | B6: LVS2R* | D6: =ROUND(+'DUOS Ex GST'!D6+'TUOS Ex GST'!D6,3) -> 13.831 | E6: =ROUND(+'DUOS Ex GST'!E6+'TUOS Ex GST'!E6,3) -> 13.506 | F6: =ROUND(+'DUOS Ex GST'!F6+'TUOS Ex GST'!F6,3) -> 10.394 | G6: =ROUND(+'DUOS Ex GST'!G6+'TUOS Ex GST'!G6,3) -> 0 | H6: =ROUND(+'DUOS Ex GST'!H6+'TUOS Ex GST'!H6,3) -> 0 | I6: =ROUND(+'DUOS Ex GST'!I6+'TUOS Ex GST'!I6,3) -> 0 | J6: =ROUND(+'DUOS Ex GST'!J6+'TUOS Ex GST'!J6,3) -> 1.721 | K6: =ROUND(+'DUOS Ex GST'!K6+'TUOS Ex GST'!K6,3) -> 0 | L6: =ROUND(+'DUOS Ex GST'!L6+'TUOS Ex GST'!L6,3) -> 0
A7: Dedicated circuit | B7: LVDed | D7: =ROUND(+'DUOS Ex GST'!D7+'TUOS Ex GST'!D7,3) -> 0 | E7: =ROUND(+'DUOS Ex GST'!E7+'TUOS Ex GST'!E7,3) -> 0 | F7: =ROUND(+'DUOS Ex GST'!F7+'TUOS Ex GST'!F7,3) -> 0 | G7: =ROUND(+'DUOS Ex GST'!G7+'TUOS Ex GST'!G7,3) -> 0 | H7: =ROUND(+'DUOS Ex GST'!H7+'TUOS Ex GST'!H7,3) -> 0 | I7: =ROUND(+'DUOS Ex GST'!I7+'TUOS Ex GST'!I7,3) -> 0 | J7: =ROUND(+'DUOS Ex GST'!J7+'TUOS Ex GST'!J7,3) -> 1.593 | K7: =ROUND(+'DUOS Ex GST'!K7+'TUOS Ex GST'!K7,3) -> 0 | L7: =ROUND(+'DUOS Ex GST'!L7+'TUOS Ex GST'!L7,3) -> 0 | O7: NA | P7: <20 (on LVS1R)
A8: Unmetered supplies | B8: UnMet | D8: =ROUND(+'DUOS Ex GST'!D8+'TUOS Ex GST'!D8,3) -> 0 | E8: =ROUND(+'DUOS Ex GST'!E8+'TUOS Ex GST'!E8,3) -> 11.699 | F8: =ROUND(+'DUOS Ex GST'!F8+'TUOS Ex GST'!F8,3) -> 8.785 | G8: =ROUND(+'DUOS Ex GST'!G8+'TUOS Ex GST'!G8,3) -> 0 | H8: =ROUND(+'DUOS Ex GST'!H8+'TUOS Ex GST'!H8,3) -> 0 | I8: =ROUND(+'DUOS Ex GST'!I8+'TUOS Ex GST'!I8,3) -> 0 | J8: =ROUND(+'DUOS Ex GST'!J8+'TUOS Ex GST'!J8,3) -> 1.505 | K8: =ROUND(+'DUOS Ex GST'!K8+'TUOS Ex GST'!K8,3) -> 0 | L8: =ROUND(+'DUOS Ex GST'!L8+'TUOS Ex GST'!L8,3) -> 0
A9: Winter Energy Tariff* | B9: WET2Step* | D9: =ROUND(+'DUOS Ex GST'!D9+'TUOS Ex GST'!D9,3) -> 8.721 | E9: =ROUND(+'DUOS Ex GST'!E9+'TUOS Ex GST'!E9,3) -> 8.889 | F9: =ROUND(+'DUOS Ex GST'!F9+'TUOS Ex GST'!F9,3) -> 6.727 | G9: =ROUND(+'DUOS Ex GST'!G9+'TUOS Ex GST'!G9,3) -> 3.714 | H9: =ROUND(+'DUOS Ex GST'!H9+'TUOS Ex GST'!H9,3) -> 0 | I9: =ROUND(+'DUOS Ex GST'!I9+'TUOS Ex GST'!I9,3) -> 0 | J9: =ROUND(+'DUOS Ex GST'!J9+'TUOS Ex GST'!J9,3) -> 0 | K9: =ROUND(+'DUOS Ex GST'!K9+'TUOS Ex GST'!K9,3) -> 0 | L9: =ROUND(+'DUOS Ex GST'!L9+'TUOS Ex GST'!L9,3) -> 0
A10: Reverse cycle airconditioning time of use* | B10: RCACkWTOU* | D10: =ROUND(+'DUOS Ex GST'!D10+'TUOS Ex GST'!D10,3) -> 0 | E10: =ROUND(+'DUOS Ex GST'!E10+'TUOS Ex GST'!E10,3) -> 21.815 | F10: =ROUND(+'DUOS Ex GST'!F10+'TUOS Ex GST'!F10,3) -> 5.02 | G10: =ROUND(+'DUOS Ex GST'!G10+'TUOS Ex GST'!G10,3) -> 0 | H10: =ROUND(+'DUOS Ex GST'!H10+'TUOS Ex GST'!H10,3) -> 0 | I10: =ROUND(+'DUOS Ex GST'!I10+'TUOS Ex GST'!I10,3) -> 0 | J10: =ROUND(+'DUOS Ex GST'!J10+'TUOS Ex GST'!J10,3) -> 1.396 | K10: =ROUND(+'DUOS Ex GST'!K10+'TUOS Ex GST'!K10,3) -> 0 | L10: =ROUND(+'DUOS Ex GST'!L10+'TUOS Ex GST'!L10,3) -> 81.27
A11: Low voltage medium 1 rate | B11: LVM1R | C11: F,T | D11: =ROUND(+'DUOS Ex GST'!D11+'TUOS Ex GST'!D11,3) -> 12.945 | E11: =ROUND(+'DUOS Ex GST'!E11+'TUOS Ex GST'!E11,3) -> 13.909 | F11: =ROUND(+'DUOS Ex GST'!F11+'TUOS Ex GST'!F11,3) -> 9.12 | G11: =ROUND(+'DUOS Ex GST'!G11+'TUOS Ex GST'!G11,3) -> 0 | H11: =ROUND(+'DUOS Ex GST'!H11+'TUOS Ex GST'!H11,3) -> 0 | I11: =ROUND(+'DUOS Ex GST'!I11+'TUOS Ex GST'!I11,3) -> 0 | J11: =ROUND(+'DUOS Ex GST'!J11+'TUOS Ex GST'!J11,3) -> 0 | K11: =ROUND(+'DUOS Ex GST'!K11+'TUOS Ex GST'!K11,3) -> 0 | L11: =ROUND(+'DUOS Ex GST'!L11+'TUOS Ex GST'!L11,3) -> 0 | O11: NA | P11: >20 & <400
A12: Low voltage medium 2 rate 5 day* | B12: LVM2R5D* | D12: =ROUND(+'DUOS Ex GST'!D12+'TUOS Ex GST'!D12,3) -> 18.587 | E12: =ROUND(+'DUOS Ex GST'!E12+'TUOS Ex GST'!E12,3) -> 10.912 | F12: =ROUND(+'DUOS Ex GST'!F12+'TUOS Ex GST'!F12,3) -> 8.272 | G12: =ROUND(+'DUOS Ex GST'!G12+'TUOS Ex GST'!G12,3) -> 0 | H12: =ROUND(+'DUOS Ex GST'!H12+'TUOS Ex GST'!H12,3) -> 0 | I12: =ROUND(+'DUOS Ex GST'!I12+'TUOS Ex GST'!I12,3) -> 0 | J12: =ROUND(+'DUOS Ex GST'!J12+'TUOS Ex GST'!J12,3) -> 1.685 | K12: =ROUND(+'DUOS Ex GST'!K12+'TUOS Ex GST'!K12,3) -> 0 | L12: =ROUND(+'DUOS Ex GST'!L12+'TUOS Ex GST'!L12,3) -> 0
A13: Low voltage medium 2 rate 7 day* | B13: LVM2R7D* | D13: =ROUND(+'DUOS Ex GST'!D13+'TUOS Ex GST'!D13,3) -> 19.963 | E13: =ROUND(+'DUOS Ex GST'!E13+'TUOS Ex GST'!E13,3) -> 11.173 | F13: =ROUND(+'DUOS Ex GST'!F13+'TUOS Ex GST'!F13,3) -> 8.718 | G13: =ROUND(+'DUOS Ex GST'!G13+'TUOS Ex GST'!G13,3) -> 0 | H13: =ROUND(+'DUOS Ex GST'!H13+'TUOS Ex GST'!H13,3) -> 0 | I13: =ROUND(+'DUOS Ex GST'!I13+'TUOS Ex GST'!I13,3) -> 0 | J13: =ROUND(+'DUOS Ex GST'!J13+'TUOS Ex GST'!J13,3) -> 1.581 | K13: =ROUND(+'DUOS Ex GST'!K13+'TUOS Ex GST'!K13,3) -> 0 | L13: =ROUND(+'DUOS Ex GST'!L13+'TUOS Ex GST'!L13,3) -> 0
A14: Low voltage KW time of use* | B14: LVkWTOU* | D14: =ROUND(+'DUOS Ex GST'!D14+'TUOS Ex GST'!D14,3) -> 0 | E14: =ROUND(+'DUOS Ex GST'!E14+'TUOS Ex GST'!E14,3) -> 10.065 | F14: =ROUND(+'DUOS Ex GST'!F14+'TUOS Ex GST'!F14,3) -> 6.271 | G14: =ROUND(+'DUOS Ex GST'!G14+'TUOS Ex GST'!G14,3) -> 0 | H14: =ROUND(+'DUOS Ex GST'!H14+'TUOS Ex GST'!H14,3) -> 0 | I14: =ROUND(+'DUOS Ex GST'!I14+'TUOS Ex GST'!I14,3) -> 0 | J14: =ROUND(+'DUOS Ex GST'!J14+'TUOS Ex GST'!J14,3) -> 1.937 | K14: =ROUND(+'DUOS Ex GST'!K14+'TUOS Ex GST'!K14,3) -> 0 | L14: =ROUND(+'DUOS Ex GST'!L14+'TUOS Ex GST'!L14,3) -> 47.978
A15: Low voltage KW time of use - HOT | B15: LVkWTOUH* | D15: =ROUND(+'DUOS Ex GST'!D15+'TUOS Ex GST'!D15,3) -> 0 | E15: =ROUND(+'DUOS Ex GST'!E15+'TUOS Ex GST'!E15,3) -> 8.547 | F15: =ROUND(+'DUOS Ex GST'!F15+'TUOS Ex GST'!F15,3) -> 6.604 | G15: =ROUND(+'DUOS Ex GST'!G15+'TUOS Ex GST'!G15,3) -> 0 | H15: =ROUND(+'DUOS Ex GST'!H15+'TUOS Ex GST'!H15,3) -> 0 | I15: =ROUND(+'DUOS Ex GST'!I15+'TUOS Ex GST'!I15,3) -> 0 | J15: =ROUND(+'DUOS Ex GST'!J15+'TUOS Ex GST'!J15,3) -> 1.683 | K15: =ROUND(+'DUOS Ex GST'!K15+'TUOS Ex GST'!K15,3) -> 0 | L15: =ROUND(+'DUOS Ex GST'!L15+'TUOS Ex GST'!L15,3) -> 75.394
A16: Low voltage large 1 rate* | B16: LVL1R* | D16: =ROUND(+'DUOS Ex GST'!D16+'TUOS Ex GST'!D16,3) -> 12.884 | E16: =ROUND(+'DUOS Ex GST'!E16+'TUOS Ex GST'!E16,3) -> 8.398 | F16: =ROUND(+'DUOS Ex GST'!F16+'TUOS Ex GST'!F16,3) -> 6.651 | G16: =ROUND(+'DUOS Ex GST'!G16+'TUOS Ex GST'!G16,3) -> 0 | H16: =ROUND(+'DUOS Ex GST'!H16+'TUOS Ex GST'!H16,3) -> 0 | I16: =ROUND(+'DUOS Ex GST'!I16+'TUOS Ex GST'!I16,3) -> 0 | J16: =ROUND(+'DUOS Ex GST'!J16+'TUOS Ex GST'!J16,3) -> 0 | K16: =ROUND(+'DUOS Ex GST'!K16+'TUOS Ex GST'!K16,3) -> 0 | L16: =ROUND(+'DUOS Ex GST'!L16+'TUOS Ex GST'!L16,3) -> 0
A17: Low voltage large 2 rate* | B17: LVL2R* | D17: =ROUND(+'DUOS Ex GST'!D17+'TUOS Ex GST'!D17,3) -> 18.584 | E17: =ROUND(+'DUOS Ex GST'!E17+'TUOS Ex GST'!E17,3) -> 11.156 | F17: =ROUND(+'DUOS Ex GST'!F17+'TUOS Ex GST'!F17,3) -> 8.881 | G17: =ROUND(+'DUOS Ex GST'!G17+'TUOS Ex GST'!G17,3) -> 0 | H17: =ROUND(+'DUOS Ex GST'!H17+'TUOS Ex GST'!H17,3) -> 0 | I17: =ROUND(+'DUOS Ex GST'!I17+'TUOS Ex GST'!I17,3) -> 0 | J17: =ROUND(+'DUOS Ex GST'!J17+'TUOS Ex GST'!J17,3) -> 1.758 | K17: =ROUND(+'DUOS Ex GST'!K17+'TUOS Ex GST'!K17,3) -> 0 | L17: =ROUND(+'DUOS Ex GST'!L17+'TUOS Ex GST'!L17,3) -> 0
A18: Low voltage large KVA time of use | B18: LVkVATOU | D18: =ROUND(+'DUOS Ex GST'!D18+'TUOS Ex GST'!D18,3) -> 0 | E18: =ROUND(+'DUOS Ex GST'!E18+'TUOS Ex GST'!E18,3) -> 2.423 | F18: =ROUND(+'DUOS Ex GST'!F18+'TUOS Ex GST'!F18,3) -> 2.004 | G18: =ROUND(+'DUOS Ex GST'!G18+'TUOS Ex GST'!G18,3) -> 0 | H18: =ROUND(+'DUOS Ex GST'!H18+'TUOS Ex GST'!H18,3) -> 0 | I18: =ROUND(+'DUOS Ex GST'!I18+'TUOS Ex GST'!I18,3) -> 0 | J18: =ROUND(+'DUOS Ex GST'!J18+'TUOS Ex GST'!J18,3) -> 1.114 | K18: =ROUND(+'DUOS Ex GST'!K18+'TUOS Ex GST'!K18,3) -> 17.877 | L18: =ROUND(+'DUOS Ex GST'!L18+'TUOS Ex GST'!L18,3) -> 26.109 | O18: >150 | P18: >400 | Q18: 150
A19: Low voltage large KVA time of use - HOT* | B19: LVkVATOUH* | D19: =ROUND(+'DUOS Ex GST'!D19+'TUOS Ex GST'!D19,3) -> 0 | E19: =ROUND(+'DUOS Ex GST'!E19+'TUOS Ex GST'!E19,3) -> 1.85 | F19: =ROUND(+'DUOS Ex GST'!F19+'TUOS Ex GST'!F19,3) -> 1.513 | G19: =ROUND(+'DUOS Ex GST'!G19+'TUOS Ex GST'!G19,3) -> 0 | H19: =ROUND(+'DUOS Ex GST'!H19+'TUOS Ex GST'!H19,3) -> 0 | I19: =ROUND(+'DUOS Ex GST'!I19+'TUOS Ex GST'!I19,3) -> 0 | J19: =ROUND(+'DUOS Ex GST'!J19+'TUOS Ex GST'!J19,3) -> 0.952 | K19: =ROUND(+'DUOS Ex GST'!K19+'TUOS Ex GST'!K19,3) -> 16.161 | L19: =ROUND(+'DUOS Ex GST'!L19+'TUOS Ex GST'!L19,3) -> 38.885 | Q19: 150
A20: High voltage KVA time of use | B20: HVkVATOU | D20: =ROUND(+'DUOS Ex GST'!D20+'TUOS Ex GST'!D20,3) -> 0 | E20: =ROUND(+'DUOS Ex GST'!E20+'TUOS Ex GST'!E20,3) -> 1.569 | F20: =ROUND(+'DUOS Ex GST'!F20+'TUOS Ex GST'!F20,3) -> 1.323 | G20: =ROUND(+'DUOS Ex GST'!G20+'TUOS Ex GST'!G20,3) -> 0 | H20: =ROUND(+'DUOS Ex GST'!H20+'TUOS Ex GST'!H20,3) -> 0 | I20: =ROUND(+'DUOS Ex GST'!I20+'TUOS Ex GST'!I20,3) -> 0 | J20: =ROUND(+'DUOS Ex GST'!J20+'TUOS Ex GST'!J20,3) -> 0.695 | K20: =ROUND(+'DUOS Ex GST'!K20+'TUOS Ex GST'!K20,3) -> 13.273 | L20: =ROUND(+'DUOS Ex GST'!L20+'TUOS Ex GST'!L20,3) -> 16.572 | O20: >150 | P20: >400 | Q20: 1150
A21: High voltage KVA time of use - HOT* | B21: HVkVATOUH* | D21: =ROUND(+'DUOS Ex GST'!D21+'TUOS Ex GST'!D21,3) -> 0 | E21: =ROUND(+'DUOS Ex GST'!E21+'TUOS Ex GST'!E21,3) -> 1.27 | F21: =ROUND(+'DUOS Ex GST'!F21+'TUOS Ex GST'!F21,3) -> 1.037 | G21: =ROUND(+'DUOS Ex GST'!G21+'TUOS Ex GST'!G21,3) -> 0 | H21: =ROUND(+'DUOS Ex GST'!H21+'TUOS Ex GST'!H21,3) -> 0 | I21: =ROUND(+'DUOS Ex GST'!I21+'TUOS Ex GST'!I21,3) -> 0 | J21: =ROUND(+'DUOS Ex GST'!J21+'TUOS Ex GST'!J21,3) -> 0.677 | K21: =ROUND(+'DUOS Ex GST'!K21+'TUOS Ex GST'!K21,3) -> 12.34 | L21: =ROUND(+'DUOS Ex GST'!L21+'TUOS Ex GST'!L21,3) -> 28.7 | Q21: 1150
A22: Subtransmission KVA time of use* | B22: SubTkVATOU* | D22: =ROUND(+'DUOS Ex GST'!D22+'TUOS Ex GST'!D22,3) -> 0 | E22: =ROUND(+'DUOS Ex GST'!E22+'TUOS Ex GST'!E22,3) -> 0.975 | F22: =ROUND(+'DUOS Ex GST'!F22+'TUOS Ex GST'!F22,3) -> 0.773 | G22: =ROUND(+'DUOS Ex GST'!G22+'TUOS Ex GST'!G22,3) -> 0 | H22: =ROUND(+'DUOS Ex GST'!H22+'TUOS Ex GST'!H22,3) -> 0 | I22: =ROUND(+'DUOS Ex GST'!I22+'TUOS Ex GST'!I22,3) -> 0 | J22: =ROUND(+'DUOS Ex GST'!J22+'TUOS Ex GST'!J22,3) -> 0.308 | K22: =ROUND(+'DUOS Ex GST'!K22+'TUOS Ex GST'!K22,3) -> 4.477 | L22: =ROUND(+'DUOS Ex GST'!L22+'TUOS Ex GST'!L22,3) -> 5.633 | Q22: 11100
A23: Time of Day | B23: TOD | C23: F,T | D23: =ROUND(+'DUOS Ex GST'!D23+'TUOS Ex GST'!D23,3) -> 6.442 | E23: =ROUND(+'DUOS Ex GST'!E23+'TUOS Ex GST'!E23,3) -> 17.678 | F23: =ROUND(+'DUOS Ex GST'!F23+'TUOS Ex GST'!F23,3) -> 10.988 | G23: =ROUND(+'DUOS Ex GST'!G23+'TUOS Ex GST'!G23,3) -> 0 | H23: =ROUND(+'DUOS Ex GST'!H23+'TUOS Ex GST'!H23,3) -> 6.226 | I23: =ROUND(+'DUOS Ex GST'!I23+'TUOS Ex GST'!I23,3) -> 4.859 | J23: =ROUND(+'DUOS Ex GST'!J23+'TUOS Ex GST'!J23,3) -> 2.986 | K23: =ROUND(+'DUOS Ex GST'!K23+'TUOS Ex GST'!K23,3) -> 0 | L23: =ROUND(+'DUOS Ex GST'!L23+'TUOS Ex GST'!L23,3) -> 0 | O23: NA | P23: <20
A24: Time of Use | B24: TOU | C24: F,T | D24: =ROUND(+'DUOS Ex GST'!D24+'TUOS Ex GST'!D24,3) -> 0 | E24: =ROUND(+'DUOS Ex GST'!E24+'TUOS Ex GST'!E24,3) -> 10.769 | F24: =ROUND(+'DUOS Ex GST'!F24+'TUOS Ex GST'!F24,3) -> 6.212 | G24: =ROUND(+'DUOS Ex GST'!G24+'TUOS Ex GST'!G24,3) -> 0 | H24: =ROUND(+'DUOS Ex GST'!H24+'TUOS Ex GST'!H24,3) -> 0 | I24: =ROUND(+'DUOS Ex GST'!I24+'TUOS Ex GST'!I24,3) -> 0 | J24: =ROUND(+'DUOS Ex GST'!J24+'TUOS Ex GST'!J24,3) -> 2.505 | K24: =ROUND(+'DUOS Ex GST'!K24+'TUOS Ex GST'!K24,3) -> 0 | L24: =ROUND(+'DUOS Ex GST'!L24+'TUOS Ex GST'!L24,3) -> 42.922 | O24: NA | P24: >20 & <400
A25: Time of Day 9pm off-peak | B25: TOD9 | C25: F, T | D25: =ROUND(+'DUOS Ex GST'!D25+'TUOS Ex GST'!D25,3) -> 6.682 | E25: =ROUND(+'DUOS Ex GST'!E25+'TUOS Ex GST'!E25,3) -> 22.094 | F25: =ROUND(+'DUOS Ex GST'!F25+'TUOS Ex GST'!F25,3) -> 15.159 | G25: =ROUND(+'DUOS Ex GST'!G25+'TUOS Ex GST'!G25,3) -> 0 | H25: =ROUND(+'DUOS Ex GST'!H25+'TUOS Ex GST'!H25,3) -> 9.72 | I25: =ROUND(+'DUOS Ex GST'!I25+'TUOS Ex GST'!I25,3) -> 8.442 | J25: =ROUND(+'DUOS Ex GST'!J25+'TUOS Ex GST'!J25,3) -> 4.136 | K25: =ROUND(+'DUOS Ex GST'!K25+'TUOS Ex GST'!K25,3) -> 0 | L25: =ROUND(+'DUOS Ex GST'!L25+'TUOS Ex GST'!L25,3) -> 0 | O25: NA | P25: <20
A26: Time of Day Flexible | B26: TODFLEX | C26: F,T | D26: =ROUND(+'DUOS Ex GST'!D26+'TUOS Ex GST'!D26,3) -> 6.682 | E26: =ROUND(+'DUOS Ex GST'!E26+'TUOS Ex GST'!E26,3) -> 19.866 | F26: =ROUND(+'DUOS Ex GST'!F26+'TUOS Ex GST'!F26,3) -> 12.81 | G26: =ROUND(+'DUOS Ex GST'!G26+'TUOS Ex GST'!G26,3) -> 0 | H26: =ROUND(+'DUOS Ex GST'!H26+'TUOS Ex GST'!H26,3) -> 6.289 | I26: =ROUND(+'DUOS Ex GST'!I26+'TUOS Ex GST'!I26,3) -> 6.059 | J26: =ROUND(+'DUOS Ex GST'!J26+'TUOS Ex GST'!J26,3) -> 3.672 | K26: =ROUND(+'DUOS Ex GST'!K26+'TUOS Ex GST'!K26,3) -> 0 | L26: =ROUND(+'DUOS Ex GST'!L26+'TUOS Ex GST'!L26,3) -> 0 | O26: Residential Customer
A27: Sesonal Demand TOU RES** | B27: LVKWTOURES | C27: F,T | D27: =ROUND(+'DUOS Ex GST'!D27+'TUOS Ex GST'!D27,3) -> 0 | E27: =ROUND(+'DUOS Ex GST'!E27+'TUOS Ex GST'!E27,3) -> 4 | F27: =ROUND(+'DUOS Ex GST'!F27+'TUOS Ex GST'!F27,3) -> 4 | G27: =ROUND(+'DUOS Ex GST'!G27+'TUOS Ex GST'!G27,3) -> 0 | H27: =ROUND(+'DUOS Ex GST'!H27+'TUOS Ex GST'!H27,3) -> 2.5 | I27: =ROUND(+'DUOS Ex GST'!I27+'TUOS Ex GST'!I27,3) -> 2.5 | J27: =ROUND(+'DUOS Ex GST'!J27+'TUOS Ex GST'!J27,3) -> 2.5 | K27: =ROUND(+'DUOS Ex GST'!K27+'TUOS Ex GST'!K27,3) -> 0 | ... N27: =ROUND(+'DUOS Ex GST'!N27+'TUOS Ex GST'!N27,3) -> 16.248 | O27: Residential Customer | Q27: 1.5 | R27: 1.5
A29: * Tariff closed to premises not already taking supply under this tariff and new connections.
A30: ** LVKWTOURES available from 1st July 2015
A31: Summer peak energy rates apply for period 1st November to 31st March (except TODFLEX which follows daylight savings periods) & LVKWTOURES which apply 1st December to 31st March.
A32: Non-summer peak energy rates apply for period 1st April to 31st October (except TODFLEX which follows non daylight savings periods) & LVKWTOURES which apply from 1st April to 30th November
A33: PFIT (Premium Feed-In Tariff) is defined by an “F” added to the front of an existing distribution tariff ie. FTOD. The PFIT tariffs are closed to new connections.
A34: TFIT (Transitional Feed-In Tariff) is defined by an “T” added to the front of an existing distribution tariff ie. TTOD. The TFIT tariffs are open to new connections that meet the solar criteria.

Sheet PFIT TFIT ex GST
A1: UED PFIT/TFIT pass through charge: 1 January 2015 (GST Exclusive)
A2: UED Network Tariff Description | B2: UED Tariff Code | C2: PFIT/TFIT Pass Through Charge (c/cust/day)
A3: Low voltage small 1 rate | B3: LVS1R | C3: 7.2021918
A4: Low voltage small 2 rate* | B4: LVS2R* | C4: =+$C$3 -> 7.2021918
A5: Dedicated circuit** | B5: LVDed**
A6: Unmetered supplies | B6: UnMet
A7: Winter Energy Tariff* | B7: WET2Step* | C7: =+$C$3 -> 7.2021918
A8: Reverse cycle airconditioning time of use* | B8: RCACkWTOU* | C8: =+$C$3 -> 7.2021918
A9: Low voltage medium 1 rate | B9: LVM1R | C9: =+$C$3 -> 7.2021918
A10: Low voltage medium 2 rate 5 day* | B10: LVM2R5D* | C10: =+$C$3 -> 7.2021918
A11: Low voltage medium 2 rate 7 day* | B11: LVM2R7D* | C11: =+$C$3 -> 7.2021918
A12: Low voltage KW time of use* | B12: LVkWTOU* | C12: =+$C$3 -> 7.2021918
A13: Low voltage KW time of use - HOT | B13: LVkWTOUH* | C13: =+$C$3 -> 7.2021918
A14: Low voltage large 1 rate* | B14: LVL1R* | C14: =+$C$3 -> 7.2021918
A15: Low voltage large 2 rate* | B15: LVL2R* | C15: =+$C$3 -> 7.2021918
A16: Low voltage large KVA time of use | B16: LVkVATOU | C16: =+$C$3 -> 7.2021918
A17: Low voltage large KVA time of use - HOT* | B17: LVkVATOUH* | C17: =+$C$3 -> 7.2021918
A18: High voltage KVA time of use | B18: HVkVATOU | C18: =+$C$3 -> 7.2021918
... A25: Sesonal Demand TOU RES | B25: LVKWTOURES | C25: =+$C$3 -> 7.2021918
A27: * Tariff closed to premises not already taking supply under this tariff and new connections.

Sheet Prescribed Ex GST
A1: 2015 Prescribed Metering Service Charges (GST Exclusive)
A4: Metering Data Services (Unmetered Supplies) | B4: $/light/annum
A5: Per light | B5: 1.258

Sheet DUOS GST
A1: Schedule of Distribution Use of System (DUOS) Tariffs: 1 January 2015 (GST Inclusive)
D3: Network Tariff Component | O3: Eligibility (consumption/ category) | Q3: Minimum Chargeable Rolling Demand | R3: Minimum Chargeable Demand
A4: Description | B4: Tariff Code | C4: PFIT (F) TFIT (T) | D4: Standing Charge (c/day) | E4: Summer Peak Energy (c/kWh) | F4: Non Summer Peak Energy Block 1 (c/kWh) | G4: Non Summer Peak Energy Block 2 (c/kWh) | J4: Off Peak Energy (c/kWh) | K4: Rolling Peak Demand c/kVA/day | L4: Summer Demand Incentive Charge c/kW/day or c/kVA/day | M4: Summer Demand Max KW c/KW/day | N4: Non-summer Demand Max KW c/KW/day | O4: kVA | P4: MWh pa | Q4: kVA | R4: KW
A5: Low voltage small 1 rate | B5: LVS1R | C5: F,T | D5: =+ROUND('DUOS Ex GST'!D5*1.1,3) -> 7.35 | E5: =+ROUND('DUOS Ex GST'!E5*1.1,3) -> 9.064 | F5: =+ROUND('DUOS Ex GST'!F5*1.1,3) -> 5.834 | G5: =+ROUND('DUOS Ex GST'!G5*1.1,3) -> 0 | H5: =+ROUND('DUOS Ex GST'!H5*1.1,3) -> 0 | I5: =+ROUND('DUOS Ex GST'!I5*1.1,3) -> 0 | J5: =+ROUND('DUOS Ex GST'!J5*1.1,3) -> 0 | K5: =+ROUND('DUOS Ex GST'!K5*1.1,3) -> 0 | L5: =+ROUND('DUOS Ex GST'!L5*1.1,3) -> 0 | O5: NA | P5: <20
A6: Low voltage small 2 rate* | B6: LVS2R* | D6: =+ROUND('DUOS Ex GST'!D6*1.1,3) -> 15.214 | E6: =+ROUND('DUOS Ex GST'!E6*1.1,3) -> 10.919 | F6: =+ROUND('DUOS Ex GST'!F6*1.1,3) -> 8.282 | G6: =+ROUND('DUOS Ex GST'!G6*1.1,3) -> 0 | H6: =+ROUND('DUOS Ex GST'!H6*1.1,3) -> 0 | I6: =+ROUND('DUOS Ex GST'!I6*1.1,3) -> 0 | J6: =+ROUND('DUOS Ex GST'!J6*1.1,3) -> 1.893 | K6: =+ROUND('DUOS Ex GST'!K6*1.1,3) -> 0 | L6: =+ROUND('DUOS Ex GST'!L6*1.1,3) -> 0
A7: Dedicated circuit** | B7: LVDed** | D7: =+ROUND('DUOS Ex GST'!D7*1.1,3) -> 0 | E7: =+ROUND('DUOS Ex GST'!E7*1.1,3) -> 0 | F7: =+ROUND('DUOS Ex GST'!F7*1.1,3) -> 0 | G7: =+ROUND('DUOS Ex GST'!G7*1.1,3) -> 0 | H7: =+ROUND('DUOS Ex GST'!H7*1.1,3) -> 0 | I7: =+ROUND('DUOS Ex GST'!I7*1.1,3) -> 0 | J7: =+ROUND('DUOS Ex GST'!J7*1.1,3) -> 1.752 | K7: =+ROUND('DUOS Ex GST'!K7*1.1,3) -> 0 | L7: =+ROUND('DUOS Ex GST'!L7*1.1,3) -> 0 | O7: NA | P7: <20 (on LVS1R)
A8: Unmetered supplies | B8: UnMet | D8: =+ROUND('DUOS Ex GST'!D8*1.1,3) -> 0 | E8: =+ROUND('DUOS Ex GST'!E8*1.1,3) -> 9.178 | F8: =+ROUND('DUOS Ex GST'!F8*1.1,3) -> 6.714 | G8: =+ROUND('DUOS Ex GST'!G8*1.1,3) -> 0 | H8: =+ROUND('DUOS Ex GST'!H8*1.1,3) -> 0 | I8: =+ROUND('DUOS Ex GST'!I8*1.1,3) -> 0 | J8: =+ROUND('DUOS Ex GST'!J8*1.1,3) -> 1.656 | K8: =+ROUND('DUOS Ex GST'!K8*1.1,3) -> 0 | L8: =+ROUND('DUOS Ex GST'!L8*1.1,3) -> 0
A9: Winter Energy Tariff* | B9: WET2Step* | D9: =+ROUND('DUOS Ex GST'!D9*1.1,3) -> 9.593 | E9: =+ROUND('DUOS Ex GST'!E9*1.1,3) -> 7.154 | F9: =+ROUND('DUOS Ex GST'!F9*1.1,3) -> 5.301 | G9: =+ROUND('DUOS Ex GST'!G9*1.1,3) -> 1.987 | H9: =+ROUND('DUOS Ex GST'!H9*1.1,3) -> 0 | I9: =+ROUND('DUOS Ex GST'!I9*1.1,3) -> 0 | J9: =+ROUND('DUOS Ex GST'!J9*1.1,3) -> 0 | K9: =+ROUND('DUOS Ex GST'!K9*1.1,3) -> 0 | L9: =+ROUND('DUOS Ex GST'!L9*1.1,3) -> 0
A10: Reverse cycle airconditioning time of use* | B10: RCACkWTOU* | D10: =+ROUND('DUOS Ex GST'!D10*1.1,3) -> 0 | E10: =+ROUND('DUOS Ex GST'!E10*1.1,3) -> 6.217 | F10: =+ROUND('DUOS Ex GST'!F10*1.1,3) -> 1.563 | G10: =+ROUND('DUOS Ex GST'!G10*1.1,3) -> 0 | H10: =+ROUND('DUOS Ex GST'!H10*1.1,3) -> 0 | I10: =+ROUND('DUOS Ex GST'!I10*1.1,3) -> 0 | J10: =+ROUND('DUOS Ex GST'!J10*1.1,3) -> 1.536 | K10: =+ROUND('DUOS Ex GST'!K10*1.1,3) -> 0 | L10: =+ROUND('DUOS Ex GST'!L10*1.1,3) -> 78.123
A11: Low voltage medium 1 rate | B11: LVM1R | C11: F,T | D11: =+ROUND('DUOS Ex GST'!D11*1.1,3) -> 14.24 | E11: =+ROUND('DUOS Ex GST'!E11*1.1,3) -> 12.517 | F11: =+ROUND('DUOS Ex GST'!F11*1.1,3) -> 7.809 | G11: =+ROUND('DUOS Ex GST'!G11*1.1,3) -> 0 | H11: =+ROUND('DUOS Ex GST'!H11*1.1,3) -> 0 | I11: =+ROUND('DUOS Ex GST'!I11*1.1,3) -> 0 | J11: =+ROUND('DUOS Ex GST'!J11*1.1,3) -> 0 | K11: =+ROUND('DUOS Ex GST'!K11*1.1,3) -> 0 | L11: =+ROUND('DUOS Ex GST'!L11*1.1,3) -> 0 | O11: NA | P11: >20 & <400
A12: Low voltage medium 2 rate 5 day* | B12: LVM2R5D* | D12: =+ROUND('DUOS Ex GST'!D12*1.1,3) -> 20.446 | E12: =+ROUND('DUOS Ex GST'!E12*1.1,3) -> 9.929 | F12: =+ROUND('DUOS Ex GST'!F12*1.1,3) -> 7.44 | G12: =+ROUND('DUOS Ex GST'!G12*1.1,3) -> 0 | H12: =+ROUND('DUOS Ex GST'!H12*1.1,3) -> 0 | I12: =+ROUND('DUOS Ex GST'!I12*1.1,3) -> 0 | J12: =+ROUND('DUOS Ex GST'!J12*1.1,3) -> 1.854 | K12: =+ROUND('DUOS Ex GST'!K12*1.1,3) -> 0 | L12: =+ROUND('DUOS Ex GST'!L12*1.1,3) -> 0
A13: Low voltage medium 2 rate 7 day* | B13: LVM2R7D* | D13: =+ROUND('DUOS Ex GST'!D13*1.1,3) -> 21.959 | E13: =+ROUND('DUOS Ex GST'!E13*1.1,3) -> 9.534 | F13: =+ROUND('DUOS Ex GST'!F13*1.1,3) -> 7.382 | G13: =+ROUND('DUOS Ex GST'!G13*1.1,3) -> 0 | H13: =+ROUND('DUOS Ex GST'!H13*1.1,3) -> 0 | I13: =+ROUND('DUOS Ex GST'!I13*1.1,3) -> 0 | J13: =+ROUND('DUOS Ex GST'!J13*1.1,3) -> 1.739 | K13: =+ROUND('DUOS Ex GST'!K13*1.1,3) -> 0 | L13: =+ROUND('DUOS Ex GST'!L13*1.1,3) -> 0
A14: Low voltage KW time of use* | B14: LVkWTOU* | D14: =+ROUND('DUOS Ex GST'!D14*1.1,3) -> 0 | E14: =+ROUND('DUOS Ex GST'!E14*1.1,3) -> 9.15 | F14: =+ROUND('DUOS Ex GST'!F14*1.1,3) -> 5.361 | G14: =+ROUND('DUOS Ex GST'!G14*1.1,3) -> 0 | H14: =+ROUND('DUOS Ex GST'!H14*1.1,3) -> 0 | I14: =+ROUND('DUOS Ex GST'!I14*1.1,3) -> 0 | J14: =+ROUND('DUOS Ex GST'!J14*1.1,3) -> 2.131 | K14: =+ROUND('DUOS Ex GST'!K14*1.1,3) -> 0 | L14: =+ROUND('DUOS Ex GST'!L14*1.1,3) -> 43.812
A15: Low voltage KW time of use - HOT | B15: LVkWTOUH* | D15: =+ROUND('DUOS Ex GST'!D15*1.1,3) -> 0 | E15: =+ROUND('DUOS Ex GST'!E15*1.1,3) -> 8.193 | F15: =+ROUND('DUOS Ex GST'!F15*1.1,3) -> 6.299 | G15: =+ROUND('DUOS Ex GST'!G15*1.1,3) -> 0 | H15: =+ROUND('DUOS Ex GST'!H15*1.1,3) -> 0 | I15: =+ROUND('DUOS Ex GST'!I15*1.1,3) -> 0 | J15: =+ROUND('DUOS Ex GST'!J15*1.1,3) -> 1.851 | K15: =+ROUND('DUOS Ex GST'!K15*1.1,3) -> 0 | L15: =+ROUND('DUOS Ex GST'!L15*1.1,3) -> 72.1
A16: Low voltage large 1 rate* | B16: LVL1R* | D16: =+ROUND('DUOS Ex GST'!D16*1.1,3) -> 14.172 | E16: =+ROUND('DUOS Ex GST'!E16*1.1,3) -> 6.49 | F16: =+ROUND('DUOS Ex GST'!F16*1.1,3) -> 5.121 | G16: =+ROUND('DUOS Ex GST'!G16*1.1,3) -> 0 | H16: =+ROUND('DUOS Ex GST'!H16*1.1,3) -> 0 | I16: =+ROUND('DUOS Ex GST'!I16*1.1,3) -> 0 | J16: =+ROUND('DUOS Ex GST'!J16*1.1,3) -> 0 | K16: =+ROUND('DUOS Ex GST'!K16*1.1,3) -> 0 | L16: =+ROUND('DUOS Ex GST'!L16*1.1,3) -> 0
A17: Low voltage large 2 rate* | B17: LVL2R* | D17: =+ROUND('DUOS Ex GST'!D17*1.1,3) -> 20.442 | E17: =+ROUND('DUOS Ex GST'!E17*1.1,3) -> 10.16 | F17: =+ROUND('DUOS Ex GST'!F17*1.1,3) -> 8.077 | G17: =+ROUND('DUOS Ex GST'!G17*1.1,3) -> 0 | H17: =+ROUND('DUOS Ex GST'!H17*1.1,3) -> 0 | I17: =+ROUND('DUOS Ex GST'!I17*1.1,3) -> 0 | J17: =+ROUND('DUOS Ex GST'!J17*1.1,3) -> 1.934 | K17: =+ROUND('DUOS Ex GST'!K17*1.1,3) -> 0 | L17: =+ROUND('DUOS Ex GST'!L17*1.1,3) -> 0
A18: Low voltage large KVA time of use | B18: LVkVATOU | D18: =+ROUND('DUOS Ex GST'!D18*1.1,3) -> 0 | E18: =+ROUND('DUOS Ex GST'!E18*1.1,3) -> 1.462 | F18: =+ROUND('DUOS Ex GST'!F18*1.1,3) -> 1.239 | G18: =+ROUND('DUOS Ex GST'!G18*1.1,3) -> 0 | H18: =+ROUND('DUOS Ex GST'!H18*1.1,3) -> 0 | I18: =+ROUND('DUOS Ex GST'!I18*1.1,3) -> 0 | J18: =+ROUND('DUOS Ex GST'!J18*1.1,3) -> 1.225 | K18: =+ROUND('DUOS Ex GST'!K18*1.1,3) -> 14.749 | L18: =+ROUND('DUOS Ex GST'!L18*1.1,3) -> 22.001 | O18: >150 | P18: >400 | Q18: 150
A19: Low voltage large KVA time of use - HOT* | B19: LVkVATOUH* | D19: =+ROUND('DUOS Ex GST'!D19*1.1,3) -> 0 | E19: =+ROUND('DUOS Ex GST'!E19*1.1,3) -> 1.275 | F19: =+ROUND('DUOS Ex GST'!F19*1.1,3) -> 1.055 | G19: =+ROUND('DUOS Ex GST'!G19*1.1,3) -> 0 | H19: =+ROUND('DUOS Ex GST'!H19*1.1,3) -> 0 | I19: =+ROUND('DUOS Ex GST'!I19*1.1,3) -> 0 | J19: =+ROUND('DUOS Ex GST'!J19*1.1,3) -> 1.047 | K19: =+ROUND('DUOS Ex GST'!K19*1.1,3) -> 14.675 | L19: =+ROUND('DUOS Ex GST'!L19*1.1,3) -> 34.617 | Q19: 150
A20: High voltage KVA time of use | B20: HVkVATOU | D20: =+ROUND('DUOS Ex GST'!D20*1.1,3) -> 0 | E20: =+ROUND('DUOS Ex GST'!E20*1.1,3) -> 0.88 | F20: =+ROUND('DUOS Ex GST'!F20*1.1,3) -> 0.778 | G20: =+ROUND('DUOS Ex GST'!G20*1.1,3) -> 0 | H20: =+ROUND('DUOS Ex GST'!H20*1.1,3) -> 0 | I20: =+ROUND('DUOS Ex GST'!I20*1.1,3) -> 0 | J20: =+ROUND('DUOS Ex GST'!J20*1.1,3) -> 0.765 | K20: =+ROUND('DUOS Ex GST'!K20*1.1,3) -> 8.972 | L20: =+ROUND('DUOS Ex GST'!L20*1.1,3) -> 12.32 | O20: >150 | P20: >400 | Q20: 1150
A21: High voltage KVA time of use - HOT* | B21: HVkVATOUH* | D21: =+ROUND('DUOS Ex GST'!D21*1.1,3) -> 0 | E21: =+ROUND('DUOS Ex GST'!E21*1.1,3) -> 0.911 | F21: =+ROUND('DUOS Ex GST'!F21*1.1,3) -> 0.754 | G21: =+ROUND('DUOS Ex GST'!G21*1.1,3) -> 0 | H21: =+ROUND('DUOS Ex GST'!H21*1.1,3) -> 0 | I21: =+ROUND('DUOS Ex GST'!I21*1.1,3) -> 0 | J21: =+ROUND('DUOS Ex GST'!J21*1.1,3) -> 0.745 | K21: =+ROUND('DUOS Ex GST'!K21*1.1,3) -> 10.347 | L21: =+ROUND('DUOS Ex GST'!L21*1.1,3) -> 25.055 | Q21: 1150
A22: Subtransmission KVA time of use* | B22: SubTkVATOU* | D22: =+ROUND('DUOS Ex GST'!D22*1.1,3) -> 0 | E22: =+ROUND('DUOS Ex GST'!E22*1.1,3) -> 0.502 | F22: =+ROUND('DUOS Ex GST'!F22*1.1,3) -> 0.391 | G22: =+ROUND('DUOS Ex GST'!G22*1.1,3) -> 0 | H22: =+ROUND('DUOS Ex GST'!H22*1.1,3) -> 0 | I22: =+ROUND('DUOS Ex GST'!I22*1.1,3) -> 0 | J22: =+ROUND('DUOS Ex GST'!J22*1.1,3) -> 0.339 | K22: =+ROUND('DUOS Ex GST'!K22*1.1,3) -> 0.878 | L22: =+ROUND('DUOS Ex GST'!L22*1.1,3) -> 1.287 | Q22: 11100
A23: Time of Day | B23: TOD | C23: F,T | D23: =+ROUND('DUOS Ex GST'!D23*1.1,3) -> 7.086 | E23: =+ROUND('DUOS Ex GST'!E23*1.1,3) -> 17.034 | F23: =+ROUND('DUOS Ex GST'!F23*1.1,3) -> 10.039 | G23: =+ROUND('DUOS Ex GST'!G23*1.1,3) -> 0 | H23: =+ROUND('DUOS Ex GST'!H23*1.1,3) -> 4.8 | I23: =+ROUND('DUOS Ex GST'!I23*1.1,3) -> 3.537 | J23: =+ROUND('DUOS Ex GST'!J23*1.1,3) -> 3.285 | K23: =+ROUND('DUOS Ex GST'!K23*1.1,3) -> 0 | L23: =+ROUND('DUOS Ex GST'!L23*1.1,3) -> 0 | O23: NA | P23: <20
A24: Time of Use | B24: TOU | C24: F,T | D24: =+ROUND('DUOS Ex GST'!D24*1.1,3) -> 0 | E24: =+ROUND('DUOS Ex GST'!E24*1.1,3) -> 9.392 | F24: =+ROUND('DUOS Ex GST'!F24*1.1,3) -> 5.706 | G24: =+ROUND('DUOS Ex GST'!G24*1.1,3) -> 0 | H24: =+ROUND('DUOS Ex GST'!H24*1.1,3) -> 0 | I24: =+ROUND('DUOS Ex GST'!I24*1.1,3) -> 0 | J24: =+ROUND('DUOS Ex GST'!J24*1.1,3) -> 2.756 | K24: =+ROUND('DUOS Ex GST'!K24*1.1,3) -> 0 | L24: =+ROUND('DUOS Ex GST'!L24*1.1,3) -> 40.785 | O24: NA | P24: >20 & <400
A25: Time of Day 9pm off-peak | B25: TOD9 | C25: F, T | D25: =+ROUND('DUOS Ex GST'!D25*1.1,3) -> 7.35 | E25: =+ROUND('DUOS Ex GST'!E25*1.1,3) -> 19.206 | F25: =+ROUND('DUOS Ex GST'!F25*1.1,3) -> 11.936 | G25: =+ROUND('DUOS Ex GST'!G25*1.1,3) -> 0 | H25: =+ROUND('DUOS Ex GST'!H25*1.1,3) -> 5.953 | I25: =+ROUND('DUOS Ex GST'!I25*1.1,3) -> 4.783 | J25: =+ROUND('DUOS Ex GST'!J25*1.1,3) -> 4.55 | K25: =+ROUND('DUOS Ex GST'!K25*1.1,3) -> 0 | L25: =+ROUND('DUOS Ex GST'!L25*1.1,3) -> 0 | O25: NA | P25: <20
A26: Time of Day Flexible | B26: TODFLEX | C26: F,T | D26: =+ROUND('DUOS Ex GST'!D26*1.1,3) -> 7.35 | E26: =+ROUND('DUOS Ex GST'!E26*1.1,3) -> 17.543 | F26: =+ROUND('DUOS Ex GST'!F26*1.1,3) -> 10.071 | G26: =+ROUND('DUOS Ex GST'!G26*1.1,3) -> 0 | H26: =+ROUND('DUOS Ex GST'!H26*1.1,3) -> 4.764 | I26: =+ROUND('DUOS Ex GST'!I26*1.1,3) -> 4.764 | J26: =+ROUND('DUOS Ex GST'!J26*1.1,3) -> 4.039 | K26: =+ROUND('DUOS Ex GST'!K26*1.1,3) -> 0 | L26: =+ROUND('DUOS Ex GST'!L26*1.1,3) -> 0 | O26: Residential Customer
A27: Sesonal Demand TOU RES** | B27: LVKWTOURES | C27: F,T | D27: =+ROUND('DUOS Ex GST'!D27*1.1,3) -> 0 | E27: =+ROUND('DUOS Ex GST'!E27*1.1,3) -> 2.75 | F27: =+ROUND('DUOS Ex GST'!F27*1.1,3) -> 2.75 | G27: =+ROUND('DUOS Ex GST'!G27*1.1,3) -> 0 | H27: =+ROUND('DUOS Ex GST'!H27*1.1,3) -> 2.75 | I27: =+ROUND('DUOS Ex GST'!I27*1.1,3) -> 2.75 | J27: =+ROUND('DUOS Ex GST'!J27*1.1,3) -> 2.75 | K27: =+ROUND('DUOS Ex GST'!K27*1.1,3) -> 0 | ... N27: =+ROUND('DUOS Ex GST'!N27*1.1,3) -> 10.131 | O27: Residential Customer | Q27: 1.5 | R27: 1.5
A29: * Tariff closed to premises not already taking supply under this tariff and new connections.
A30: ** LVKWTOURES available from 1st July 2015
A31: Summer peak energy rates apply for period 1st November to 31st March (except TODFLEX which follows daylight savings periods) & LVKWTOURES which apply 1st December to 31st March.
A32: Non-summer peak energy rates apply for period 1st April to 31st October (except TODFLEX which follows non daylight savings periods) & LVKWTOURES which apply from 1st April to 30th November
A33: PFIT (Premium Feed-In Tariff) is defined by an “F” added to the front of an existing distribution tariff ie. FTOD. The PFIT tariffs are closed to new connections.
A34: TFIT (Transitional Feed-In Tariff) is defined by an “T” added to the front of an existing distribution tariff ie. TTOD. The TFIT tariffs are open to new connections that meet the solar criteria.

Sheet TUOS GST
A1: Schedule of Transmission Use of System (TUOS) Tariffs: 1 January 2015 (GST Inclusive)
D3: Network Tariff Component | O3: Eligibility (consumption/ category) | Q3: Minimum Chargeable Rolling Demand | R3: Minimum Chargeable Demand
A4: Description | B4: Tariff Code | C4: PFIT (F) TFIT (T) | D4: Standing Charge (c/day) | E4: Summer Peak Energy (c/kWh) | F4: Non Summer Peak Energy Block 1 (c/kWh) | G4: Non Summer Peak Energy Block 2 (c/kWh) | J4: Off Peak Energy (c/kWh) | K4: Rolling Peak Demand c/kVA/day | L4: Summer Demand Incentive Charge c/kW/day or c/kVA/day | M4: Summer Demand Max KW c/KW/day | N4: Non-summer Demand Max KW c/KW/day | O4: kVA | P4: MWh pa | Q4: kVA | R4: KW
A5: Low voltage small 1 rate | B5: LVS1R | C5: F,T | D5: =+ROUND('TUOS Ex GST'!D5*1.1,3) -> 0 | E5: =+ROUND('TUOS Ex GST'!E5*1.1,3) -> 2.345 | F5: =+ROUND('TUOS Ex GST'!F5*1.1,3) -> 1.96 | G5: =+ROUND('TUOS Ex GST'!G5*1.1,3) -> 0 | H5: =+ROUND('TUOS Ex GST'!H5*1.1,3) -> 0 | I5: =+ROUND('TUOS Ex GST'!I5*1.1,3) -> 0 | J5: =+ROUND('TUOS Ex GST'!J5*1.1,3) -> 0 | K5: =+ROUND('TUOS Ex GST'!K5*1.1,3) -> 0 | L5: =+ROUND('TUOS Ex GST'!L5*1.1,3) -> 0 | O5: NA | P5: <20
A6: Low voltage small 2 rate* | B6: LVS2R* | D6: =+ROUND('TUOS Ex GST'!D6*1.1,3) -> 0 | E6: =+ROUND('TUOS Ex GST'!E6*1.1,3) -> 3.938 | F6: =+ROUND('TUOS Ex GST'!F6*1.1,3) -> 3.152 | G6: =+ROUND('TUOS Ex GST'!G6*1.1,3) -> 0 | H6: =+ROUND('TUOS Ex GST'!H6*1.1,3) -> 0 | I6: =+ROUND('TUOS Ex GST'!I6*1.1,3) -> 0 | J6: =+ROUND('TUOS Ex GST'!J6*1.1,3) -> 0 | K6: =+ROUND('TUOS Ex GST'!K6*1.1,3) -> 0 | L6: =+ROUND('TUOS Ex GST'!L6*1.1,3) -> 0
A7: Dedicated circuit** | B7: LVDed** | D7: =+ROUND('TUOS Ex GST'!D7*1.1,3) -> 0 | E7: =+ROUND('TUOS Ex GST'!E7*1.1,3) -> 0 | F7: =+ROUND('TUOS Ex GST'!F7*1.1,3) -> 0 | G7: =+ROUND('TUOS Ex GST'!G7*1.1,3) -> 0 | H7: =+ROUND('TUOS Ex GST'!H7*1.1,3) -> 0 | I7: =+ROUND('TUOS Ex GST'!I7*1.1,3) -> 0 | J7: =+ROUND('TUOS Ex GST'!J7*1.1,3) -> 0 | K7: =+ROUND('TUOS Ex GST'!K7*1.1,3) -> 0 | L7: =+ROUND('TUOS Ex GST'!L7*1.1,3) -> 0 | O7: NA | P7: <20 (on LVS1R)
A8: Unmetered supplies | B8: UnMet | D8: =+ROUND('TUOS Ex GST'!D8*1.1,3) -> 0 | E8: =+ROUND('TUOS Ex GST'!E8*1.1,3) -> 3.691 | F8: =+ROUND('TUOS Ex GST'!F8*1.1,3) -> 2.949 | G8: =+ROUND('TUOS Ex GST'!G8*1.1,3) -> 0 | H8: =+ROUND('TUOS Ex GST'!H8*1.1,3) -> 0 | I8: =+ROUND('TUOS Ex GST'!I8*1.1,3) -> 0 | J8: =+ROUND('TUOS Ex GST'!J8*1.1,3) -> 0 | K8: =+ROUND('TUOS Ex GST'!K8*1.1,3) -> 0 | L8: =+ROUND('TUOS Ex GST'!L8*1.1,3) -> 0
A9: Winter Energy Tariff* | B9: WET2Step* | D9: =+ROUND('TUOS Ex GST'!D9*1.1,3) -> 0 | E9: =+ROUND('TUOS Ex GST'!E9*1.1,3) -> 2.624 | F9: =+ROUND('TUOS Ex GST'!F9*1.1,3) -> 2.099 | G9: =+ROUND('TUOS Ex GST'!G9*1.1,3) -> 2.099 | H9: =+ROUND('TUOS Ex GST'!H9*1.1,3) -> 0 | I9: =+ROUND('TUOS Ex GST'!I9*1.1,3) -> 0 | J9: =+ROUND('TUOS Ex GST'!J9*1.1,3) -> 0 | K9: =+ROUND('TUOS Ex GST'!K9*1.1,3) -> 0 | L9: =+ROUND('TUOS Ex GST'!L9*1.1,3) -> 0
A10: Reverse cycle airconditioning time of use* | B10: RCACkWTOU* | D10: =+ROUND('TUOS Ex GST'!D10*1.1,3) -> 0 | E10: =+ROUND('TUOS Ex GST'!E10*1.1,3) -> 17.779 | F10: =+ROUND('TUOS Ex GST'!F10*1.1,3) -> 3.959 | G10: =+ROUND('TUOS Ex GST'!G10*1.1,3) -> 0 | H10: =+ROUND('TUOS Ex GST'!H10*1.1,3) -> 0 | I10: =+ROUND('TUOS Ex GST'!I10*1.1,3) -> 0 | J10: =+ROUND('TUOS Ex GST'!J10*1.1,3) -> 0 | K10: =+ROUND('TUOS Ex GST'!K10*1.1,3) -> 0 | L10: =+ROUND('TUOS Ex GST'!L10*1.1,3) -> 11.274
A11: Low voltage medium 1 rate | B11: LVM1R | C11: F,T | D11: =+ROUND('TUOS Ex GST'!D11*1.1,3) -> 0 | E11: =+ROUND('TUOS Ex GST'!E11*1.1,3) -> 2.783 | F11: =+ROUND('TUOS Ex GST'!F11*1.1,3) -> 2.223 | G11: =+ROUND('TUOS Ex GST'!G11*1.1,3) -> 0 | H11: =+ROUND('TUOS Ex GST'!H11*1.1,3) -> 0 | I11: =+ROUND('TUOS Ex GST'!I11*1.1,3) -> 0 | J11: =+ROUND('TUOS Ex GST'!J11*1.1,3) -> 0 | K11: =+ROUND('TUOS Ex GST'!K11*1.1,3) -> 0 | L11: =+ROUND('TUOS Ex GST'!L11*1.1,3) -> 0 | O11: NA | P11: >20 & <400
A12: Low voltage medium 2 rate 5 day* | B12: LVM2R5D* | D12: =+ROUND('TUOS Ex GST'!D12*1.1,3) -> 0 | E12: =+ROUND('TUOS Ex GST'!E12*1.1,3) -> 2.075 | F12: =+ROUND('TUOS Ex GST'!F12*1.1,3) -> 1.659 | G12: =+ROUND('TUOS Ex GST'!G12*1.1,3) -> 0 | H12: =+ROUND('TUOS Ex GST'!H12*1.1,3) -> 0 | I12: =+ROUND('TUOS Ex GST'!I12*1.1,3) -> 0 | J12: =+ROUND('TUOS Ex GST'!J12*1.1,3) -> 0 | K12: =+ROUND('TUOS Ex GST'!K12*1.1,3) -> 0 | L12: =+ROUND('TUOS Ex GST'!L12*1.1,3) -> 0
A13: Low voltage medium 2 rate 7 day* | B13: LVM2R7D* | D13: =+ROUND('TUOS Ex GST'!D13*1.1,3) -> 0 | E13: =+ROUND('TUOS Ex GST'!E13*1.1,3) -> 2.757 | F13: =+ROUND('TUOS Ex GST'!F13*1.1,3) -> 2.208 | G13: =+ROUND('TUOS Ex GST'!G13*1.1,3) -> 0 | H13: =+ROUND('TUOS Ex GST'!H13*1.1,3) -> 0 | I13: =+ROUND('TUOS Ex GST'!I13*1.1,3) -> 0 | J13: =+ROUND('TUOS Ex GST'!J13*1.1,3) -> 0 | K13: =+ROUND('TUOS Ex GST'!K13*1.1,3) -> 0 | L13: =+ROUND('TUOS Ex GST'!L13*1.1,3) -> 0
A14: Low voltage KW time of use* | B14: LVkWTOU* | D14: =+ROUND('TUOS Ex GST'!D14*1.1,3) -> 0 | E14: =+ROUND('TUOS Ex GST'!E14*1.1,3) -> 1.922 | F14: =+ROUND('TUOS Ex GST'!F14*1.1,3) -> 1.537 | G14: =+ROUND('TUOS Ex GST'!G14*1.1,3) -> 0 | H14: =+ROUND('TUOS Ex GST'!H14*1.1,3) -> 0 | I14: =+ROUND('TUOS Ex GST'!I14*1.1,3) -> 0 | J14: =+ROUND('TUOS Ex GST'!J14*1.1,3) -> 0 | K14: =+ROUND('TUOS Ex GST'!K14*1.1,3) -> 0 | L14: =+ROUND('TUOS Ex GST'!L14*1.1,3) -> 8.964
A15: Low voltage KW time of use - HOT | B15: LVkWTOUH* | D15: =+ROUND('TUOS Ex GST'!D15*1.1,3) -> 0 | E15: =+ROUND('TUOS Ex GST'!E15*1.1,3) -> 1.209 | F15: =+ROUND('TUOS Ex GST'!F15*1.1,3) -> 0.966 | G15: =+ROUND('TUOS Ex GST'!G15*1.1,3) -> 0 | H15: =+ROUND('TUOS Ex GST'!H15*1.1,3) -> 0 | I15: =+ROUND('TUOS Ex GST'!I15*1.1,3) -> 0 | J15: =+ROUND('TUOS Ex GST'!J15*1.1,3) -> 0 | K15: =+ROUND('TUOS Ex GST'!K15*1.1,3) -> 0 | L15: =+ROUND('TUOS Ex GST'!L15*1.1,3) -> 10.834
A16: Low voltage large 1 rate* | B16: LVL1R* | D16: =+ROUND('TUOS Ex GST'!D16*1.1,3) -> 0 | E16: =+ROUND('TUOS Ex GST'!E16*1.1,3) -> 2.748 | F16: =+ROUND('TUOS Ex GST'!F16*1.1,3) -> 2.196 | G16: =+ROUND('TUOS Ex GST'!G16*1.1,3) -> 0 | H16: =+ROUND('TUOS Ex GST'!H16*1.1,3) -> 0 | I16: =+ROUND('TUOS Ex GST'!I16*1.1,3) -> 0 | J16: =+ROUND('TUOS Ex GST'!J16*1.1,3) -> 0 | K16: =+ROUND('TUOS Ex GST'!K16*1.1,3) -> 0 | L16: =+ROUND('TUOS Ex GST'!L16*1.1,3) -> 0
A17: Low voltage large 2 rate* | B17: LVL2R* | D17: =+ROUND('TUOS Ex GST'!D17*1.1,3) -> 0 | E17: =+ROUND('TUOS Ex GST'!E17*1.1,3) -> 2.112 | F17: =+ROUND('TUOS Ex GST'!F17*1.1,3) -> 1.692 | G17: =+ROUND('TUOS Ex GST'!G17*1.1,3) -> 0 | H17: =+ROUND('TUOS Ex GST'!H17*1.1,3) -> 0 | I17: =+ROUND('TUOS Ex GST'!I17*1.1,3) -> 0 | J17: =+ROUND('TUOS Ex GST'!J17*1.1,3) -> 0 | K17: =+ROUND('TUOS Ex GST'!K17*1.1,3) -> 0 | L17: =+ROUND('TUOS Ex GST'!L17*1.1,3) -> 0
A18: Low voltage large KVA time of use | B18: LVkVATOU | D18: =+ROUND('TUOS Ex GST'!D18*1.1,3) -> 0 | E18: =+ROUND('TUOS Ex GST'!E18*1.1,3) -> 1.203 | F18: =+ROUND('TUOS Ex GST'!F18*1.1,3) -> 0.966 | G18: =+ROUND('TUOS Ex GST'!G18*1.1,3) -> 0 | H18: =+ROUND('TUOS Ex GST'!H18*1.1,3) -> 0 | I18: =+ROUND('TUOS Ex GST'!I18*1.1,3) -> 0 | J18: =+ROUND('TUOS Ex GST'!J18*1.1,3) -> 0 | K18: =+ROUND('TUOS Ex GST'!K18*1.1,3) -> 4.916 | L18: =+ROUND('TUOS Ex GST'!L18*1.1,3) -> 6.719 | O18: >150 | P18: >400 | Q18: 150
A19: Low voltage large KVA time of use - HOT* | B19: LVkVATOUH* | D19: =+ROUND('TUOS Ex GST'!D19*1.1,3) -> 0 | E19: =+ROUND('TUOS Ex GST'!E19*1.1,3) -> 0.76 | F19: =+ROUND('TUOS Ex GST'!F19*1.1,3) -> 0.609 | G19: =+ROUND('TUOS Ex GST'!G19*1.1,3) -> 0 | H19: =+ROUND('TUOS Ex GST'!H19*1.1,3) -> 0 | I19: =+ROUND('TUOS Ex GST'!I19*1.1,3) -> 0 | J19: =+ROUND('TUOS Ex GST'!J19*1.1,3) -> 0 | K19: =+ROUND('TUOS Ex GST'!K19*1.1,3) -> 3.102 | L19: =+ROUND('TUOS Ex GST'!L19*1.1,3) -> 8.157 | Q19: 150
A20: High voltage KVA time of use | B20: HVkVATOU | D20: =+ROUND('TUOS Ex GST'!D20*1.1,3) -> 0 | E20: =+ROUND('TUOS Ex GST'!E20*1.1,3) -> 0.846 | F20: =+ROUND('TUOS Ex GST'!F20*1.1,3) -> 0.678 | G20: =+ROUND('TUOS Ex GST'!G20*1.1,3) -> 0 | H20: =+ROUND('TUOS Ex GST'!H20*1.1,3) -> 0 | I20: =+ROUND('TUOS Ex GST'!I20*1.1,3) -> 0 | J20: =+ROUND('TUOS Ex GST'!J20*1.1,3) -> 0 | K20: =+ROUND('TUOS Ex GST'!K20*1.1,3) -> 5.629 | L20: =+ROUND('TUOS Ex GST'!L20*1.1,3) -> 5.909 | O20: >150 | P20: >400 | Q20: 1150
A21: High voltage KVA time of use - HOT* | B21: HVkVATOUH* | D21: =+ROUND('TUOS Ex GST'!D21*1.1,3) -> 0 | E21: =+ROUND('TUOS Ex GST'!E21*1.1,3) -> 0.486 | F21: =+ROUND('TUOS Ex GST'!F21*1.1,3) -> 0.387 | G21: =+ROUND('TUOS Ex GST'!G21*1.1,3) -> 0 | H21: =+ROUND('TUOS Ex GST'!H21*1.1,3) -> 0 | I21: =+ROUND('TUOS Ex GST'!I21*1.1,3) -> 0 | J21: =+ROUND('TUOS Ex GST'!J21*1.1,3) -> 0 | K21: =+ROUND('TUOS Ex GST'!K21*1.1,3) -> 3.227 | L21: =+ROUND('TUOS Ex GST'!L21*1.1,3) -> 6.515 | Q21: 1150
A22: Subtransmission KVA time of use* | B22: SubTkVATOU* | D22: =+ROUND('TUOS Ex GST'!D22*1.1,3) -> 0 | E22: =+ROUND('TUOS Ex GST'!E22*1.1,3) -> 0.571 | F22: =+ROUND('TUOS Ex GST'!F22*1.1,3) -> 0.46 | G22: =+ROUND('TUOS Ex GST'!G22*1.1,3) -> 0 | H22: =+ROUND('TUOS Ex GST'!H22*1.1,3) -> 0 | I22: =+ROUND('TUOS Ex GST'!I22*1.1,3) -> 0 | J22: =+ROUND('TUOS Ex GST'!J22*1.1,3) -> 0 | K22: =+ROUND('TUOS Ex GST'!K22*1.1,3) -> 4.047 | L22: =+ROUND('TUOS Ex GST'!L22*1.1,3) -> 4.909 | Q22: 11100
A23: Time of Day | B23: TOD | C23: F,T | D23: =+ROUND('TUOS Ex GST'!D23*1.1,3) -> 0 | E23: =+ROUND('TUOS Ex GST'!E23*1.1,3) -> 2.412 | F23: =+ROUND('TUOS Ex GST'!F23*1.1,3) -> 2.048 | G23: =+ROUND('TUOS Ex GST'!G23*1.1,3) -> 0 | H23: =+ROUND('TUOS Ex GST'!H23*1.1,3) -> 2.048 | I23: =+ROUND('TUOS Ex GST'!I23*1.1,3) -> 1.808 | J23: =+ROUND('TUOS Ex GST'!J23*1.1,3) -> 0 | K23: =+ROUND('TUOS Ex GST'!K23*1.1,3) -> 0 | L23: =+ROUND('TUOS Ex GST'!L23*1.1,3) -> 0 | O23: NA | P23: <20
A24: Time of Use | B24: TOU | C24: F,T | D24: =+ROUND('TUOS Ex GST'!D24*1.1,3) -> 0 | E24: =+ROUND('TUOS Ex GST'!E24*1.1,3) -> 2.454 | F24: =+ROUND('TUOS Ex GST'!F24*1.1,3) -> 1.128 | G24: =+ROUND('TUOS Ex GST'!G24*1.1,3) -> 0 | H24: =+ROUND('TUOS Ex GST'!H24*1.1,3) -> 0 | I24: =+ROUND('TUOS Ex GST'!I24*1.1,3) -> 0 | J24: =+ROUND('TUOS Ex GST'!J24*1.1,3) -> 0 | K24: =+ROUND('TUOS Ex GST'!K24*1.1,3) -> 0 | L24: =+ROUND('TUOS Ex GST'!L24*1.1,3) -> 6.43 | O24: NA | P24: >20 & <400
A25: Time of Day 9pm off-peak | B25: TOD9 | C25: F, T | D25: =+ROUND('TUOS Ex GST'!D25*1.1,3) -> 0 | E25: =+ROUND('TUOS Ex GST'!E25*1.1,3) -> 5.097 | F25: =+ROUND('TUOS Ex GST'!F25*1.1,3) -> 4.739 | G25: =+ROUND('TUOS Ex GST'!G25*1.1,3) -> 0 | H25: =+ROUND('TUOS Ex GST'!H25*1.1,3) -> 4.739 | I25: =+ROUND('TUOS Ex GST'!I25*1.1,3) -> 4.503 | J25: =+ROUND('TUOS Ex GST'!J25*1.1,3) -> 0 | K25: =+ROUND('TUOS Ex GST'!K25*1.1,3) -> 0 | L25: =+ROUND('TUOS Ex GST'!L25*1.1,3) -> 0 | O25: NA | P25: <20
A26: Time of Day Flexible | B26: TODFLEX | C26: F,T | D26: =+ROUND('TUOS Ex GST'!D26*1.1,3) -> 0 | E26: =+ROUND('TUOS Ex GST'!E26*1.1,3) -> 4.31 | F26: =+ROUND('TUOS Ex GST'!F26*1.1,3) -> 4.021 | G26: =+ROUND('TUOS Ex GST'!G26*1.1,3) -> 0 | H26: =+ROUND('TUOS Ex GST'!H26*1.1,3) -> 2.154 | I26: =+ROUND('TUOS Ex GST'!I26*1.1,3) -> 1.901 | J26: =+ROUND('TUOS Ex GST'!J26*1.1,3) -> 0 | K26: =+ROUND('TUOS Ex GST'!K26*1.1,3) -> 0 | L26: =+ROUND('TUOS Ex GST'!L26*1.1,3) -> 0 | O26: Residential Customer
A27: Sesonal Demand TOU RES | B27: LVKWTOURES** | C27: F,T | E27: =+ROUND('TUOS Ex GST'!E27*1.1,3) -> 1.65 | F27: =+ROUND('TUOS Ex GST'!F27*1.1,3) -> 1.65 | G27: =+ROUND('TUOS Ex GST'!G27*1.1,3) -> 0 | H27: =+ROUND('TUOS Ex GST'!H27*1.1,3) -> 0 | I27: =+ROUND('TUOS Ex GST'!I27*1.1,3) -> 0 | J27: =+ROUND('TUOS Ex GST'!J27*1.1,3) -> 0 | K27: =+ROUND('TUOS Ex GST'!K27*1.1,3) -> 0 | L27: =+ROUND('TUOS Ex GST'!L27*1.1,3) -> 0 | ... N27: =+ROUND('TUOS Ex GST'!N27*1.1,3) -> 7.742 | O27: Residential Customer | Q27: 1.5 | R27: 1.5
A29: * Tariff closed to premises not already taking supply under this tariff and new connections.
A30: ** LVKWTOURES available from 1st July 2015
A31: Summer peak energy rates apply for period 1st November to 31st March (except TODFLEX which follows daylight savings periods) & LVKWTOURES which apply 1st December to 31st March.
A32: Non-summer peak energy rates apply for period 1st April to 31st October (except TODFLEX which follows non daylight savings periods) & LVKWTOURES which apply from 1st April to 30th November
A33: PFIT (Premium Feed-In Tariff) is defined by an “F” added to the front of an existing distribution tariff ie. FTOD. The PFIT tariffs are closed to new connections.
A34: TFIT (Transitional Feed-In Tariff) is defined by an “T” added to the front of an existing distribution tariff ie. TTOD. The TFIT tariffs are open to new connections that meet the solar criteria.

Sheet NUOS GST
A1: Schedule of Network Use of System (NUOS) Tariffs: 1 January 2015 (GST Inclusive)
D3: Network Tariff Component | O3: Eligibility (consumption/ category) | Q3: Minimum Chargeable Rolling Demand | R3: Minimum Chargeable Demand
A4: Description | B4: Tariff Code | C4: PFIT (F) TFIT (T) | D4: Standing Charge (c/day) | E4: Summer Peak Energy (c/kWh) | F4: Non Summer Peak Energy Block 1 (c/kWh) | G4: Non Summer Peak Energy Block 2 (c/kWh) | J4: Off Peak Energy (c/kWh) | K4: Rolling Peak Demand c/kVA/day | L4: Summer Demand Incentive Charge c/kW/day or c/kVA/day | M4: Summer Demand Max KW c/KW/day | N4: Non-summer Demand Max KW c/KW/day | O4: kVA | P4: MWh pa | Q4: kVA | R4: KW
A5: Low voltage small 1 rate | B5: LVS1R | C5: F,T | D5: =ROUND(+'DUOS GST'!D5+'TUOS GST'!D5,3) -> 7.35 | E5: =ROUND(+'DUOS GST'!E5+'TUOS GST'!E5,3) -> 11.409 | F5: =ROUND(+'DUOS GST'!F5+'TUOS GST'!F5,3) -> 7.794 | G5: =ROUND(+'DUOS GST'!G5+'TUOS GST'!G5,3) -> 0 | H5: =ROUND(+'DUOS GST'!H5+'TUOS GST'!H5,3) -> 0 | I5: =ROUND(+'DUOS GST'!I5+'TUOS GST'!I5,3) -> 0 | J5: =ROUND(+'DUOS GST'!J5+'TUOS GST'!J5,3) -> 0 | K5: =ROUND(+'DUOS GST'!K5+'TUOS GST'!K5,3) -> 0 | L5: =ROUND(+'DUOS GST'!L5+'TUOS GST'!L5,3) -> 0 | O5: NA | P5: <20
A6: Low voltage small 2 rate* | B6: LVS2R* | D6: =ROUND(+'DUOS GST'!D6+'TUOS GST'!D6,3) -> 15.214 | E6: =ROUND(+'DUOS GST'!E6+'TUOS GST'!E6,3) -> 14.857 | F6: =ROUND(+'DUOS GST'!F6+'TUOS GST'!F6,3) -> 11.434 | G6: =ROUND(+'DUOS GST'!G6+'TUOS GST'!G6,3) -> 0 | H6: =ROUND(+'DUOS GST'!H6+'TUOS GST'!H6,3) -> 0 | I6: =ROUND(+'DUOS GST'!I6+'TUOS GST'!I6,3) -> 0 | J6: =ROUND(+'DUOS GST'!J6+'TUOS GST'!J6,3) -> 1.893 | K6: =ROUND(+'DUOS GST'!K6+'TUOS GST'!K6,3) -> 0 | L6: =ROUND(+'DUOS GST'!L6+'TUOS GST'!L6,3) -> 0
A7: Dedicated circuit** | B7: LVDed** | D7: =ROUND(+'DUOS GST'!D7+'TUOS GST'!D7,3) -> 0 | E7: =ROUND(+'DUOS GST'!E7+'TUOS GST'!E7,3) -> 0 | F7: =ROUND(+'DUOS GST'!F7+'TUOS GST'!F7,3) -> 0 | G7: =ROUND(+'DUOS GST'!G7+'TUOS GST'!G7,3) -> 0 | H7: =ROUND(+'DUOS GST'!H7+'TUOS GST'!H7,3) -> 0 | I7: =ROUND(+'DUOS GST'!I7+'TUOS GST'!I7,3) -> 0 | J7: =ROUND(+'DUOS GST'!J7+'TUOS GST'!J7,3) -> 1.752 | K7: =ROUND(+'DUOS GST'!K7+'TUOS GST'!K7,3) -> 0 | L7: =ROUND(+'DUOS GST'!L7+'TUOS GST'!L7,3) -> 0 | O7: NA | P7: <20 (on LVS1R)
A8: Unmetered supplies | B8: UnMet | D8: =ROUND(+'DUOS GST'!D8+'TUOS GST'!D8,3) -> 0 | E8: =ROUND(+'DUOS GST'!E8+'TUOS GST'!E8,3) -> 12.869 | F8: =ROUND(+'DUOS GST'!F8+'TUOS GST'!F8,3) -> 9.663 | G8: =ROUND(+'DUOS GST'!G8+'TUOS GST'!G8,3) -> 0 | H8: =ROUND(+'DUOS GST'!H8+'TUOS GST'!H8,3) -> 0 | I8: =ROUND(+'DUOS GST'!I8+'TUOS GST'!I8,3) -> 0 | J8: =ROUND(+'DUOS GST'!J8+'TUOS GST'!J8,3) -> 1.656 | K8: =ROUND(+'DUOS GST'!K8+'TUOS GST'!K8,3) -> 0 | L8: =ROUND(+'DUOS GST'!L8+'TUOS GST'!L8,3) -> 0
A9: Winter Energy Tariff* | B9: WET2Step* | D9: =ROUND(+'DUOS GST'!D9+'TUOS GST'!D9,3) -> 9.593 | E9: =ROUND(+'DUOS GST'!E9+'TUOS GST'!E9,3) -> 9.778 | F9: =ROUND(+'DUOS GST'!F9+'TUOS GST'!F9,3) -> 7.4 | G9: =ROUND(+'DUOS GST'!G9+'TUOS GST'!G9,3) -> 4.086 | H9: =ROUND(+'DUOS GST'!H9+'TUOS GST'!H9,3) -> 0 | I9: =ROUND(+'DUOS GST'!I9+'TUOS GST'!I9,3) -> 0 | J9: =ROUND(+'DUOS GST'!J9+'TUOS GST'!J9,3) -> 0 | K9: =ROUND(+'DUOS GST'!K9+'TUOS GST'!K9,3) -> 0 | L9: =ROUND(+'DUOS GST'!L9+'TUOS GST'!L9,3) -> 0
A10: Reverse cycle airconditioning time of use* | B10: RCACkWTOU* | D10: =ROUND(+'DUOS GST'!D10+'TUOS GST'!D10,3) -> 0 | E10: =ROUND(+'DUOS GST'!E10+'TUOS GST'!E10,3) -> 23.996 | F10: =ROUND(+'DUOS GST'!F10+'TUOS GST'!F10,3) -> 5.522 | G10: =ROUND(+'DUOS GST'!G10+'TUOS GST'!G10,3) -> 0 | H10: =ROUND(+'DUOS GST'!H10+'TUOS GST'!H10,3) -> 0 | I10: =ROUND(+'DUOS GST'!I10+'TUOS GST'!I10,3) -> 0 | J10: =ROUND(+'DUOS GST'!J10+'TUOS GST'!J10,3) -> 1.536 | K10: =ROUND(+'DUOS GST'!K10+'TUOS GST'!K10,3) -> 0 | L10: =ROUND(+'DUOS GST'!L10+'TUOS GST'!L10,3) -> 89.397
A11: Low voltage medium 1 rate | B11: LVM1R | C11: F,T | D11: =ROUND(+'DUOS GST'!D11+'TUOS GST'!D11,3) -> 14.24 | E11: =ROUND(+'DUOS GST'!E11+'TUOS GST'!E11,3) -> 15.3 | F11: =ROUND(+'DUOS GST'!F11+'TUOS GST'!F11,3) -> 10.032 | G11: =ROUND(+'DUOS GST'!G11+'TUOS GST'!G11,3) -> 0 | H11: =ROUND(+'DUOS GST'!H11+'TUOS GST'!H11,3) -> 0 | I11: =ROUND(+'DUOS GST'!I11+'TUOS GST'!I11,3) -> 0 | J11: =ROUND(+'DUOS GST'!J11+'TUOS GST'!J11,3) -> 0 | K11: =ROUND(+'DUOS GST'!K11+'TUOS GST'!K11,3) -> 0 | L11: =ROUND(+'DUOS GST'!L11+'TUOS GST'!L11,3) -> 0 | O11: NA | P11: >20 & <400
A12: Low voltage medium 2 rate 5 day* | B12: LVM2R5D* | D12: =ROUND(+'DUOS GST'!D12+'TUOS GST'!D12,3) -> 20.446 | E12: =ROUND(+'DUOS GST'!E12+'TUOS GST'!E12,3) -> 12.004 | F12: =ROUND(+'DUOS GST'!F12+'TUOS GST'!F12,3) -> 9.099 | G12: =ROUND(+'DUOS GST'!G12+'TUOS GST'!G12,3) -> 0 | H12: =ROUND(+'DUOS GST'!H12+'TUOS GST'!H12,3) -> 0 | I12: =ROUND(+'DUOS GST'!I12+'TUOS GST'!I12,3) -> 0 | J12: =ROUND(+'DUOS GST'!J12+'TUOS GST'!J12,3) -> 1.854 | K12: =ROUND(+'DUOS GST'!K12+'TUOS GST'!K12,3) -> 0 | L12: =ROUND(+'DUOS GST'!L12+'TUOS GST'!L12,3) -> 0
A13: Low voltage medium 2 rate 7 day* | B13: LVM2R7D* | D13: =ROUND(+'DUOS GST'!D13+'TUOS GST'!D13,3) -> 21.959 | E13: =ROUND(+'DUOS GST'!E13+'TUOS GST'!E13,3) -> 12.291 | F13: =ROUND(+'DUOS GST'!F13+'TUOS GST'!F13,3) -> 9.59 | G13: =ROUND(+'DUOS GST'!G13+'TUOS GST'!G13,3) -> 0 | H13: =ROUND(+'DUOS GST'!H13+'TUOS GST'!H13,3) -> 0 | I13: =ROUND(+'DUOS GST'!I13+'TUOS GST'!I13,3) -> 0 | J13: =ROUND(+'DUOS GST'!J13+'TUOS GST'!J13,3) -> 1.739 | K13: =ROUND(+'DUOS GST'!K13+'TUOS GST'!K13,3) -> 0 | L13: =ROUND(+'DUOS GST'!L13+'TUOS GST'!L13,3) -> 0
