Workbook
Name _Hlk318882101: 'ACS Tariff classes & tariffs'!#REF!
Name current_pricing_year: '[1]Model builder'!$E$23
Name JS_final_round: [1]JS!$C$25:$L$34
Name JS_final_round_C: [1]JS!$C$24:$L$24

Sheet EECL Price List
B7: Ergon Energy Corporation Limited
B8: 2017-18 Price List for Alternative Control Services | H8: Key: | J8: These services are subject to an additional layer of price regulation at the jurisdictional level, through Schedule 8 of the Electricity Regulation 2006. Even though the national economic regulator (the AER) has approved a higher price that EECL can charge for this service, the Queensland Government has stipulated a (lower) maximum price EECL is able to charge customers in EECL's supply area for these services.
B9: Release 1.1 - 1 July 2017 | D9: Release 0.0 - 1 July 2017 | F9: Release 0.0 - 1 July 2017 | J9: These services are subject to an additional layer of price regulation at the jurisdictional level, through Schedule 8 of the Electricity Regulation 2006. Even though the national economic regulator (the AER) has approved a higher price that EECL can charge for this service, the Queensland Government has stipulated that long rural / isolated customers in EECL's supply area are only able to be charged for these services at the same rate as an urban / short rural customer.
A12: Ref | B12: Service | C12: Service description | D12: Product Codes | H12: Ellipse Cost Code | I12: Urban/short rural feeder price | K12: Long rural/isolated feeder price | M12: AER classification | N12: Notes | O12: B2B Retailer only | P12: Form "A" Required
D13: Urban | E13: Short rural | F13: Long rural | G13: Isolated | I13: GST Excl | J13: GST Incl | K13: GST Excl | L13: GST Incl | O13: Customer
B14: Pre-Connection Services
A15: 1 | B15: Application fee - Basic or standard connection | C15: Services associated with assessing an application requesting a connection to be made (or altered) between Ergon Energy's network and the customer’s installation, and the preparation of a compliant basic or standard connection offer. Applies to small customers classified as a Standard Asset Customer (SAC), as per Ergon Energy's pricing proposal. | D15: APFSAC | H15: 8000 | I15: 888.4 | J15: =I15*1.1 -> 977.24 | K15: =I15 -> 888.4 | L15: =J15 -> 977.24 | M15: Fee Based Service | N15: Fixed fee applies | O15: Customer | P15: No
A16: 2 | B16: Application fee - Basic or standard connection - Micro-embedded generators | C16: Services associated with assessing a micro-embedded generator application requesting a connection to be made (or altered) between Ergon Energy's network and the customer’s installation, and the preparation of a compliant basic or standard connection offer. Applies to micro-embedded generators only (a subset of Standard Asset Customers, as per Ergon Energy's pricing proposal). No technical assessment required. | D16: APFMEG | H16: 8001 | I16: 48.6 | J16: =I16*1.1 -> 53.46 | K16: =I16 -> 48.6 | L16: =J16 -> 53.46 | M16: Fee Based Service | N16: Fixed fee applies | O16: Customer | P16: No
A17: 3 | B17: Application fee - Basic or standard connection - Micro-embedded generators - Technical assessment required | C17: Services associated with assessing a micro-embedded generator application requesting a connection to be made (or altered) between Ergon Energy's network and the customer’s installation, and the preparation of a compliant basic or standard connection offer. Applies to micro-embedded generators only (a subset of Standard Asset Customers, as per Ergon Energy's pricing proposal), where a technical assessment is required to be undertaken by Ergon Energy. | D17: APFMTA | H17: 8002 | I17: 220.7 | J17: =I17*1.1 -> 242.77 | K17: =I17 -> 220.7 | L17: =J17 -> 242.77 | M17: Fee Based Service | N17: Fixed fee applies | O17: Customer | P17: No
A18: 4 | B18: Application fee - Real estate development connection | C18: Services associated with assessing an application requesting a connection to be made between Ergon Energy's network and a real estate developer's installation, and the preparation of a compliant connection offer. Includes works carried out by contractors and/or Ergon Energy. | D18: APFRED | H18: 8003 | I18: 930.2 | J18: =I18*1.1 -> 1023.22 | K18: =I18 -> 930.2 | L18: =J18 -> 1023.22 | M18: Fee Based Service | N18: Fixed fee applies | O18: Customer | P18: No
A19: 5 | B19: Protection and Power Quality assessment prior to connection | C19: Evaluation of application protection design for completeness against engineering connection standard. Study of Power Quality issues including Flicker, Harmonics and DC voltage injection. | D19: PPQA | H19: 8004 | I19: 1376.7 | J19: =I19*1.1 -> 1514.37 | K19: =I19 -> 1376.7 | L19: =J19 -> 1514.37 | M19: Fee Based Service | N19: Fixed fee applies | O19: Customer | P19: No
A20: 40 | B20: Application fee - Negotiated connection | C20: Services associated with assessing an application requesting a connection to be made (or altered) between Ergon Energy's network and the customer’s installation, and the costs associated with negotiating and preparing a negotiated connection offer. Applies to small customers classified as a Standard Asset Customer (SAC), as per Ergon Energy's pricing proposal, with the exception of micro-embedded generators. | D20: As Quoted | H20: 8005 | I20: POA | K20: POA | M20: Quoted Service | N20: Price on application | O20: Customer | P20: No
A21: 41 | B21: Application fee - Negotiated connection - Micro-embedded generators | C21: Services associated with assessing a micro-embedded generator application requesting a connection to be made (or altered) between Ergon Energy's network and the customer’s installation, and the costs associated with negotiating and preparing a negotiated connection offer. Applies to micro-embedded generators only (a subset of SAC, as per Ergon Energy's pricing proposal). | D21: As Quoted | H21: 8006 | I21: POA | K21: POA | M21: Quoted Service | N21: Price on application | O21: Customer | P21: No
A22: 42 | B22: Application fee - Negotiated - Major customer connection | C22: Services associated with assessing a major customer connection application requesting a connection to be made (or altered) between Ergon Energy's network and the customer’s installation, and the costs associated with negotiating and preparing a compliant negotiated connection offer. Applies to major customers classified as an Individually Calculated Customer (ICC), Connection Asset Customer (CAC) or Embedded Generator (EG), as per Ergon Energy's pricing proposal. | D22: As Quoted | H22: 8007 | I22: POA | K22: POA | M22: Quoted Service | N22: Price on application | O22: Customer | P22: No
A23: 43 | B23: Carrying out planning studies and analysis relating to connection applications | C23: Services associated with carrying out additional planning studies and analysis on the distribution system which are reasonably required to assess a small customer or real estate development connection application. Excludes planning studies and analysis that would otherwise be required for distributor purposes or for the efficient management of the shared network. Applies to small customers classified as a Standard Asset Customer, as per Ergon Energy's pricing proposal (including micro-embedded generators), and real estate developers. | D23: As Quoted | H23: 8008 | I23: POA | K23: POA | M23: Quoted Service | N23: Price on application | O23: Customer | P23: No
A24: 44 | B24: Feasibility and concept scoping, including planning and design, for major customer connections | C24: Detailed design and advice for major customer connections for the selected (preferred) connection option. This includes shared network planning and design works incurred during the feasibility and concept scoping phases (i.e. before the connection offer has been accepted) (where applicable). | D24: As Quoted | H24: 8009 | I24: POA | K24: POA | M24: Quoted Service | N24: Price on application | O24: Customer | P24: No
A25: 45 | B25: Tender process | C25: Applies where Ergon Energy conducts a tender process on behalf of a connection applicant to procure connection services that can be provided by a third party, or where the connection applicant conducts a tender process and requires assistance from Ergon Energy | D25: As Quoted | H25: 8010 | I25: POA | K25: POA | M25: Quoted Service | N25: Price on application | O25: Customer | P25: No
A26: 46 | B26: Pre-connection site inspection | C26: Site inspection in order to determine nature of connection being sought | D26: As Quoted | H26: 8011 | I26: POA | K26: POA | M26: Quoted Service | N26: Price on application | O26: Customer | P26: No
A27: 47 | B27: Provision of site-specific connection information and advice | C27: Provision of site-specific connection advice, data and/or information on request (during the connection enquiry and/or connection application stage only). For example: - advice on project feasibility - advice on whether augmentation would likely be required - capacity information, including specific network capacity - load profiles for load flow studies - requests to review reports and designs prepared by external consultants, prior to lodgement of connection application - additional or more detailed specification and design options. Excludes information provided in planning reports/studies and project scopes. | D27: As Quoted | H27: 8012 | I27: POA | K27: POA | M27: Quoted Service | N27: Price on application | O27: Customer | P27: No
A28: 48 | B28: Preparation of preliminary designs and planning reports for major customer connections, including project scopes and estimates | C28: Initial specification and design outline for major customer connections. Includes general evaluation and advice on asset ownership options, indicative estimates of viable connection options, and recommendation on the most suitable option. | D28: As Quoted | H28: 8013 | I28: POA | K28: POA | M28: Quoted Service | N28: Price on application | O28: Customer | P28: No
A29: 49 | B29: Customer build, own and operate consultation services | C29: Provision of advice, design and specification on request to an applicant considering a build-own-operate asset ownership option for connection assets. | D29: As Quoted | H29: 8014 | I29: POA | K29: POA | M29: Quoted Service | N29: Price on application | O29: Customer | P29: No
A30: 50 | B30: Detailed enquiry response fee - embedded generation | C30: Costs associated with preparing a detailed enquiry response pursuant to Chapter 5 of the NER. Applies to any embedded generation connection applicant that submits an enquiry under the connection process set out in Chapter 5 of the NER and seeks a detailed enquiry response. | D30: As Quoted | H30: 8015 | I30: POA | K30: POA | M30: Quoted Service | N30: Price on application | O30: Customer | P30: No
B31: Connection Services
A32: 6 | B32: Temporary connection, not in permanent position - single phase metered - urban/short rural feeders | C32: Connection of a single phase supply to a meter location that is not permanent (i.e. short term supply) | D32: TBSSPU | E32: TBSSPS | H32: 8020 | I32: 412.7 | J32: =I32*1.1 -> 453.97 | M32: Fee Based Service | N32: Fixed fee applies, capped to maximum specified in Schedule 8 of Electricity Regulation 2006 | O32: B2B Retailer only | P32: Yes
A33: 6-CF | B33: Call out fee for temporary connection, not in permanent position - single phase metered - urban/short rural feeders | C33: Travel time to perform a fee based service requested by a retailer or customer, and the service is unable to be performed due to customer/retailer fault. Connection of a single phase supply to a meter location that is not permanent (i.e. short term supply) | D33: CFTBSSPU | E33: CFTBSSPS | H33: 8021 | I33: 116.9 | J33: =I33*1.1 -> 128.59 | M33: Fee Based Service | N33: Fixed fee applies | O33: B2B Retailer only | P33: N/A
A34: 7 | B34: Temporary connection, not in permanent position - single phase metered - long rural/isolated feeders | C34: Connection of a single phase supply to a meter location that is not permanent (i.e. short term supply) | F34: TBSSPL | G34: TBSSPI | H34: 8022 | K34: 412.7 | L34: =K34*1.1 -> 453.97 | M34: Fee Based Service | N34: Fixed fee applies, capped to maximum specified in Schedule 8 of Electricity Regulation 2006 | O34: B2B Retailer only | P34: Yes
A35: 7-CF | B35: Call out fee for temporary connection, not in permanent position - single phase metered - long rural/isolated feeders | C35: Travel time to perform a fee based service requested by a retailer or customer, and the service is unable to be performed due to customer/retailer fault. Connection of a single phase supply to a meter location that is not permanent (i.e. short term supply) | F35: CFTBSSPL | G35: CFTBSSPI | H35: 8023 | K35: 412.7 | L35: =K35*1.1 -> 453.97 | M35: Fee Based Service | N35: Fixed fee applies, capped to the maximum price of the associated service (to be consistent with Schedule 8 of Electricity Regulation 2006) | O35: B2B Retailer only | P35: N/A
A36: 8 | B36: Temporary connection, not in permanent position - multi phase metered - urban/short rural feeders | C36: Connection of a multi phase supply to a meter location that is not permanent (i.e. short term supply) | D36: TBSMPU | E36: TBSMPS | H36: 8024 | I36: 412.7 | J36: =I36*1.1 -> 453.97 | M36: Fee Based Service | N36: Fixed fee applies, capped to maximum specified in Schedule 8 of Electricity Regulation 2006 | O36: B2B Retailer only | P36: Yes
A37: 8-CF | B37: Call out fee for temporary connection, not in permanent position - multi-phase metered - urban/short rural feeders | C37: Travel time to perform a fee based service requested by a retailer or customer, and the service is unable to be performed due to customer/retailer fault. Connection of a multi-phase supply to a meter location that is not permanent (i.e. short term supply) | D37: CFTBSMPU | E37: CFTBSMPS | H37: 8025 | I37: 116.9 | J37: =I37*1.1 -> 128.59 | M37: Fee Based Service | N37: Fixed fee applies | O37: B2B Retailer only | P37: N/A
A38: 9 | B38: Temporary connection, not in permanent position - multi phase metered - long rural/isolated feeders | C38: Connection of a multi phase supply to a meter location that is not permanent (i.e. short term supply) | F38: TBSMPL | G38: TBSMPI | H38: 8026 | K38: 412.7 | L38: =K38*1.1 -> 453.97 | M38: Fee Based Service | N38: Fixed fee applies, capped to maximum specified in Schedule 8 of Electricity Regulation 2006 | O38: B2B Retailer only | P38: Yes
A39: 9-CF | B39: Call out fee for temporary connection, not in permanent position - multi-phase metered - long rural/isolated feeders | C39: Travel time to perform a fee based service requested by a retailer or customer, and the service is unable to be performed due to customer/retailer fault. Connection of a multi-phase supply to a meter location that is not permanent (i.e. short term supply) | F39: CFTBSMPL | G39: CFTBSMPI | H39: 8027 | K39: 412.7 | L39: =K39*1.1 -> 453.97 | M39: Fee Based Service | N39: Fixed fee applies, capped to the maximum price of the associated service (to be consistent with Schedule 8 of Electricity Regulation 2006) | O39: B2B Retailer only | P39: N/A
A40: 51 | B40: Design and construction of connection assets for major customers | C40: Detailed design work and construction of connection assets after a connection offer has been made. Applies to major customers classified as an Individually Calculated Customer (ICC), Connection Asset Customer (CAC) or Embedded Generator (EG) as per Ergon Energy's pricing proposal. | D40: As Quoted | H40: 8028 | I40: POA | K40: POA | M40: Quoted Service | N40: Price on application | O40: Customer | P40: No
A41: 52 | B41: Commissioning and energisation of major customer connections | C41: Includes: - inspection and testing of connection assets prior to physical connection to the network - physical connection and energisation of electricity equipment to allow conveyance of electricity - administration services involved in reconciling the financials of a connection project, and processing and finalising network information and contracts in relation to a connection - generation required (if any) to supply existing customers while equipment is de-energised to allow testing and commissioning Applies to major customers classified as an Individually Calculated Customer (ICC), Connection Asset Customer (CAC) or Embedded Generator (EG) as per Ergon Energy's pricing proposal. | D41: As Quoted | H41: 8029 | I41: POA | K41: POA | M41: Quoted Service | N41: Price on application | O41: Customer | P41: Yes
A42: 53 | B42: Design and construction for real estate developments | C42: Detailed design work and construction for a real estate development connection after a connection offer has been made. Includes work associated with augmentation to the shared network which is directly attributable to the establishment or alteration of the real estate development connection | D42: As Quoted | H42: 8030 | I42: POA | K42: POA | M42: Quoted Service | N42: Price on application | O42: Customer | P42: No
A43: 54 | B43: Commissioning and energisation of real estate development connections | C43: Includes: - inspection and testing prior to physical connection to the network - physical connection and energisation of electricity equipment to allow conveyance of electricity - administration services involved in reconciling the financials of a connection project, and processing and finalising network information and contracts in relation to a connection - generation required (if any) to supply existing customers while equipment is de-energised to allow testing and commissioning | D43: As Quoted | H43: 8031 | I43: POA | K43: POA | M43: Quoted Service | N43: Price on application | O43: Customer | P43: Yes
A44: 55 | B44: Removal of network constraint for embedded generator | C44: Augmenting the network to remove a constraint faced by an embedded generator | D44: As Quoted | H44: 8032 | I44: POA | K44: POA | M44: Quoted Service | N44: Price on application | O44: Customer | P44: No
B45: Post Connection Services
A46: 10 | B46: Supply abolishment during business hours - urban/short rural feeders | C46: Decommissioning of a NMI and associated metering when present. May be used where a property is to be demolished; supply is no longer required; an alternative connection point is to be used; or a redundant supply is to be removed | D46: SUPABOLU | E46: SUPABOLS | H46: 8040 | I46: 350.9 | J46: =I46*1.1 -> 385.99 | M46: Fee Based Service | N46: Fixed fee applies | O46: B2B Retailer only | P46: No
A47: 10-CF | B47: Call out fee for supply abolishment during business hours - urban/short rural feeders | C47: Travel time to perform a fee based service requested by a retailer or customer, and the service is unable to be performed due to customer/retailer fault. Decommissioning of a NMI and associated metering when present. May be used where a property is to be demolished; supply is no longer required; an alternative connection point is to be used; or a redundant supply is to be removed | D47: CFSUPABOLU | E47: CFSUPABOLS | H47: 8041 | I47: 116.9 | J47: =I47*1.1 -> 128.59 | M47: Fee Based Service | N47: Fixed fee applies | O47: B2B Retailer only | P47: N/A
A48: 11 | B48: Supply abolishment during business hours - long rural/isolated feeders | C48: Decommissioning of a NMI and associated metering when present. May be used where a property is to be demolished; supply is no longer required; an alternative connection point is to be used; or a redundant supply is to be removed | F48: SUPABOLL | G48: SUPABOLI | H48: 8042 | K48: 350.9 | L48: =K48*1.1 -> 385.99 | M48: Fee Based Service | N48: Fixed fee applies, capped to UR/SR price as per Schedule 8 of Electricity Regulation 2006 | O48: B2B Retailer only | P48: No
...

Sheet ACS Tariff classes & tariffs
F1: 4 | G1: 5 | H1: 6 | I1: 7
D3: Ergon Energy Corporation Limited
D4: 2017-18 ACS tariffs by tariff class
D8: Tariff class | E8: Tariff | F8: Product Codes
F9: Service undertaken | J9: No service undertaken due to customer/retailer fault (Call out fee)
B10: 1 | D10: Fee based services (urban/short rural) | E10: =VLOOKUP(B10,'EECL Price List'!$A$12:$P$172,2,FALSE) -> Application fee - Basic or standard connection | F10: =IF(VLOOKUP($B10,'EECL Price List'!$A$12:$P$172,F$1,FALSE)=0,"",VLOOKUP($B10,'EECL Price List'!$A$12:$P$172,F$1,FALSE)) -> APFSAC | G10: =IF(VLOOKUP($B10,'EECL Price List'!$A$12:$P$172,G$1,FALSE)=0,"",VLOOKUP($B10,'EECL Price List'!$A$12:$P$172,G$1,FALSE)) | J10: =IFERROR(IF(VLOOKUP($C10,'EECL Price List'!$A$12:$P$172,F$1,FALSE)=0,"",VLOOKUP($C10,'EECL Price List'!$A$12:$P$172,F$1,FALSE)),"") | K10: =IFERROR(IF(VLOOKUP($C10,'EECL Price List'!$A$12:$P$172,G$1,FALSE)=0,"",VLOOKUP($C10,'EECL Price List'!$A$12:$P$172,G$1,FALSE)),"")
B11: 2 | E11: =VLOOKUP(B11,'EECL Price List'!$A$12:$P$172,2,FALSE) -> Application fee - Basic or standard connection - Micro-embedded generators | F11: =IF(VLOOKUP($B11,'EECL Price List'!$A$12:$P$172,F$1,FALSE)=0,"",VLOOKUP($B11,'EECL Price List'!$A$12:$P$172,F$1,FALSE)) -> APFMEG | G11: =IF(VLOOKUP($B11,'EECL Price List'!$A$12:$P$172,G$1,FALSE)=0,"",VLOOKUP($B11,'EECL Price List'!$A$12:$P$172,G$1,FALSE)) | J11: =IFERROR(IF(VLOOKUP($C11,'EECL Price List'!$A$12:$P$172,F$1,FALSE)=0,"",VLOOKUP($C11,'EECL Price List'!$A$12:$P$172,F$1,FALSE)),"") | K11: =IFERROR(IF(VLOOKUP($C11,'EECL Price List'!$A$12:$P$172,G$1,FALSE)=0,"",VLOOKUP($C11,'EECL Price List'!$A$12:$P$172,G$1,FALSE)),"")
B12: 3 | E12: =VLOOKUP(B12,'EECL Price List'!$A$12:$P$172,2,FALSE) -> Application fee - Basic or standard connection - Micro-embedded generators - Technical assessment required | F12: =IF(VLOOKUP($B12,'EECL Price List'!$A$12:$P$172,F$1,FALSE)=0,"",VLOOKUP($B12,'EECL Price List'!$A$12:$P$172,F$1,FALSE)) -> APFMTA | G12: =IF(VLOOKUP($B12,'EECL Price List'!$A$12:$P$172,G$1,FALSE)=0,"",VLOOKUP($B12,'EECL Price List'!$A$12:$P$172,G$1,FALSE)) | J12: =IFERROR(IF(VLOOKUP($C12,'EECL Price List'!$A$12:$P$172,F$1,FALSE)=0,"",VLOOKUP($C12,'EECL Price List'!$A$12:$P$172,F$1,FALSE)),"") | K12: =IFERROR(IF(VLOOKUP($C12,'EECL Price List'!$A$12:$P$172,G$1,FALSE)=0,"",VLOOKUP($C12,'EECL Price List'!$A$12:$P$172,G$1,FALSE)),"")
B13: 4 | E13: =VLOOKUP(B13,'EECL Price List'!$A$12:$P$172,2,FALSE) -> Application fee - Real estate development connection | F13: =IF(VLOOKUP($B13,'EECL Price List'!$A$12:$P$172,F$1,FALSE)=0,"",VLOOKUP($B13,'EECL Price List'!$A$12:$P$172,F$1,FALSE)) -> APFRED | G13: =IF(VLOOKUP($B13,'EECL Price List'!$A$12:$P$172,G$1,FALSE)=0,"",VLOOKUP($B13,'EECL Price List'!$A$12:$P$172,G$1,FALSE)) | J13: =IFERROR(IF(VLOOKUP($C13,'EECL Price List'!$A$12:$P$172,F$1,FALSE)=0,"",VLOOKUP($C13,'EECL Price List'!$A$12:$P$172,F$1,FALSE)),"") | K13: =IFERROR(IF(VLOOKUP($C13,'EECL Price List'!$A$12:$P$172,G$1,FALSE)=0,"",VLOOKUP($C13,'EECL Price List'!$A$12:$P$172,G$1,FALSE)),"")
B14: 5 | E14: =VLOOKUP(B14,'EECL Price List'!$A$12:$P$172,2,FALSE) -> Protection and Power Quality assessment prior to connection | F14: =IF(VLOOKUP($B14,'EECL Price List'!$A$12:$P$172,F$1,FALSE)=0,"",VLOOKUP($B14,'EECL Price List'!$A$12:$P$172,F$1,FALSE)) -> PPQA | G14: =IF(VLOOKUP($B14,'EECL Price List'!$A$12:$P$172,G$1,FALSE)=0,"",VLOOKUP($B14,'EECL Price List'!$A$12:$P$172,G$1,FALSE)) | J14: =IFERROR(IF(VLOOKUP($C14,'EECL Price List'!$A$12:$P$172,F$1,FALSE)=0,"",VLOOKUP($C14,'EECL Price List'!$A$12:$P$172,F$1,FALSE)),"") | K14: =IFERROR(IF(VLOOKUP($C14,'EECL Price List'!$A$12:$P$172,G$1,FALSE)=0,"",VLOOKUP($C14,'EECL Price List'!$A$12:$P$172,G$1,FALSE)),"")
B15: 6 | C15: 6-CF | E15: =VLOOKUP(B15,'EECL Price List'!$A$12:$P$172,2,FALSE) -> Temporary connection, not in permanent position - single phase metered - urban/short rural feeders | F15: =IF(VLOOKUP($B15,'EECL Price List'!$A$12:$P$172,F$1,FALSE)=0,"",VLOOKUP($B15,'EECL Price List'!$A$12:$P$172,F$1,FALSE)) -> TBSSPU | G15: =IF(VLOOKUP($B15,'EECL Price List'!$A$12:$P$172,G$1,FALSE)=0,"",VLOOKUP($B15,'EECL Price List'!$A$12:$P$172,G$1,FALSE)) -> TBSSPS | J15: =IFERROR(IF(VLOOKUP($C15,'EECL Price List'!$A$12:$P$172,F$1,FALSE)=0,"",VLOOKUP($C15,'EECL Price List'!$A$12:$P$172,F$1,FALSE)),"") -> CFTBSSPU | K15: =IFERROR(IF(VLOOKUP($C15,'EECL Price List'!$A$12:$P$172,G$1,FALSE)=0,"",VLOOKUP($C15,'EECL Price List'!$A$12:$P$172,G$1,FALSE)),"") -> CFTBSSPS
B16: 8 | C16: 8-CF | E16: =VLOOKUP(B16,'EECL Price List'!$A$12:$P$172,2,FALSE) -> Temporary connection, not in permanent position - multi phase metered - urban/short rural feeders | F16: =IF(VLOOKUP($B16,'EECL Price List'!$A$12:$P$172,F$1,FALSE)=0,"",VLOOKUP($B16,'EECL Price List'!$A$12:$P$172,F$1,FALSE)) -> TBSMPU | G16: =IF(VLOOKUP($B16,'EECL Price List'!$A$12:$P$172,G$1,FALSE)=0,"",VLOOKUP($B16,'EECL Price List'!$A$12:$P$172,G$1,FALSE)) -> TBSMPS | J16: =IFERROR(IF(VLOOKUP($C16,'EECL Price List'!$A$12:$P$172,F$1,FALSE)=0,"",VLOOKUP($C16,'EECL Price List'!$A$12:$P$172,F$1,FALSE)),"") -> CFTBSMPU | K16: =IFERROR(IF(VLOOKUP($C16,'EECL Price List'!$A$12:$P$172,G$1,FALSE)=0,"",VLOOKUP($C16,'EECL Price List'!$A$12:$P$172,G$1,FALSE)),"") -> CFTBSMPS
B17: 10 | C17: 10-CF | E17: =VLOOKUP(B17,'EECL Price List'!$A$12:$P$172,2,FALSE) -> Supply abolishment during business hours - urban/short rural feeders | F17: =IF(VLOOKUP($B17,'EECL Price List'!$A$12:$P$172,F$1,FALSE)=0,"",VLOOKUP($B17,'EECL Price List'!$A$12:$P$172,F$1,FALSE)) -> SUPABOLU | G17: =IF(VLOOKUP($B17,'EECL Price List'!$A$12:$P$172,G$1,FALSE)=0,"",VLOOKUP($B17,'EECL Price List'!$A$12:$P$172,G$1,FALSE)) -> SUPABOLS | J17: =IFERROR(IF(VLOOKUP($C17,'EECL Price List'!$A$12:$P$172,F$1,FALSE)=0,"",VLOOKUP($C17,'EECL Price List'!$A$12:$P$172,F$1,FALSE)),"") -> CFSUPABOLU | K17: =IFERROR(IF(VLOOKUP($C17,'EECL Price List'!$A$12:$P$172,G$1,FALSE)=0,"",VLOOKUP($C17,'EECL Price List'!$A$12:$P$172,G$1,FALSE)),"") -> CFSUPABOLS
B18: 12 | C18: 12-CF | E18: =VLOOKUP(B18,'EECL Price List'!$A$12:$P$172,2,FALSE) -> De-energisation during business hours - urban/short rural feeders | F18: =IF(VLOOKUP($B18,'EECL Price List'!$A$12:$P$172,F$1,FALSE)=0,"",VLOOKUP($B18,'EECL Price List'!$A$12:$P$172,F$1,FALSE)) -> DEENBHU | G18: =IF(VLOOKUP($B18,'EECL Price List'!$A$12:$P$172,G$1,FALSE)=0,"",VLOOKUP($B18,'EECL Price List'!$A$12:$P$172,G$1,FALSE)) -> DEENBHS | J18: =IFERROR(IF(VLOOKUP($C18,'EECL Price List'!$A$12:$P$172,F$1,FALSE)=0,"",VLOOKUP($C18,'EECL Price List'!$A$12:$P$172,F$1,FALSE)),"") -> CFDEENBHU | K18: =IFERROR(IF(VLOOKUP($C18,'EECL Price List'!$A$12:$P$172,G$1,FALSE)=0,"",VLOOKUP($C18,'EECL Price List'!$A$12:$P$172,G$1,FALSE)),"") -> CFDEENBHS
B19: 14 | C19: 14-CF | E19: =VLOOKUP(B19,'EECL Price List'!$A$12:$P$172,2,FALSE) -> Re-energisation during business hours - urban/short rural feeders | F19: =IF(VLOOKUP($B19,'EECL Price List'!$A$12:$P$172,F$1,FALSE)=0,"",VLOOKUP($B19,'EECL Price List'!$A$12:$P$172,F$1,FALSE)) -> REENBHU | G19: =IF(VLOOKUP($B19,'EECL Price List'!$A$12:$P$172,G$1,FALSE)=0,"",VLOOKUP($B19,'EECL Price List'!$A$12:$P$172,G$1,FALSE)) -> REENBHS | J19: =IFERROR(IF(VLOOKUP($C19,'EECL Price List'!$A$12:$P$172,F$1,FALSE)=0,"",VLOOKUP($C19,'EECL Price List'!$A$12:$P$172,F$1,FALSE)),"") -> CFREENBHU | K19: =IFERROR(IF(VLOOKUP($C19,'EECL Price List'!$A$12:$P$172,G$1,FALSE)=0,"",VLOOKUP($C19,'EECL Price List'!$A$12:$P$172,G$1,FALSE)),"") -> CFREENBHS
B20: 16 | C20: 16-CF | E20: =VLOOKUP(B20,'EECL Price List'!$A$12:$P$172,2,FALSE) -> Re-energisation during business hours - after de-energisation for debt - urban/short rural feeders | F20: =IF(VLOOKUP($B20,'EECL Price List'!$A$12:$P$172,F$1,FALSE)=0,"",VLOOKUP($B20,'EECL Price List'!$A$12:$P$172,F$1,FALSE)) -> REDDBHU | G20: =IF(VLOOKUP($B20,'EECL Price List'!$A$12:$P$172,G$1,FALSE)=0,"",VLOOKUP($B20,'EECL Price List'!$A$12:$P$172,G$1,FALSE)) -> REDDBHS | J20: =IFERROR(IF(VLOOKUP($C20,'EECL Price List'!$A$12:$P$172,F$1,FALSE)=0,"",VLOOKUP($C20,'EECL Price List'!$A$12:$P$172,F$1,FALSE)),"") -> CFREDDBHU | K20: =IFERROR(IF(VLOOKUP($C20,'EECL Price List'!$A$12:$P$172,G$1,FALSE)=0,"",VLOOKUP($C20,'EECL Price List'!$A$12:$P$172,G$1,FALSE)),"") -> CFREDDBHS
B21: 18 | E21: =VLOOKUP(B21,'EECL Price List'!$A$12:$P$172,2,FALSE) -> Accreditation of alternative service providers - real estate developments | F21: =IF(VLOOKUP($B21,'EECL Price List'!$A$12:$P$172,F$1,FALSE)=0,"",VLOOKUP($B21,'EECL Price List'!$A$12:$P$172,F$1,FALSE)) -> ASPRED | G21: =IF(VLOOKUP($B21,'EECL Price List'!$A$12:$P$172,G$1,FALSE)=0,"",VLOOKUP($B21,'EECL Price List'!$A$12:$P$172,G$1,FALSE)) | J21: =IFERROR(IF(VLOOKUP($C21,'EECL Price List'!$A$12:$P$172,F$1,FALSE)=0,"",VLOOKUP($C21,'EECL Price List'!$A$12:$P$172,F$1,FALSE)),"") | K21: =IFERROR(IF(VLOOKUP($C21,'EECL Price List'!$A$12:$P$172,G$1,FALSE)=0,"",VLOOKUP($C21,'EECL Price List'!$A$12:$P$172,G$1,FALSE)),"")
B22: 19 | C22: 19-CF | E22: =VLOOKUP(B22,'EECL Price List'!$A$12:$P$172,2,FALSE) -> Install replacement meter (Type 5 and 6) – Single phase – urban/short rural feeder | F22: =IF(VLOOKUP($B22,'EECL Price List'!$A$12:$P$172,F$1,FALSE)=0,"",VLOOKUP($B22,'EECL Price List'!$A$12:$P$172,F$1,FALSE)) -> MSNGLU | G22: =IF(VLOOKUP($B22,'EECL Price List'!$A$12:$P$172,G$1,FALSE)=0,"",VLOOKUP($B22,'EECL Price List'!$A$12:$P$172,G$1,FALSE)) -> MSNGLS | J22: =IFERROR(IF(VLOOKUP($C22,'EECL Price List'!$A$12:$P$172,F$1,FALSE)=0,"",VLOOKUP($C22,'EECL Price List'!$A$12:$P$172,F$1,FALSE)),"") -> CFMSNGLU | K22: =IFERROR(IF(VLOOKUP($C22,'EECL Price List'!$A$12:$P$172,G$1,FALSE)=0,"",VLOOKUP($C22,'EECL Price List'!$A$12:$P$172,G$1,FALSE)),"") -> CFMSNGLS
B23: 21 | C23: 21-CF | E23: =VLOOKUP(B23,'EECL Price List'!$A$12:$P$172,2,FALSE) -> Install replacement meter (Type 5 and 6) – Dual element – urban/short rural feeder | F23: =IF(VLOOKUP($B23,'EECL Price List'!$A$12:$P$172,F$1,FALSE)=0,"",VLOOKUP($B23,'EECL Price List'!$A$12:$P$172,F$1,FALSE)) -> MDUALU | G23: =IF(VLOOKUP($B23,'EECL Price List'!$A$12:$P$172,G$1,FALSE)=0,"",VLOOKUP($B23,'EECL Price List'!$A$12:$P$172,G$1,FALSE)) -> MDUALS | J23: =IFERROR(IF(VLOOKUP($C23,'EECL Price List'!$A$12:$P$172,F$1,FALSE)=0,"",VLOOKUP($C23,'EECL Price List'!$A$12:$P$172,F$1,FALSE)),"") -> CFMDUALU | K23: =IFERROR(IF(VLOOKUP($C23,'EECL Price List'!$A$12:$P$172,G$1,FALSE)=0,"",VLOOKUP($C23,'EECL Price List'!$A$12:$P$172,G$1,FALSE)),"") -> CFMDUALS
B24: 23 | C24: 23-CF | E24: =VLOOKUP(B24,'EECL Price List'!$A$12:$P$172,2,FALSE) -> Install replacement meter (Type 5 and 6) – Polyphase – urban/short rural feeder | F24: =IF(VLOOKUP($B24,'EECL Price List'!$A$12:$P$172,F$1,FALSE)=0,"",VLOOKUP($B24,'EECL Price List'!$A$12:$P$172,F$1,FALSE)) -> MTHREU | G24: =IF(VLOOKUP($B24,'EECL Price List'!$A$12:$P$172,G$1,FALSE)=0,"",VLOOKUP($B24,'EECL Price List'!$A$12:$P$172,G$1,FALSE)) -> MTHRES | J24: =IFERROR(IF(VLOOKUP($C24,'EECL Price List'!$A$12:$P$172,F$1,FALSE)=0,"",VLOOKUP($C24,'EECL Price List'!$A$12:$P$172,F$1,FALSE)),"") -> CFMTHREU | K24: =IFERROR(IF(VLOOKUP($C24,'EECL Price List'!$A$12:$P$172,G$1,FALSE)=0,"",VLOOKUP($C24,'EECL Price List'!$A$12:$P$172,G$1,FALSE)),"") -> CFMTHRES
B25: 25 | C25: 25-CF | E25: =VLOOKUP(B25,'EECL Price List'!$A$12:$P$172,2,FALSE) -> Install replacement meter (CT) – urban/short rural feeder | F25: =IF(VLOOKUP($B25,'EECL Price List'!$A$12:$P$172,F$1,FALSE)=0,"",VLOOKUP($B25,'EECL Price List'!$A$12:$P$172,F$1,FALSE)) -> MCTU | G25: =IF(VLOOKUP($B25,'EECL Price List'!$A$12:$P$172,G$1,FALSE)=0,"",VLOOKUP($B25,'EECL Price List'!$A$12:$P$172,G$1,FALSE)) -> MCTS | J25: =IFERROR(IF(VLOOKUP($C25,'EECL Price List'!$A$12:$P$172,F$1,FALSE)=0,"",VLOOKUP($C25,'EECL Price List'!$A$12:$P$172,F$1,FALSE)),"") -> CFMCTU | K25: =IFERROR(IF(VLOOKUP($C25,'EECL Price List'!$A$12:$P$172,G$1,FALSE)=0,"",VLOOKUP($C25,'EECL Price List'!$A$12:$P$172,G$1,FALSE)),"") -> CFMCTS
B26: 140 | C26: 157-CF | E26: =VLOOKUP(B26,'EECL Price List'!$A$12:$P$172,2,FALSE) -> Install new meter (Type 5 and 6) – Single phase – Primary | F26: =IF(VLOOKUP($B26,'EECL Price List'!$A$12:$P$172,F$1,FALSE)=0,"",VLOOKUP($B26,'EECL Price List'!$A$12:$P$172,F$1,FALSE)) -> NMSPU | G26: =IF(VLOOKUP($B26,'EECL Price List'!$A$12:$P$172,G$1,FALSE)=0,"",VLOOKUP($B26,'EECL Price List'!$A$12:$P$172,G$1,FALSE)) -> NMSPS | J26: =IFERROR(IF(VLOOKUP($C26,'EECL Price List'!$A$12:$P$172,F$1,FALSE)=0,"",VLOOKUP($C26,'EECL Price List'!$A$12:$P$172,F$1,FALSE)),"") -> CFNMSPU | K26: =IFERROR(IF(VLOOKUP($C26,'EECL Price List'!$A$12:$P$172,G$1,FALSE)=0,"",VLOOKUP($C26,'EECL Price List'!$A$12:$P$172,G$1,FALSE)),"") -> CFNMSPS
B27: 141 | C27: 157-CF | E27: =VLOOKUP(B27,'EECL Price List'!$A$12:$P$172,2,FALSE) -> Install new meter (Type 5 and 6) – Single phase – Primary plus embedded generation | F27: =IF(VLOOKUP($B27,'EECL Price List'!$A$12:$P$172,F$1,FALSE)=0,"",VLOOKUP($B27,'EECL Price List'!$A$12:$P$172,F$1,FALSE)) -> NMSPEGU | G27: =IF(VLOOKUP($B27,'EECL Price List'!$A$12:$P$172,G$1,FALSE)=0,"",VLOOKUP($B27,'EECL Price List'!$A$12:$P$172,G$1,FALSE)) -> NMSPEGS | J27: =IFERROR(IF(VLOOKUP($C27,'EECL Price List'!$A$12:$P$172,F$1,FALSE)=0,"",VLOOKUP($C27,'EECL Price List'!$A$12:$P$172,F$1,FALSE)),"") -> CFNMSPU | K27: =IFERROR(IF(VLOOKUP($C27,'EECL Price List'!$A$12:$P$172,G$1,FALSE)=0,"",VLOOKUP($C27,'EECL Price List'!$A$12:$P$172,G$1,FALSE)),"") -> CFNMSPS
B28: 142 | C28: 158-CF | E28: =VLOOKUP(B28,'EECL Price List'!$A$12:$P$172,2,FALSE) -> Install new meter (Type 5 and 6) – Dual element – Primary plus controlled load | F28: =IF(VLOOKUP($B28,'EECL Price List'!$A$12:$P$172,F$1,FALSE)=0,"",VLOOKUP($B28,'EECL Price List'!$A$12:$P$172,F$1,FALSE)) -> NMDPCLU | G28: =IF(VLOOKUP($B28,'EECL Price List'!$A$12:$P$172,G$1,FALSE)=0,"",VLOOKUP($B28,'EECL Price List'!$A$12:$P$172,G$1,FALSE)) -> NMDPCLS | J28: =IFERROR(IF(VLOOKUP($C28,'EECL Price List'!$A$12:$P$172,F$1,FALSE)=0,"",VLOOKUP($C28,'EECL Price List'!$A$12:$P$172,F$1,FALSE)),"") -> CFNMDUALU | K28: =IFERROR(IF(VLOOKUP($C28,'EECL Price List'!$A$12:$P$172,G$1,FALSE)=0,"",VLOOKUP($C28,'EECL Price List'!$A$12:$P$172,G$1,FALSE)),"") -> CFNMDUALS
B29: 143 | C29: 158-CF | E29: =VLOOKUP(B29,'EECL Price List'!$A$12:$P$172,2,FALSE) -> Install new meter (Type 5 and 6) – Dual element – Primary plus controlled load plus embedded generation | F29: =IF(VLOOKUP($B29,'EECL Price List'!$A$12:$P$172,F$1,FALSE)=0,"",VLOOKUP($B29,'EECL Price List'!$A$12:$P$172,F$1,FALSE)) -> NMDPCLEGU | G29: =IF(VLOOKUP($B29,'EECL Price List'!$A$12:$P$172,G$1,FALSE)=0,"",VLOOKUP($B29,'EECL Price List'!$A$12:$P$172,G$1,FALSE)) -> NMDPCLEGS | J29: =IFERROR(IF(VLOOKUP($C29,'EECL Price List'!$A$12:$P$172,F$1,FALSE)=0,"",VLOOKUP($C29,'EECL Price List'!$A$12:$P$172,F$1,FALSE)),"") -> CFNMDUALU | K29: =IFERROR(IF(VLOOKUP($C29,'EECL Price List'!$A$12:$P$172,G$1,FALSE)=0,"",VLOOKUP($C29,'EECL Price List'!$A$12:$P$172,G$1,FALSE)),"") -> CFNMDUALS
B30: 144 | C30: 159-CF | E30: =VLOOKUP(B30,'EECL Price List'!$A$12:$P$172,2,FALSE) -> Install new meter (Type 5 and 6) – Polyphase – Primary | F30: =IF(VLOOKUP($B30,'EECL Price List'!$A$12:$P$172,F$1,FALSE)=0,"",VLOOKUP($B30,'EECL Price List'!$A$12:$P$172,F$1,FALSE)) -> NMPPU | G30: =IF(VLOOKUP($B30,'EECL Price List'!$A$12:$P$172,G$1,FALSE)=0,"",VLOOKUP($B30,'EECL Price List'!$A$12:$P$172,G$1,FALSE)) -> NMPPS | J30: =IFERROR(IF(VLOOKUP($C30,'EECL Price List'!$A$12:$P$172,F$1,FALSE)=0,"",VLOOKUP($C30,'EECL Price List'!$A$12:$P$172,F$1,FALSE)),"") -> CFNMTHREU | K30: =IFERROR(IF(VLOOKUP($C30,'EECL Price List'!$A$12:$P$172,G$1,FALSE)=0,"",VLOOKUP($C30,'EECL Price List'!$A$12:$P$172,G$1,FALSE)),"") -> CFNMTHRES
B31: 145 | C31: 159-CF | E31: =VLOOKUP(B31,'EECL Price List'!$A$12:$P$172,2,FALSE) -> Install new meter (Type 5 and 6) – Polyphase – Primary plus embedded generation | F31: =IF(VLOOKUP($B31,'EECL Price List'!$A$12:$P$172,F$1,FALSE)=0,"",VLOOKUP($B31,'EECL Price List'!$A$12:$P$172,F$1,FALSE)) -> NMPPEGU | G31: =IF(VLOOKUP($B31,'EECL Price List'!$A$12:$P$172,G$1,FALSE)=0,"",VLOOKUP($B31,'EECL Price List'!$A$12:$P$172,G$1,FALSE)) -> NMPPEGS | J31: =IFERROR(IF(VLOOKUP($C31,'EECL Price List'!$A$12:$P$172,F$1,FALSE)=0,"",VLOOKUP($C31,'EECL Price List'!$A$12:$P$172,F$1,FALSE)),"") -> CFNMTHREU | K31: =IFERROR(IF(VLOOKUP($C31,'EECL Price List'!$A$12:$P$172,G$1,FALSE)=0,"",VLOOKUP($C31,'EECL Price List'!$A$12:$P$172,G$1,FALSE)),"") -> CFNMTHRES
B32: 146 | C32: 160-CF | E32: =VLOOKUP(B32,'EECL Price List'!$A$12:$P$172,2,FALSE) -> Install new meter (CT) – Primary | F32: =IF(VLOOKUP($B32,'EECL Price List'!$A$12:$P$172,F$1,FALSE)=0,"",VLOOKUP($B32,'EECL Price List'!$A$12:$P$172,F$1,FALSE)) -> NMCTPU | G32: =IF(VLOOKUP($B32,'EECL Price List'!$A$12:$P$172,G$1,FALSE)=0,"",VLOOKUP($B32,'EECL Price List'!$A$12:$P$172,G$1,FALSE)) -> NMCTPS | J32: =IFERROR(IF(VLOOKUP($C32,'EECL Price List'!$A$12:$P$172,F$1,FALSE)=0,"",VLOOKUP($C32,'EECL Price List'!$A$12:$P$172,F$1,FALSE)),"") -> CFNMCTU | K32: =IFERROR(IF(VLOOKUP($C32,'EECL Price List'!$A$12:$P$172,G$1,FALSE)=0,"",VLOOKUP($C32,'EECL Price List'!$A$12:$P$172,G$1,FALSE)),"") -> CFNMCTS
B33: 147 | C33: 160-CF | E33: =VLOOKUP(B33,'EECL Price List'!$A$12:$P$172,2,FALSE) -> Install new meter (CT) – Primary plus embedded generation | F33: =IF(VLOOKUP($B33,'EECL Price List'!$A$12:$P$172,F$1,FALSE)=0,"",VLOOKUP($B33,'EECL Price List'!$A$12:$P$172,F$1,FALSE)) -> NMCTPEGU | G33: =IF(VLOOKUP($B33,'EECL Price List'!$A$12:$P$172,G$1,FALSE)=0,"",VLOOKUP($B33,'EECL Price List'!$A$12:$P$172,G$1,FALSE)) -> NMCTPEGS | J33: =IFERROR(IF(VLOOKUP($C33,'EECL Price List'!$A$12:$P$172,F$1,FALSE)=0,"",VLOOKUP($C33,'EECL Price List'!$A$12:$P$172,F$1,FALSE)),"") -> CFNMCTU | K33: =IFERROR(IF(VLOOKUP($C33,'EECL Price List'!$A$12:$P$172,G$1,FALSE)=0,"",VLOOKUP($C33,'EECL Price List'!$A$12:$P$172,G$1,FALSE)),"") -> CFNMCTS
... B42: 156 | C42: 160-CF | E42: =VLOOKUP(B42,'EECL Price List'!$A$12:$P$172,2,FALSE) -> Install new meter (CT) to accommodate embedded generation installation | F42: =IF(VLOOKUP($B42,'EECL Price List'!$A$12:$P$172,F$1,FALSE)=0,"",VLOOKUP($B42,'EECL Price List'!$A$12:$P$172,F$1,FALSE)) -> NCTAEGU | G42: =IF(VLOOKUP($B42,'EECL Price List'!$A$12:$P$172,G$1,FALSE)=0,"",VLOOKUP($B42,'EECL Price List'!$A$12:$P$172,G$1,FALSE)) -> NCTAEGS | J42: =IFERROR(IF(VLOOKUP($C42,'EECL Price List'!$A$12:$P$172,F$1,FALSE)=0,"",VLOOKUP($C42,'EECL Price List'!$A$12:$P$172,F$1,FALSE)),"") -> CFNMCTU | K42: =IFERROR(IF(VLOOKUP($C42,'EECL Price List'!$A$12:$P$172,G$1,FALSE)=0,"",VLOOKUP($C42,'EECL Price List'!$A$12:$P$172,G$1,FALSE)),"") -> CFNMCTS
B43: 1 | D43: Fee based services (long rural/isolated) | E43: =VLOOKUP(B43,'EECL Price List'!$A$12:$P$172,2,FALSE) -> Application fee - Basic or standard connection | F43: =IF(VLOOKUP($B43,'EECL Price List'!$A$12:$P$172,F$1,FALSE)=0,"",VLOOKUP($B43,'EECL Price List'!$A$12:$P$172,F$1,FALSE)) -> APFSAC | G43: =IF(VLOOKUP($B43,'EECL Price List'!$A$12:$P$172,I$1,FALSE)=0,"",VLOOKUP($B43,'EECL Price List'!$A$12:$P$172,I$1,FALSE))
B44: 2 | E44: =VLOOKUP(B44,'EECL Price List'!$A$12:$P$172,2,FALSE) -> Application fee - Basic or standard connection - Micro-embedded generators | F44: =IF(VLOOKUP($B44,'EECL Price List'!$A$12:$P$172,F$1,FALSE)=0,"",VLOOKUP($B44,'EECL Price List'!$A$12:$P$172,F$1,FALSE)) -> APFMEG | G44: =IF(VLOOKUP($B44,'EECL Price List'!$A$12:$P$172,I$1,FALSE)=0,"",VLOOKUP($B44,'EECL Price List'!$A$12:$P$172,I$1,FALSE))
B45: 3 | E45: =VLOOKUP(B45,'EECL Price List'!$A$12:$P$172,2,FALSE) -> Application fee - Basic or standard connection - Micro-embedded generators - Technical assessment required | F45: =IF(VLOOKUP($B45,'EECL Price List'!$A$12:$P$172,F$1,FALSE)=0,"",VLOOKUP($B45,'EECL Price List'!$A$12:$P$172,F$1,FALSE)) -> APFMTA | G45: =IF(VLOOKUP($B45,'EECL Price List'!$A$12:$P$172,I$1,FALSE)=0,"",VLOOKUP($B45,'EECL Price List'!$A$12:$P$172,I$1,FALSE))
B46: 4 | E46: =VLOOKUP(B46,'EECL Price List'!$A$12:$P$172,2,FALSE) -> Application fee - Real estate development connection | F46: =IF(VLOOKUP($B46,'EECL Price List'!$A$12:$P$172,F$1,FALSE)=0,"",VLOOKUP($B46,'EECL Price List'!$A$12:$P$172,F$1,FALSE)) -> APFRED | G46: =IF(VLOOKUP($B46,'EECL Price List'!$A$12:$P$172,I$1,FALSE)=0,"",VLOOKUP($B46,'EECL Price List'!$A$12:$P$172,I$1,FALSE))
B47: 5 | E47: =VLOOKUP(B47,'EECL Price List'!$A$12:$P$172,2,FALSE) -> Protection and Power Quality assessment prior to connection | F47: =IF(VLOOKUP($B47,'EECL Price List'!$A$12:$P$172,F$1,FALSE)=0,"",VLOOKUP($B47,'EECL Price List'!$A$12:$P$172,F$1,FALSE)) -> PPQA | G47: =IF(VLOOKUP($B47,'EECL Price List'!$A$12:$P$172,I$1,FALSE)=0,"",VLOOKUP($B47,'EECL Price List'!$A$12:$P$172,I$1,FALSE))
B48: 7 | C48: 7-CF | E48: =VLOOKUP(B48,'EECL Price List'!$A$12:$P$172,2,FALSE) -> Temporary connection, not in permanent position - single phase metered - long rural/isolated feeders | F48: =IF(VLOOKUP($B48,'EECL Price List'!$A$12:$P$172,H$1,FALSE)=0,"",VLOOKUP($B48,'EECL Price List'!$A$12:$P$172,H$1,FALSE)) -> TBSSPL | G48: =IF(VLOOKUP($B48,'EECL Price List'!$A$12:$P$172,I$1,FALSE)=0,"",VLOOKUP($B48,'EECL Price List'!$A$12:$P$172,I$1,FALSE)) -> TBSSPI | J48: =IF(VLOOKUP($C48,'EECL Price List'!$A$12:$P$172,H$1,FALSE)=0,"",VLOOKUP($C48,'EECL Price List'!$A$12:$P$172,H$1,FALSE)) -> CFTBSSPL | K48: =IF(VLOOKUP($C48,'EECL Price List'!$A$12:$P$172,I$1,FALSE)=0,"",VLOOKUP($C48,'EECL Price List'!$A$12:$P$172,I$1,FALSE)) -> CFTBSSPI
B49: 9 | C49: 9-CF | E49: =VLOOKUP(B49,'EECL Price List'!$A$12:$P$172,2,FALSE) -> Temporary connection, not in permanent position - multi phase metered - long rural/isolated feeders | F49: =IF(VLOOKUP($B49,'EECL Price List'!$A$12:$P$172,H$1,FALSE)=0,"",VLOOKUP($B49,'EECL Price List'!$A$12:$P$172,H$1,FALSE)) -> TBSMPL | G49: =IF(VLOOKUP($B49,'EECL Price List'!$A$12:$P$172,I$1,FALSE)=0,"",VLOOKUP($B49,'EECL Price List'!$A$12:$P$172,I$1,FALSE)) -> TBSMPI | J49: =IF(VLOOKUP($C49,'EECL Price List'!$A$12:$P$172,H$1,FALSE)=0,"",VLOOKUP($C49,'EECL Price List'!$A$12:$P$172,H$1,FALSE)) -> CFTBSMPL | K49: =IF(VLOOKUP($C49,'EECL Price List'!$A$12:$P$172,I$1,FALSE)=0,"",VLOOKUP($C49,'EECL Price List'!$A$12:$P$172,I$1,FALSE)) -> CFTBSMPI
B50: 11 | C50: 11-CF | E50: =VLOOKUP(B50,'EECL Price List'!$A$12:$P$172,2,FALSE) -> Supply abolishment during business hours - long rural/isolated feeders | F50: =IF(VLOOKUP($B50,'EECL Price List'!$A$12:$P$172,H$1,FALSE)=0,"",VLOOKUP($B50,'EECL Price List'!$A$12:$P$172,H$1,FALSE)) -> SUPABOLL | G50: =IF(VLOOKUP($B50,'EECL Price List'!$A$12:$P$172,I$1,FALSE)=0,"",VLOOKUP($B50,'EECL Price List'!$A$12:$P$172,I$1,FALSE)) -> SUPABOLI | J50: =IF(VLOOKUP($C50,'EECL Price List'!$A$12:$P$172,H$1,FALSE)=0,"",VLOOKUP($C50,'EECL Price List'!$A$12:$P$172,H$1,FALSE)) -> CFSUPABOLL | K50: =IF(VLOOKUP($C50,'EECL Price List'!$A$12:$P$172,I$1,FALSE)=0,"",VLOOKUP($C50,'EECL Price List'!$A$12:$P$172,I$1,FALSE)) -> CFSUPABOLI
B51: 13 | C51: 13-CF | E51: =VLOOKUP(B51,'EECL Price List'!$A$12:$P$172,2,FALSE) -> De-energisation during business hours - long rural/isolated feeders | F51: =IF(VLOOKUP($B51,'EECL Price List'!$A$12:$P$172,H$1,FALSE)=0,"",VLOOKUP($B51,'EECL Price List'!$A$12:$P$172,H$1,FALSE)) -> DEENBHL | G51: =IF(VLOOKUP($B51,'EECL Price List'!$A$12:$P$172,I$1,FALSE)=0,"",VLOOKUP($B51,'EECL Price List'!$A$12:$P$172,I$1,FALSE)) -> DEENBHI | J51: =IF(VLOOKUP($C51,'EECL Price List'!$A$12:$P$172,H$1,FALSE)=0,"",VLOOKUP($C51,'EECL Price List'!$A$12:$P$172,H$1,FALSE)) -> CFDEENBHL | K51: =IF(VLOOKUP($C51,'EECL Price List'!$A$12:$P$172,I$1,FALSE)=0,"",VLOOKUP($C51,'EECL Price List'!$A$12:$P$172,I$1,FALSE)) -> CFDEENBHI
B52: 15 | C52: 15-CF | E52: =VLOOKUP(B52,'EECL Price List'!$A$12:$P$172,2,FALSE) -> Re-energisation during business hours - long rural/isolated feeders | F52: =IF(VLOOKUP($B52,'EECL Price List'!$A$12:$P$172,H$1,FALSE)=0,"",VLOOKUP($B52,'EECL Price List'!$A$12:$P$172,H$1,FALSE)) -> REENBHL | G52: =IF(VLOOKUP($B52,'EECL Price List'!$A$12:$P$172,I$1,FALSE)=0,"",VLOOKUP($B52,'EECL Price List'!$A$12:$P$172,I$1,FALSE)) -> REENBHI | J52: =IF(VLOOKUP($C52,'EECL Price List'!$A$12:$P$172,H$1,FALSE)=0,"",VLOOKUP($C52,'EECL Price List'!$A$12:$P$172,H$1,FALSE)) -> CFREENBHL | K52: =IF(VLOOKUP($C52,'EECL Price List'!$A$12:$P$172,I$1,FALSE)=0,"",VLOOKUP($C52,'EECL Price List'!$A$12:$P$172,I$1,FALSE)) -> CFREENBHI
...
