Workbook
Name _Hlk318882101: 'ACS Tariff classes & tariffs'!#REF!
Name current_pricing_year: '[1]Model builder'!$E$23
Name JS_final_round: [1]JS!$C$25:$L$34
Name JS_final_round_C: [1]JS!$C$24:$L$24
Name ProdCodes: 'ACS Price List'!$D$13:$G$180

Sheet ACS Price List
B7: Ergon Energy Corporation Limited
B8: 2017-18 Price List for Alternative Control Services | H8: Key: | J8: These services are subject to an additional layer of price regulation at the jurisdictional level, through Schedule 8 of the Electricity Regulation 2006. Even though the national economic regulator (the AER) has approved a higher price that EECL can charge for this service, the Queensland Government has stipulated a (lower) maximum price EECL is able to charge customers in EECL's supply area for these services.
B9: Release 2.0 - 1 December 2017 | D9: Release 0.0 - 1 July 2017 | F9: Release 0.0 - 1 July 2017 | J9: These services are subject to an additional layer of price regulation at the jurisdictional level, through Schedule 8 of the Electricity Regulation 2006. Even though the national economic regulator (the AER) has approved a higher price that EECL can charge for this service, the Queensland Government has stipulated that long rural / isolated customers in EECL's supply area are only able to be charged for these services at the same rate as an urban / short rural customer.
A12: Ref | B12: Service | C12: Service description | D12: Product Codes | H12: Ellipse Cost Code | I12: Urban/short rural feeder price | K12: Long rural/isolated feeder price | M12: AER classification | N12: Notes | O12: B2B Retailer only | P12: Form "A" Required | Q12: B2B Service Order Type
D13: Urban | E13: Short rural | F13: Long rural | G13: Isolated | I13: GST Excl | J13: GST Incl | K13: GST Excl | L13: GST Incl | O13: Customer
A14: Fee Based and Quoted Services
B15: Pre-Connection Services
A16: 1 | B16: Application fee - Basic or standard connection | C16: Services associated with assessing an application requesting a connection to be made (or altered) between Ergon Energy's network and the customer’s installation, and the preparation of a compliant basic or standard connection offer. Applies to small customers classified as a Standard Asset Customer (SAC), as per Ergon Energy's pricing proposal. | D16: APFSAC | H16: 8000 | I16: 888.4 | J16: =I16*1.1 -> 977.24 | K16: =I16 -> 888.4 | L16: =J16 -> 977.24 | M16: Fee Based Service | N16: Fixed fee applies | O16: Customer | P16: No | Q16: N/A
A17: 2 | B17: Application fee - Basic or standard connection - Micro-embedded generators | C17: Services associated with assessing a micro-embedded generator application requesting a connection to be made (or altered) between Ergon Energy's network and the customer’s installation, and the preparation of a compliant basic or standard connection offer. Applies to micro-embedded generators only (a subset of Standard Asset Customers, as per Ergon Energy's pricing proposal). No technical assessment required. | D17: APFMEG | H17: 8001 | I17: 48.6 | J17: =I17*1.1 -> 53.46 | K17: =I17 -> 48.6 | L17: =J17 -> 53.46 | M17: Fee Based Service | N17: Fixed fee applies | O17: Customer | P17: No | Q17: N/A
A18: 3 | B18: Application fee - Basic or standard connection - Micro-embedded generators - Technical assessment required | C18: Services associated with assessing a micro-embedded generator application requesting a connection to be made (or altered) between Ergon Energy's network and the customer’s installation, and the preparation of a compliant basic or standard connection offer. Applies to micro-embedded generators only (a subset of Standard Asset Customers, as per Ergon Energy's pricing proposal), where a technical assessment is required to be undertaken by Ergon Energy. | D18: APFMTA | H18: 8002 | I18: 220.7 | J18: =I18*1.1 -> 242.77 | K18: =I18 -> 220.7 | L18: =J18 -> 242.77 | M18: Fee Based Service | N18: Fixed fee applies | O18: Customer | P18: No | Q18: N/A
A19: 4 | B19: Application fee - Real estate development connection | C19: Services associated with assessing an application requesting a connection to be made between Ergon Energy's network and a real estate developer's installation, and the preparation of a compliant connection offer. Includes works carried out by contractors and/or Ergon Energy. | D19: APFRED | H19: 8003 | I19: 930.2 | J19: =I19*1.1 -> 1023.22 | K19: =I19 -> 930.2 | L19: =J19 -> 1023.22 | M19: Fee Based Service | N19: Fixed fee applies | O19: Customer | P19: No | Q19: N/A
A20: 5 | B20: Protection and Power Quality assessment prior to connection | C20: Evaluation of application protection design for completeness against engineering connection standard. Study of Power Quality issues including Flicker, Harmonics and DC voltage injection. | D20: PPQA | H20: 8004 | I20: 1376.7 | J20: =I20*1.1 -> 1514.37 | K20: =I20 -> 1376.7 | L20: =J20 -> 1514.37 | M20: Fee Based Service | N20: Fixed fee applies | O20: Customer | P20: No | Q20: N/A
A21: 40 | B21: Application fee - Negotiated connection | C21: Services associated with assessing an application requesting a connection to be made (or altered) between Ergon Energy's network and the customer’s installation, and the costs associated with negotiating and preparing a negotiated connection offer. Applies to small customers classified as a Standard Asset Customer (SAC), as per Ergon Energy's pricing proposal, with the exception of micro-embedded generators. | D21: As Quoted | H21: 8005 | I21: POA | K21: POA | M21: Quoted Service | N21: Price on application | O21: Customer | P21: No | Q21: N/A
A22: 41 | B22: Application fee - Negotiated connection - Micro-embedded generators | C22: Services associated with assessing a micro-embedded generator application requesting a connection to be made (or altered) between Ergon Energy's network and the customer’s installation, and the costs associated with negotiating and preparing a negotiated connection offer. Applies to micro-embedded generators only (a subset of SAC, as per Ergon Energy's pricing proposal). | D22: As Quoted | H22: 8006 | I22: POA | K22: POA | M22: Quoted Service | N22: Price on application | O22: Customer | P22: No | Q22: N/A
A23: 42 | B23: Application fee - Negotiated - Major customer connection | C23: Services associated with assessing a major customer connection application requesting a connection to be made (or altered) between Ergon Energy's network and the customer’s installation, and the costs associated with negotiating and preparing a compliant negotiated connection offer. Applies to major customers classified as an Individually Calculated Customer (ICC), Connection Asset Customer (CAC) or Embedded Generator (EG), as per Ergon Energy's pricing proposal. | D23: As Quoted | H23: 8007 | I23: POA | K23: POA | M23: Quoted Service | N23: Price on application | O23: Customer | P23: No | Q23: N/A
A24: 43 | B24: Carrying out planning studies and analysis relating to connection applications | C24: Services associated with carrying out additional planning studies and analysis on the distribution system which are reasonably required to assess a small customer or real estate development connection application. Excludes planning studies and analysis that would otherwise be required for distributor purposes or for the efficient management of the shared network. Applies to small customers classified as a Standard Asset Customer, as per Ergon Energy's pricing proposal (including micro-embedded generators), and real estate developers. | D24: As Quoted | H24: 8008 | I24: POA | K24: POA | M24: Quoted Service | N24: Price on application | O24: Customer | P24: No | Q24: N/A
A25: 44 | B25: Feasibility and concept scoping, including planning and design, for major customer connections | C25: Detailed design and advice for major customer connections for the selected (preferred) connection option. This includes shared network planning and design works incurred during the feasibility and concept scoping phases (i.e. before the connection offer has been accepted) (where applicable). | D25: As Quoted | H25: 8009 | I25: POA | K25: POA | M25: Quoted Service | N25: Price on application | O25: Customer | P25: No | Q25: N/A
A26: 45 | B26: Tender process | C26: Applies where Ergon Energy conducts a tender process on behalf of a connection applicant to procure connection services that can be provided by a third party, or where the connection applicant conducts a tender process and requires assistance from Ergon Energy | D26: As Quoted | H26: 8010 | I26: POA | K26: POA | M26: Quoted Service | N26: Price on application | O26: Customer | P26: No | Q26: N/A
A27: 46 | B27: Pre-connection site inspection | C27: Site inspection in order to determine nature of connection being sought | D27: As Quoted | H27: 8011 | I27: POA | K27: POA | M27: Quoted Service | N27: Price on application | O27: Customer | P27: No | Q27: N/A
A28: 47 | B28: Provision of site-specific connection information and advice | C28: Provision of site-specific connection advice, data and/or information on request (during the connection enquiry and/or connection application stage only). For example: - advice on project feasibility - advice on whether augmentation would likely be required - capacity information, including specific network capacity - load profiles for load flow studies - requests to review reports and designs prepared by external consultants, prior to lodgement of connection application - additional or more detailed specification and design options. Excludes information provided in planning reports/studies and project scopes. | D28: As Quoted | H28: 8012 | I28: POA | K28: POA | M28: Quoted Service | N28: Price on application | O28: Customer | P28: No | Q28: N/A
A29: 48 | B29: Preparation of preliminary designs and planning reports for major customer connections, including project scopes and estimates | C29: Initial specification and design outline for major customer connections. Includes general evaluation and advice on asset ownership options, indicative estimates of viable connection options, and recommendation on the most suitable option. | D29: As Quoted | H29: 8013 | I29: POA | K29: POA | M29: Quoted Service | N29: Price on application | O29: Customer | P29: No | Q29: N/A
A30: 49 | B30: Customer build, own and operate consultation services | C30: Provision of advice, design and specification on request to an applicant considering a build-own-operate asset ownership option for connection assets. | D30: As Quoted | H30: 8014 | I30: POA | K30: POA | M30: Quoted Service | N30: Price on application | O30: Customer | P30: No | Q30: N/A
A31: 50 | B31: Detailed enquiry response fee - embedded generation | C31: Costs associated with preparing a detailed enquiry response pursuant to Chapter 5 of the NER. Applies to any embedded generation connection applicant that submits an enquiry under the connection process set out in Chapter 5 of the NER and seeks a detailed enquiry response. | D31: As Quoted | H31: 8015 | I31: POA | K31: POA | M31: Quoted Service | N31: Price on application | O31: Customer | P31: No | Q31: N/A
B32: Connection Services
A33: 6 | B33: Temporary connection, not in permanent position - single phase metered - urban/short rural feeders | C33: Connection of a single phase supply to a meter location that is not permanent (i.e. short term supply). Excludes work on metering equipment. | D33: TBSSPU | E33: TBSSPS | H33: 8020 | I33: 330.2 | J33: =I33*1.1 -> 363.22 | M33: Fee Based Service | N33: Fixed fee applies. Aggregate of this service and #161-M capped to maximum specified in Schedule 8 of Electricity Regulation 2006 | O33: B2B Retailer only | P33: Yes | Q33: Supply Service Works (SSW) - Establish Temporary Supply
A34: 6-CF | B34: Call out fee for temporary connection, not in permanent position - single phase metered - urban/short rural feeders | C34: Travel time to perform a temporary connection, requested by a retailer or customer, and the service is unable to be performed due to customer/retailer fault. | D34: CFTBSSPU | E34: CFTBSSPS | H34: 8021 | I34: 116.9 | J34: =I34*1.1 -> 128.59 | M34: Fee Based Service | N34: Fixed fee applies | O34: B2B Retailer only | P34: N/A | Q34: N/A
A35: 7 | B35: Temporary connection, not in permanent position - single phase metered - long rural/isolated feeders | C35: Connection of a single phase supply to a meter location that is not permanent (i.e. short term supply). Excludes work on metering equipment. | F35: TBSSPL | G35: TBSSPI | H35: 8022 | K35: 330.2 | L35: =K35*1.1 -> 363.22 | M35: Fee Based Service | N35: Fixed fee applies. Aggregate of this service and #161-M capped to maximum specified in Schedule 8 of Electricity Regulation 2006 | O35: B2B Retailer only | P35: Yes | Q35: Supply Service Works (SSW) - Establish Temporary Supply
A36: 7-CF | B36: Call out fee for temporary connection, not in permanent position - single phase metered - long rural/isolated feeders | C36: Travel time to perform a temporary connection requested by a retailer or customer, and the service is unable to be performed due to customer/retailer fault. | F36: CFTBSSPL | G36: CFTBSSPI | H36: 8023 | K36: 330.2 | L36: =K36*1.1 -> 363.22 | M36: Fee Based Service | N36: Fixed fee applies, capped to the maximum price of the associated service (to be consistent with Schedule 8 of Electricity Regulation 2006) | O36: B2B Retailer only | P36: N/A | Q36: N/A
A37: 8 | B37: Temporary connection, not in permanent position - multi phase metered - urban/short rural feeders | C37: Connection of a multi phase supply to a meter location that is not permanent (i.e. short term supply). Excludes work on metering equipment. | D37: TBSMPU | E37: TBSMPS | H37: 8024 | I37: 330.2 | J37: =I37*1.1 -> 363.22 | M37: Fee Based Service | N37: Fixed fee applies. Aggregate of this service and #161-M capped to maximum specified in Schedule 8 of Electricity Regulation 2006 | O37: B2B Retailer only | P37: Yes | Q37: Supply Service Works (SSW) - Establish Temporary Supply
A38: 8-CF | B38: Call out fee for temporary connection, not in permanent position - multi-phase metered - urban/short rural feeders | C38: Travel time to perform a temporary connection requested by a retailer or customer, and the service is unable to be performed due to customer/retailer fault. | D38: CFTBSMPU | E38: CFTBSMPS | H38: 8025 | I38: 116.9 | J38: =I38*1.1 -> 128.59 | M38: Fee Based Service | N38: Fixed fee applies | O38: B2B Retailer only | P38: N/A | Q38: N/A
A39: 9 | B39: Temporary connection, not in permanent position - multi phase metered - long rural/isolated feeders | C39: Connection of a multi phase supply to a meter location that is not permanent (i.e. short term supply). Excludes work on metering equipment. | F39: TBSMPL | G39: TBSMPI | H39: 8026 | K39: 330.2 | L39: =K39*1.1 -> 363.22 | M39: Fee Based Service | N39: Fixed fee applies. Aggregate of this service and #161-M capped to maximum specified in Schedule 8 of Electricity Regulation 2006 | O39: B2B Retailer only | P39: Yes | Q39: Supply Service Works (SSW) - Establish Temporary Supply
A40: 9-CF | B40: Call out fee for temporary connection, not in permanent position - multi-phase metered - long rural/isolated feeders | C40: Travel time to perform a temporary connection requested by a retailer or customer, and the service is unable to be performed due to customer/retailer fault. | F40: CFTBSMPL | G40: CFTBSMPI | H40: 8027 | K40: 330.2 | L40: =K40*1.1 -> 363.22 | M40: Fee Based Service | N40: Fixed fee applies, capped to the maximum price of the associated service (to be consistent with Schedule 8 of Electricity Regulation 2006) | O40: B2B Retailer only | P40: N/A | Q40: N/A
A41: 161-M | B41: Work on metering equipment for temporary connection, not in permanent position - single phase or multi phase metered | C41: Work on metering equipment undertaken by Ergon Energy to accommodate a temporary connection. Note: this service is only available for non-grid connected areas of our network (isolated feeders and the Mount Isa-Cloncurry supply network). | D41: MTBSU | E41: MTBSS | F41: MTBSL | G41: MTBSI | H41: 8033 | I41: 82.5 | J41: =I41*1.1 -> 90.75 | K41: 82.5 | L41: =K41*1.1 -> 90.75 | M41: Fee Based Service | N41: Fixed fee applies. Aggregate of this service and relevant temporary connection service capped to maximum specified in Schedule 8 of Electricity Regulation 2006 | O41: B2B Retailer only | P41: Yes | Q41: Supply Service Works (SSW) - Establish Temporary Supply
A42: 51 | B42: Design and construction of connection assets for major customers | C42: Detailed design work and construction of connection assets after a connection offer has been made. Applies to major customers classified as an Individually Calculated Customer (ICC), Connection Asset Customer (CAC) or Embedded Generator (EG) as per Ergon Energy's pricing proposal. | D42: As Quoted | H42: 8028 | I42: POA | K42: POA | M42: Quoted Service | N42: Price on application | O42: Customer | P42: No | Q42: N/A
A43: 52 | B43: Commissioning and energisation of major customer connections | C43: Includes: - inspection and testing of connection assets prior to physical connection to the network - physical connection and energisation of electricity equipment to allow conveyance of electricity - administration services involved in reconciling the financials of a connection project, and processing and finalising network information and contracts in relation to a connection - generation required (if any) to supply existing customers while equipment is de-energised to allow testing and commissioning Applies to major customers classified as an Individually Calculated Customer (ICC), Connection Asset Customer (CAC) or Embedded Generator (EG) as per Ergon Energy's pricing proposal. | D43: As Quoted | H43: 8029 | I43: POA | K43: POA | M43: Quoted Service | N43: Price on application | O43: Customer | P43: No | Q43: N/A
A44: 53 | B44: Design and construction for real estate developments | C44: Detailed design work and construction for a real estate development connection after a connection offer has been made. Includes work associated with augmentation to the shared network which is directly attributable to the establishment or alteration of the real estate development connection | D44: As Quoted | H44: 8030 | I44: POA | K44: POA | M44: Quoted Service | N44: Price on application | O44: Customer | P44: No | Q44: N/A
A45: 54 | B45: Commissioning and energisation of real estate development connections | C45: Includes: - inspection and testing prior to physical connection to the network - physical connection and energisation of electricity equipment to allow conveyance of electricity - administration services involved in reconciling the financials of a connection project, and processing and finalising network information and contracts in relation to a connection - generation required (if any) to supply existing customers while equipment is de-energised to allow testing and commissioning | D45: As Quoted | H45: 8031 | I45: POA | K45: POA | M45: Quoted Service | N45: Price on application | O45: Customer | P45: Yes | Q45: N/A
A46: 55 | B46: Removal of network constraint for embedded generator | C46: Augmenting the network to remove a constraint faced by an embedded generator | D46: As Quoted | H46: 8032 | I46: POA | K46: POA | M46: Quoted Service | N46: Price on application | O46: Customer | P46: No | Q46: N/A
B47: Post Connection Services
A48: 10 | B48: Supply abolishment during business hours - urban/short rural feeders | C48: Retailer requests Ergon Energy to abolish supply at a connection point and decommission a NMI. May be used where a property is to be demolished; supply is no longer required; an alternative connection point is to be used; or a redundant supply is to be removed. Excludes decommissioning of metering undertaken by Ergon Energy or an alternative provider. | D48: SUPABOLU | E48: SUPABOLS | H48: 8040 | I48: 292.4 | J48: =I48*1.1 -> 321.64 | M48: Fee Based Service | N48: Fixed fee applies | O48: B2B Retailer only | P48: No | Q48: Supply Service Works (SSW) - Supply Abolishment
...

Sheet ACS Tariff classes & tariffs
G1: 4 | H1: 5 | I1: 6 | J1: 7
E3: Ergon Energy Corporation Limited
E4: 2017-18 ACS tariffs by tariff class
E8: Tariff class | F8: Tariff | G8: Product Codes
G9: Service undertaken | O9: No service undertaken due to fault of another party (Call out fee)
G10: Primary Service | K10: Metering Component (MC Fee) | O10: (Call out fee)
B11: 1 | E11: Fee based services (urban/short rural) | F11: =VLOOKUP(B11,'ACS Price List'!$A$12:$P$180,2,FALSE) -> Application fee - Basic or standard connection | G11: =IF(VLOOKUP($B11,'ACS Price List'!$A$12:$P$180,G$1,FALSE)=0,"",VLOOKUP($B11,'ACS Price List'!$A$12:$P$180,G$1,FALSE)) -> APFSAC | H11: =IF(VLOOKUP($B11,'ACS Price List'!$A$12:$P$180,H$1,FALSE)=0,"",VLOOKUP($B11,'ACS Price List'!$A$12:$P$180,H$1,FALSE)) | K11: =IFERROR(IF(VLOOKUP($C11,'ACS Price List'!$A$12:$P$180,G$1,FALSE)=0,"",VLOOKUP($C11,'ACS Price List'!$A$12:$P$180,G$1,FALSE)),"") | L11: =IFERROR(IF(VLOOKUP($C11,'ACS Price List'!$A$12:$P$180,H$1,FALSE)=0,"",VLOOKUP($C11,'ACS Price List'!$A$12:$P$180,H$1,FALSE)),"") | O11: =IFERROR(IF(VLOOKUP($D11,'ACS Price List'!$A$12:$P$180,G$1,FALSE)=0,"",VLOOKUP($D11,'ACS Price List'!$A$12:$P$180,G$1,FALSE)),"") | P11: =IFERROR(IF(VLOOKUP($D11,'ACS Price List'!$A$12:$P$180,H$1,FALSE)=0,"",VLOOKUP($D11,'ACS Price List'!$A$12:$P$180,H$1,FALSE)),"") | U11: =COUNTA(G11:G45,H16:H23,K16:K18,L16:L18,O16:P23,O25:P45,H25:H45) -> 128
B12: 2 | F12: =VLOOKUP(B12,'ACS Price List'!$A$12:$P$180,2,FALSE) -> Application fee - Basic or standard connection - Micro-embedded generators | G12: =IF(VLOOKUP($B12,'ACS Price List'!$A$12:$P$180,G$1,FALSE)=0,"",VLOOKUP($B12,'ACS Price List'!$A$12:$P$180,G$1,FALSE)) -> APFMEG | H12: =IF(VLOOKUP($B12,'ACS Price List'!$A$12:$P$180,H$1,FALSE)=0,"",VLOOKUP($B12,'ACS Price List'!$A$12:$P$180,H$1,FALSE)) | K12: =IFERROR(IF(VLOOKUP($C12,'ACS Price List'!$A$12:$P$180,G$1,FALSE)=0,"",VLOOKUP($C12,'ACS Price List'!$A$12:$P$180,G$1,FALSE)),"") | L12: =IFERROR(IF(VLOOKUP($C12,'ACS Price List'!$A$12:$P$180,H$1,FALSE)=0,"",VLOOKUP($C12,'ACS Price List'!$A$12:$P$180,H$1,FALSE)),"") | O12: =IFERROR(IF(VLOOKUP($D12,'ACS Price List'!$A$12:$P$180,G$1,FALSE)=0,"",VLOOKUP($D12,'ACS Price List'!$A$12:$P$180,G$1,FALSE)),"") | P12: =IFERROR(IF(VLOOKUP($D12,'ACS Price List'!$A$12:$P$180,H$1,FALSE)=0,"",VLOOKUP($D12,'ACS Price List'!$A$12:$P$180,H$1,FALSE)),"")
B13: 3 | F13: =VLOOKUP(B13,'ACS Price List'!$A$12:$P$180,2,FALSE) -> Application fee - Basic or standard connection - Micro-embedded generators - Technical assessment required | G13: =IF(VLOOKUP($B13,'ACS Price List'!$A$12:$P$180,G$1,FALSE)=0,"",VLOOKUP($B13,'ACS Price List'!$A$12:$P$180,G$1,FALSE)) -> APFMTA | H13: =IF(VLOOKUP($B13,'ACS Price List'!$A$12:$P$180,H$1,FALSE)=0,"",VLOOKUP($B13,'ACS Price List'!$A$12:$P$180,H$1,FALSE)) | K13: =IFERROR(IF(VLOOKUP($C13,'ACS Price List'!$A$12:$P$180,G$1,FALSE)=0,"",VLOOKUP($C13,'ACS Price List'!$A$12:$P$180,G$1,FALSE)),"") | L13: =IFERROR(IF(VLOOKUP($C13,'ACS Price List'!$A$12:$P$180,H$1,FALSE)=0,"",VLOOKUP($C13,'ACS Price List'!$A$12:$P$180,H$1,FALSE)),"") | O13: =IFERROR(IF(VLOOKUP($D13,'ACS Price List'!$A$12:$P$180,G$1,FALSE)=0,"",VLOOKUP($D13,'ACS Price List'!$A$12:$P$180,G$1,FALSE)),"") | P13: =IFERROR(IF(VLOOKUP($D13,'ACS Price List'!$A$12:$P$180,H$1,FALSE)=0,"",VLOOKUP($D13,'ACS Price List'!$A$12:$P$180,H$1,FALSE)),"")
B14: 4 | F14: =VLOOKUP(B14,'ACS Price List'!$A$12:$P$180,2,FALSE) -> Application fee - Real estate development connection | G14: =IF(VLOOKUP($B14,'ACS Price List'!$A$12:$P$180,G$1,FALSE)=0,"",VLOOKUP($B14,'ACS Price List'!$A$12:$P$180,G$1,FALSE)) -> APFRED | H14: =IF(VLOOKUP($B14,'ACS Price List'!$A$12:$P$180,H$1,FALSE)=0,"",VLOOKUP($B14,'ACS Price List'!$A$12:$P$180,H$1,FALSE)) | K14: =IFERROR(IF(VLOOKUP($C14,'ACS Price List'!$A$12:$P$180,G$1,FALSE)=0,"",VLOOKUP($C14,'ACS Price List'!$A$12:$P$180,G$1,FALSE)),"") | L14: =IFERROR(IF(VLOOKUP($C14,'ACS Price List'!$A$12:$P$180,H$1,FALSE)=0,"",VLOOKUP($C14,'ACS Price List'!$A$12:$P$180,H$1,FALSE)),"") | O14: =IFERROR(IF(VLOOKUP($D14,'ACS Price List'!$A$12:$P$180,G$1,FALSE)=0,"",VLOOKUP($D14,'ACS Price List'!$A$12:$P$180,G$1,FALSE)),"") | P14: =IFERROR(IF(VLOOKUP($D14,'ACS Price List'!$A$12:$P$180,H$1,FALSE)=0,"",VLOOKUP($D14,'ACS Price List'!$A$12:$P$180,H$1,FALSE)),"")
B15: 5 | F15: =VLOOKUP(B15,'ACS Price List'!$A$12:$P$180,2,FALSE) -> Protection and Power Quality assessment prior to connection | G15: =IF(VLOOKUP($B15,'ACS Price List'!$A$12:$P$180,G$1,FALSE)=0,"",VLOOKUP($B15,'ACS Price List'!$A$12:$P$180,G$1,FALSE)) -> PPQA | H15: =IF(VLOOKUP($B15,'ACS Price List'!$A$12:$P$180,H$1,FALSE)=0,"",VLOOKUP($B15,'ACS Price List'!$A$12:$P$180,H$1,FALSE)) | K15: =IFERROR(IF(VLOOKUP($C15,'ACS Price List'!$A$12:$P$180,G$1,FALSE)=0,"",VLOOKUP($C15,'ACS Price List'!$A$12:$P$180,G$1,FALSE)),"") | L15: =IFERROR(IF(VLOOKUP($C15,'ACS Price List'!$A$12:$P$180,H$1,FALSE)=0,"",VLOOKUP($C15,'ACS Price List'!$A$12:$P$180,H$1,FALSE)),"") | O15: =IFERROR(IF(VLOOKUP($D15,'ACS Price List'!$A$12:$P$180,G$1,FALSE)=0,"",VLOOKUP($D15,'ACS Price List'!$A$12:$P$180,G$1,FALSE)),"") | P15: =IFERROR(IF(VLOOKUP($D15,'ACS Price List'!$A$12:$P$180,H$1,FALSE)=0,"",VLOOKUP($D15,'ACS Price List'!$A$12:$P$180,H$1,FALSE)),"")
B16: 6 | C16: 161-M | D16: 6-CF | F16: =VLOOKUP(B16,'ACS Price List'!$A$12:$P$180,2,FALSE) -> Temporary connection, not in permanent position - single phase metered - urban/short rural feeders | G16: =IF(VLOOKUP($B16,'ACS Price List'!$A$12:$P$180,G$1,FALSE)=0,"",VLOOKUP($B16,'ACS Price List'!$A$12:$P$180,G$1,FALSE)) -> TBSSPU | H16: =IF(VLOOKUP($B16,'ACS Price List'!$A$12:$P$180,H$1,FALSE)=0,"",VLOOKUP($B16,'ACS Price List'!$A$12:$P$180,H$1,FALSE)) -> TBSSPS | K16: =IFERROR(IF(VLOOKUP($C16,'ACS Price List'!$A$12:$P$180,G$1,FALSE)=0,"",VLOOKUP($C16,'ACS Price List'!$A$12:$P$180,G$1,FALSE)),"") -> MTBSU | L16: =IFERROR(IF(VLOOKUP($C16,'ACS Price List'!$A$12:$P$180,H$1,FALSE)=0,"",VLOOKUP($C16,'ACS Price List'!$A$12:$P$180,H$1,FALSE)),"") -> MTBSS | O16: =IFERROR(IF(VLOOKUP($D16,'ACS Price List'!$A$12:$P$180,G$1,FALSE)=0,"",VLOOKUP($D16,'ACS Price List'!$A$12:$P$180,G$1,FALSE)),"") -> CFTBSSPU | P16: =IFERROR(IF(VLOOKUP($D16,'ACS Price List'!$A$12:$P$180,H$1,FALSE)=0,"",VLOOKUP($D16,'ACS Price List'!$A$12:$P$180,H$1,FALSE)),"") -> CFTBSSPS
B17: 8 | C17: 161-M | D17: 8-CF | F17: =VLOOKUP(B17,'ACS Price List'!$A$12:$P$180,2,FALSE) -> Temporary connection, not in permanent position - multi phase metered - urban/short rural feeders | G17: =IF(VLOOKUP($B17,'ACS Price List'!$A$12:$P$180,G$1,FALSE)=0,"",VLOOKUP($B17,'ACS Price List'!$A$12:$P$180,G$1,FALSE)) -> TBSMPU | H17: =IF(VLOOKUP($B17,'ACS Price List'!$A$12:$P$180,H$1,FALSE)=0,"",VLOOKUP($B17,'ACS Price List'!$A$12:$P$180,H$1,FALSE)) -> TBSMPS | K17: =IFERROR(IF(VLOOKUP($C17,'ACS Price List'!$A$12:$P$180,G$1,FALSE)=0,"",VLOOKUP($C17,'ACS Price List'!$A$12:$P$180,G$1,FALSE)),"") -> MTBSU | L17: =IFERROR(IF(VLOOKUP($C17,'ACS Price List'!$A$12:$P$180,H$1,FALSE)=0,"",VLOOKUP($C17,'ACS Price List'!$A$12:$P$180,H$1,FALSE)),"") -> MTBSS | O17: =IFERROR(IF(VLOOKUP($D17,'ACS Price List'!$A$12:$P$180,G$1,FALSE)=0,"",VLOOKUP($D17,'ACS Price List'!$A$12:$P$180,G$1,FALSE)),"") -> CFTBSMPU | P17: =IFERROR(IF(VLOOKUP($D17,'ACS Price List'!$A$12:$P$180,H$1,FALSE)=0,"",VLOOKUP($D17,'ACS Price List'!$A$12:$P$180,H$1,FALSE)),"") -> CFTBSMPS
B18: 10 | C18: 162-M | D18: 10-CF | F18: =VLOOKUP(B18,'ACS Price List'!$A$12:$P$180,2,FALSE) -> Supply abolishment during business hours - urban/short rural feeders | G18: =IF(VLOOKUP($B18,'ACS Price List'!$A$12:$P$180,G$1,FALSE)=0,"",VLOOKUP($B18,'ACS Price List'!$A$12:$P$180,G$1,FALSE)) -> SUPABOLU | H18: =IF(VLOOKUP($B18,'ACS Price List'!$A$12:$P$180,H$1,FALSE)=0,"",VLOOKUP($B18,'ACS Price List'!$A$12:$P$180,H$1,FALSE)) -> SUPABOLS | K18: =IFERROR(IF(VLOOKUP($C18,'ACS Price List'!$A$12:$P$180,G$1,FALSE)=0,"",VLOOKUP($C18,'ACS Price List'!$A$12:$P$180,G$1,FALSE)),"") -> MSUPABOLU | L18: =IFERROR(IF(VLOOKUP($C18,'ACS Price List'!$A$12:$P$180,H$1,FALSE)=0,"",VLOOKUP($C18,'ACS Price List'!$A$12:$P$180,H$1,FALSE)),"") -> MSUPABOLS | O18: =IFERROR(IF(VLOOKUP($D18,'ACS Price List'!$A$12:$P$180,G$1,FALSE)=0,"",VLOOKUP($D18,'ACS Price List'!$A$12:$P$180,G$1,FALSE)),"") -> CFSUPABOLU | P18: =IFERROR(IF(VLOOKUP($D18,'ACS Price List'!$A$12:$P$180,H$1,FALSE)=0,"",VLOOKUP($D18,'ACS Price List'!$A$12:$P$180,H$1,FALSE)),"") -> CFSUPABOLS
B19: 12 | D19: 12-CF | F19: =VLOOKUP(B19,'ACS Price List'!$A$12:$P$180,2,FALSE) -> De-energisation during business hours - urban/short rural feeders | G19: =IF(VLOOKUP($B19,'ACS Price List'!$A$12:$P$180,G$1,FALSE)=0,"",VLOOKUP($B19,'ACS Price List'!$A$12:$P$180,G$1,FALSE)) -> DEENBHU | H19: =IF(VLOOKUP($B19,'ACS Price List'!$A$12:$P$180,H$1,FALSE)=0,"",VLOOKUP($B19,'ACS Price List'!$A$12:$P$180,H$1,FALSE)) -> DEENBHS | K19: =IFERROR(IF(VLOOKUP($C19,'ACS Price List'!$A$12:$P$180,G$1,FALSE)=0,"",VLOOKUP($C19,'ACS Price List'!$A$12:$P$180,G$1,FALSE)),"") | L19: =IFERROR(IF(VLOOKUP($C19,'ACS Price List'!$A$12:$P$180,H$1,FALSE)=0,"",VLOOKUP($C19,'ACS Price List'!$A$12:$P$180,H$1,FALSE)),"") | O19: =IFERROR(IF(VLOOKUP($D19,'ACS Price List'!$A$12:$P$180,G$1,FALSE)=0,"",VLOOKUP($D19,'ACS Price List'!$A$12:$P$180,G$1,FALSE)),"") -> CFDEENBHU | P19: =IFERROR(IF(VLOOKUP($D19,'ACS Price List'!$A$12:$P$180,H$1,FALSE)=0,"",VLOOKUP($D19,'ACS Price List'!$A$12:$P$180,H$1,FALSE)),"") -> CFDEENBHS
B20: 14 | D20: 14-CF | F20: =VLOOKUP(B20,'ACS Price List'!$A$12:$P$180,2,FALSE) -> Re-energisation during business hours - urban/short rural feeders | G20: =IF(VLOOKUP($B20,'ACS Price List'!$A$12:$P$180,G$1,FALSE)=0,"",VLOOKUP($B20,'ACS Price List'!$A$12:$P$180,G$1,FALSE)) -> REENBHU | H20: =IF(VLOOKUP($B20,'ACS Price List'!$A$12:$P$180,H$1,FALSE)=0,"",VLOOKUP($B20,'ACS Price List'!$A$12:$P$180,H$1,FALSE)) -> REENBHS | K20: =IFERROR(IF(VLOOKUP($C20,'ACS Price List'!$A$12:$P$180,G$1,FALSE)=0,"",VLOOKUP($C20,'ACS Price List'!$A$12:$P$180,G$1,FALSE)),"") | L20: =IFERROR(IF(VLOOKUP($C20,'ACS Price List'!$A$12:$P$180,H$1,FALSE)=0,"",VLOOKUP($C20,'ACS Price List'!$A$12:$P$180,H$1,FALSE)),"") | O20: =IFERROR(IF(VLOOKUP($D20,'ACS Price List'!$A$12:$P$180,G$1,FALSE)=0,"",VLOOKUP($D20,'ACS Price List'!$A$12:$P$180,G$1,FALSE)),"") -> CFREENBHU | P20: =IFERROR(IF(VLOOKUP($D20,'ACS Price List'!$A$12:$P$180,H$1,FALSE)=0,"",VLOOKUP($D20,'ACS Price List'!$A$12:$P$180,H$1,FALSE)),"") -> CFREENBHS
B21: 14-VE | D21: 14-CF | F21: =VLOOKUP(B21,'ACS Price List'!$A$12:$P$180,2,FALSE) -> Visual examination during business hours for remote re-energisation - urban/short rural feeders | G21: =IF(VLOOKUP($B21,'ACS Price List'!$A$12:$P$180,G$1,FALSE)=0,"",VLOOKUP($B21,'ACS Price List'!$A$12:$P$180,G$1,FALSE)) -> VEREENBHU | H21: =IF(VLOOKUP($B21,'ACS Price List'!$A$12:$P$180,H$1,FALSE)=0,"",VLOOKUP($B21,'ACS Price List'!$A$12:$P$180,H$1,FALSE)) -> VEREENBHS | K21: =IFERROR(IF(VLOOKUP($C21,'ACS Price List'!$A$12:$P$180,G$1,FALSE)=0,"",VLOOKUP($C21,'ACS Price List'!$A$12:$P$180,G$1,FALSE)),"") | L21: =IFERROR(IF(VLOOKUP($C21,'ACS Price List'!$A$12:$P$180,H$1,FALSE)=0,"",VLOOKUP($C21,'ACS Price List'!$A$12:$P$180,H$1,FALSE)),"") | O21: =IFERROR(IF(VLOOKUP($D21,'ACS Price List'!$A$12:$P$180,G$1,FALSE)=0,"",VLOOKUP($D21,'ACS Price List'!$A$12:$P$180,G$1,FALSE)),"") -> CFREENBHU | P21: =IFERROR(IF(VLOOKUP($D21,'ACS Price List'!$A$12:$P$180,H$1,FALSE)=0,"",VLOOKUP($D21,'ACS Price List'!$A$12:$P$180,H$1,FALSE)),"") -> CFREENBHS
B22: 16 | D22: 16-CF | F22: =VLOOKUP(B22,'ACS Price List'!$A$12:$P$180,2,FALSE) -> Re-energisation during business hours - after de-energisation for debt - urban/short rural feeders | G22: =IF(VLOOKUP($B22,'ACS Price List'!$A$12:$P$180,G$1,FALSE)=0,"",VLOOKUP($B22,'ACS Price List'!$A$12:$P$180,G$1,FALSE)) -> REDDBHU | H22: =IF(VLOOKUP($B22,'ACS Price List'!$A$12:$P$180,H$1,FALSE)=0,"",VLOOKUP($B22,'ACS Price List'!$A$12:$P$180,H$1,FALSE)) -> REDDBHS | K22: =IFERROR(IF(VLOOKUP($C22,'ACS Price List'!$A$12:$P$180,G$1,FALSE)=0,"",VLOOKUP($C22,'ACS Price List'!$A$12:$P$180,G$1,FALSE)),"") | L22: =IFERROR(IF(VLOOKUP($C22,'ACS Price List'!$A$12:$P$180,H$1,FALSE)=0,"",VLOOKUP($C22,'ACS Price List'!$A$12:$P$180,H$1,FALSE)),"") | O22: =IFERROR(IF(VLOOKUP($D22,'ACS Price List'!$A$12:$P$180,G$1,FALSE)=0,"",VLOOKUP($D22,'ACS Price List'!$A$12:$P$180,G$1,FALSE)),"") -> CFREDDBHU | P22: =IFERROR(IF(VLOOKUP($D22,'ACS Price List'!$A$12:$P$180,H$1,FALSE)=0,"",VLOOKUP($D22,'ACS Price List'!$A$12:$P$180,H$1,FALSE)),"") -> CFREDDBHS
B23: 16-VE | D23: 16-CF | F23: =VLOOKUP(B23,'ACS Price List'!$A$12:$P$180,2,FALSE) -> Visual examination during business hours for remote re-energisation - after de-energisation for debt - urban/short rural feeders | G23: =IF(VLOOKUP($B23,'ACS Price List'!$A$12:$P$180,G$1,FALSE)=0,"",VLOOKUP($B23,'ACS Price List'!$A$12:$P$180,G$1,FALSE)) -> VEREDDBHU | H23: =IF(VLOOKUP($B23,'ACS Price List'!$A$12:$P$180,H$1,FALSE)=0,"",VLOOKUP($B23,'ACS Price List'!$A$12:$P$180,H$1,FALSE)) -> VEREDDBHS | K23: =IFERROR(IF(VLOOKUP($C23,'ACS Price List'!$A$12:$P$180,G$1,FALSE)=0,"",VLOOKUP($C23,'ACS Price List'!$A$12:$P$180,G$1,FALSE)),"") | L23: =IFERROR(IF(VLOOKUP($C23,'ACS Price List'!$A$12:$P$180,H$1,FALSE)=0,"",VLOOKUP($C23,'ACS Price List'!$A$12:$P$180,H$1,FALSE)),"") | O23: =IFERROR(IF(VLOOKUP($D23,'ACS Price List'!$A$12:$P$180,G$1,FALSE)=0,"",VLOOKUP($D23,'ACS Price List'!$A$12:$P$180,G$1,FALSE)),"") -> CFREDDBHU | P23: =IFERROR(IF(VLOOKUP($D23,'ACS Price List'!$A$12:$P$180,H$1,FALSE)=0,"",VLOOKUP($D23,'ACS Price List'!$A$12:$P$180,H$1,FALSE)),"") -> CFREDDBHS
B24: 18 | F24: =VLOOKUP(B24,'ACS Price List'!$A$12:$P$180,2,FALSE) -> Accreditation of alternative service providers - real estate developments | G24: =IF(VLOOKUP($B24,'ACS Price List'!$A$12:$P$180,G$1,FALSE)=0,"",VLOOKUP($B24,'ACS Price List'!$A$12:$P$180,G$1,FALSE)) -> ASPRED | H24: =IF(VLOOKUP($B24,'ACS Price List'!$A$12:$P$180,H$1,FALSE)=0,"",VLOOKUP($B24,'ACS Price List'!$A$12:$P$180,H$1,FALSE)) | K24: =IFERROR(IF(VLOOKUP($C24,'ACS Price List'!$A$12:$P$180,G$1,FALSE)=0,"",VLOOKUP($C24,'ACS Price List'!$A$12:$P$180,G$1,FALSE)),"") | L24: =IFERROR(IF(VLOOKUP($C24,'ACS Price List'!$A$12:$P$180,H$1,FALSE)=0,"",VLOOKUP($C24,'ACS Price List'!$A$12:$P$180,H$1,FALSE)),"") | O24: =IFERROR(IF(VLOOKUP($D24,'ACS Price List'!$A$12:$P$180,G$1,FALSE)=0,"",VLOOKUP($D24,'ACS Price List'!$A$12:$P$180,G$1,FALSE)),"") | P24: =IFERROR(IF(VLOOKUP($D24,'ACS Price List'!$A$12:$P$180,H$1,FALSE)=0,"",VLOOKUP($D24,'ACS Price List'!$A$12:$P$180,H$1,FALSE)),"")
B25: 19 | D25: 19-CF | F25: =VLOOKUP(B25,'ACS Price List'!$A$12:$P$180,2,FALSE) -> Install replacement meter (Type 5 and 6) – Single phase – urban/short rural feeder | G25: =IF(VLOOKUP($B25,'ACS Price List'!$A$12:$P$180,G$1,FALSE)=0,"",VLOOKUP($B25,'ACS Price List'!$A$12:$P$180,G$1,FALSE)) -> MSNGLU | H25: =IF(VLOOKUP($B25,'ACS Price List'!$A$12:$P$180,H$1,FALSE)=0,"",VLOOKUP($B25,'ACS Price List'!$A$12:$P$180,H$1,FALSE)) -> MSNGLS | K25: =IFERROR(IF(VLOOKUP($C25,'ACS Price List'!$A$12:$P$180,G$1,FALSE)=0,"",VLOOKUP($C25,'ACS Price List'!$A$12:$P$180,G$1,FALSE)),"") | L25: =IFERROR(IF(VLOOKUP($C25,'ACS Price List'!$A$12:$P$180,H$1,FALSE)=0,"",VLOOKUP($C25,'ACS Price List'!$A$12:$P$180,H$1,FALSE)),"") | O25: =IFERROR(IF(VLOOKUP($D25,'ACS Price List'!$A$12:$P$180,G$1,FALSE)=0,"",VLOOKUP($D25,'ACS Price List'!$A$12:$P$180,G$1,FALSE)),"") -> CFMSNGLU | P25: =IFERROR(IF(VLOOKUP($D25,'ACS Price List'!$A$12:$P$180,H$1,FALSE)=0,"",VLOOKUP($D25,'ACS Price List'!$A$12:$P$180,H$1,FALSE)),"") -> CFMSNGLS
B26: 21 | D26: 21-CF | F26: =VLOOKUP(B26,'ACS Price List'!$A$12:$P$180,2,FALSE) -> Install replacement meter (Type 5 and 6) – Dual element – urban/short rural feeder | G26: =IF(VLOOKUP($B26,'ACS Price List'!$A$12:$P$180,G$1,FALSE)=0,"",VLOOKUP($B26,'ACS Price List'!$A$12:$P$180,G$1,FALSE)) -> MDUALU | H26: =IF(VLOOKUP($B26,'ACS Price List'!$A$12:$P$180,H$1,FALSE)=0,"",VLOOKUP($B26,'ACS Price List'!$A$12:$P$180,H$1,FALSE)) -> MDUALS | K26: =IFERROR(IF(VLOOKUP($C26,'ACS Price List'!$A$12:$P$180,G$1,FALSE)=0,"",VLOOKUP($C26,'ACS Price List'!$A$12:$P$180,G$1,FALSE)),"") | L26: =IFERROR(IF(VLOOKUP($C26,'ACS Price List'!$A$12:$P$180,H$1,FALSE)=0,"",VLOOKUP($C26,'ACS Price List'!$A$12:$P$180,H$1,FALSE)),"") | O26: =IFERROR(IF(VLOOKUP($D26,'ACS Price List'!$A$12:$P$180,G$1,FALSE)=0,"",VLOOKUP($D26,'ACS Price List'!$A$12:$P$180,G$1,FALSE)),"") -> CFMDUALU | P26: =IFERROR(IF(VLOOKUP($D26,'ACS Price List'!$A$12:$P$180,H$1,FALSE)=0,"",VLOOKUP($D26,'ACS Price List'!$A$12:$P$180,H$1,FALSE)),"") -> CFMDUALS
B27: 23 | D27: 23-CF | F27: =VLOOKUP(B27,'ACS Price List'!$A$12:$P$180,2,FALSE) -> Install replacement meter (Type 5 and 6) – Polyphase – urban/short rural feeder | G27: =IF(VLOOKUP($B27,'ACS Price List'!$A$12:$P$180,G$1,FALSE)=0,"",VLOOKUP($B27,'ACS Price List'!$A$12:$P$180,G$1,FALSE)) -> MTHREU | H27: =IF(VLOOKUP($B27,'ACS Price List'!$A$12:$P$180,H$1,FALSE)=0,"",VLOOKUP($B27,'ACS Price List'!$A$12:$P$180,H$1,FALSE)) -> MTHRES | K27: =IFERROR(IF(VLOOKUP($C27,'ACS Price List'!$A$12:$P$180,G$1,FALSE)=0,"",VLOOKUP($C27,'ACS Price List'!$A$12:$P$180,G$1,FALSE)),"") | L27: =IFERROR(IF(VLOOKUP($C27,'ACS Price List'!$A$12:$P$180,H$1,FALSE)=0,"",VLOOKUP($C27,'ACS Price List'!$A$12:$P$180,H$1,FALSE)),"") | O27: =IFERROR(IF(VLOOKUP($D27,'ACS Price List'!$A$12:$P$180,G$1,FALSE)=0,"",VLOOKUP($D27,'ACS Price List'!$A$12:$P$180,G$1,FALSE)),"") -> CFMTHREU | P27: =IFERROR(IF(VLOOKUP($D27,'ACS Price List'!$A$12:$P$180,H$1,FALSE)=0,"",VLOOKUP($D27,'ACS Price List'!$A$12:$P$180,H$1,FALSE)),"") -> CFMTHRES
B28: 25 | D28: 25-CF | F28: =VLOOKUP(B28,'ACS Price List'!$A$12:$P$180,2,FALSE) -> Install replacement meter (CT) – urban/short rural feeder | G28: =IF(VLOOKUP($B28,'ACS Price List'!$A$12:$P$180,G$1,FALSE)=0,"",VLOOKUP($B28,'ACS Price List'!$A$12:$P$180,G$1,FALSE)) -> MCTU | H28: =IF(VLOOKUP($B28,'ACS Price List'!$A$12:$P$180,H$1,FALSE)=0,"",VLOOKUP($B28,'ACS Price List'!$A$12:$P$180,H$1,FALSE)) -> MCTS | K28: =IFERROR(IF(VLOOKUP($C28,'ACS Price List'!$A$12:$P$180,G$1,FALSE)=0,"",VLOOKUP($C28,'ACS Price List'!$A$12:$P$180,G$1,FALSE)),"") | L28: =IFERROR(IF(VLOOKUP($C28,'ACS Price List'!$A$12:$P$180,H$1,FALSE)=0,"",VLOOKUP($C28,'ACS Price List'!$A$12:$P$180,H$1,FALSE)),"") | O28: =IFERROR(IF(VLOOKUP($D28,'ACS Price List'!$A$12:$P$180,G$1,FALSE)=0,"",VLOOKUP($D28,'ACS Price List'!$A$12:$P$180,G$1,FALSE)),"") -> CFMCTU | P28: =IFERROR(IF(VLOOKUP($D28,'ACS Price List'!$A$12:$P$180,H$1,FALSE)=0,"",VLOOKUP($D28,'ACS Price List'!$A$12:$P$180,H$1,FALSE)),"") -> CFMCTS
B29: 140 | D29: 157-CF | F29: =VLOOKUP(B29,'ACS Price List'!$A$12:$P$180,2,FALSE) -> Install new meter (Type 5 and 6) – Single phase – Primary | G29: =IF(VLOOKUP($B29,'ACS Price List'!$A$12:$P$180,G$1,FALSE)=0,"",VLOOKUP($B29,'ACS Price List'!$A$12:$P$180,G$1,FALSE)) -> NMSPU | H29: =IF(VLOOKUP($B29,'ACS Price List'!$A$12:$P$180,H$1,FALSE)=0,"",VLOOKUP($B29,'ACS Price List'!$A$12:$P$180,H$1,FALSE)) -> NMSPS | K29: =IFERROR(IF(VLOOKUP($C29,'ACS Price List'!$A$12:$P$180,G$1,FALSE)=0,"",VLOOKUP($C29,'ACS Price List'!$A$12:$P$180,G$1,FALSE)),"") | L29: =IFERROR(IF(VLOOKUP($C29,'ACS Price List'!$A$12:$P$180,H$1,FALSE)=0,"",VLOOKUP($C29,'ACS Price List'!$A$12:$P$180,H$1,FALSE)),"") | O29: =IFERROR(IF(VLOOKUP($D29,'ACS Price List'!$A$12:$P$180,G$1,FALSE)=0,"",VLOOKUP($D29,'ACS Price List'!$A$12:$P$180,G$1,FALSE)),"") -> CFNMSPU | P29: =IFERROR(IF(VLOOKUP($D29,'ACS Price List'!$A$12:$P$180,H$1,FALSE)=0,"",VLOOKUP($D29,'ACS Price List'!$A$12:$P$180,H$1,FALSE)),"") -> CFNMSPS
B30: 141 | D30: 157-CF | F30: =VLOOKUP(B30,'ACS Price List'!$A$12:$P$180,2,FALSE) -> Install new meter (Type 5 and 6) – Single phase – Primary plus embedded generation | G30: =IF(VLOOKUP($B30,'ACS Price List'!$A$12:$P$180,G$1,FALSE)=0,"",VLOOKUP($B30,'ACS Price List'!$A$12:$P$180,G$1,FALSE)) -> NMSPEGU | H30: =IF(VLOOKUP($B30,'ACS Price List'!$A$12:$P$180,H$1,FALSE)=0,"",VLOOKUP($B30,'ACS Price List'!$A$12:$P$180,H$1,FALSE)) -> NMSPEGS | K30: =IFERROR(IF(VLOOKUP($C30,'ACS Price List'!$A$12:$P$180,G$1,FALSE)=0,"",VLOOKUP($C30,'ACS Price List'!$A$12:$P$180,G$1,FALSE)),"") | L30: =IFERROR(IF(VLOOKUP($C30,'ACS Price List'!$A$12:$P$180,H$1,FALSE)=0,"",VLOOKUP($C30,'ACS Price List'!$A$12:$P$180,H$1,FALSE)),"") | O30: =IFERROR(IF(VLOOKUP($D30,'ACS Price List'!$A$12:$P$180,G$1,FALSE)=0,"",VLOOKUP($D30,'ACS Price List'!$A$12:$P$180,G$1,FALSE)),"") -> CFNMSPU | P30: =IFERROR(IF(VLOOKUP($D30,'ACS Price List'!$A$12:$P$180,H$1,FALSE)=0,"",VLOOKUP($D30,'ACS Price List'!$A$12:$P$180,H$1,FALSE)),"") -> CFNMSPS
B31: 142 | D31: 158-CF | F31: =VLOOKUP(B31,'ACS Price List'!$A$12:$P$180,2,FALSE) -> Install new meter (Type 5 and 6) – Dual element – Primary plus controlled load | G31: =IF(VLOOKUP($B31,'ACS Price List'!$A$12:$P$180,G$1,FALSE)=0,"",VLOOKUP($B31,'ACS Price List'!$A$12:$P$180,G$1,FALSE)) -> NMDPCLU | H31: =IF(VLOOKUP($B31,'ACS Price List'!$A$12:$P$180,H$1,FALSE)=0,"",VLOOKUP($B31,'ACS Price List'!$A$12:$P$180,H$1,FALSE)) -> NMDPCLS | K31: =IFERROR(IF(VLOOKUP($C31,'ACS Price List'!$A$12:$P$180,G$1,FALSE)=0,"",VLOOKUP($C31,'ACS Price List'!$A$12:$P$180,G$1,FALSE)),"") | L31: =IFERROR(IF(VLOOKUP($C31,'ACS Price List'!$A$12:$P$180,H$1,FALSE)=0,"",VLOOKUP($C31,'ACS Price List'!$A$12:$P$180,H$1,FALSE)),"") | O31: =IFERROR(IF(VLOOKUP($D31,'ACS Price List'!$A$12:$P$180,G$1,FALSE)=0,"",VLOOKUP($D31,'ACS Price List'!$A$12:$P$180,G$1,FALSE)),"") -> CFNMDUALU | P31: =IFERROR(IF(VLOOKUP($D31,'ACS Price List'!$A$12:$P$180,H$1,FALSE)=0,"",VLOOKUP($D31,'ACS Price List'!$A$12:$P$180,H$1,FALSE)),"") -> CFNMDUALS
B32: 143 | D32: 158-CF | F32: =VLOOKUP(B32,'ACS Price List'!$A$12:$P$180,2,FALSE) -> Install new meter (Type 5 and 6) – Dual element – Primary plus controlled load plus embedded generation | G32: =IF(VLOOKUP($B32,'ACS Price List'!$A$12:$P$180,G$1,FALSE)=0,"",VLOOKUP($B32,'ACS Price List'!$A$12:$P$180,G$1,FALSE)) -> NMDPCLEGU | H32: =IF(VLOOKUP($B32,'ACS Price List'!$A$12:$P$180,H$1,FALSE)=0,"",VLOOKUP($B32,'ACS Price List'!$A$12:$P$180,H$1,FALSE)) -> NMDPCLEGS | K32: =IFERROR(IF(VLOOKUP($C32,'ACS Price List'!$A$12:$P$180,G$1,FALSE)=0,"",VLOOKUP($C32,'ACS Price List'!$A$12:$P$180,G$1,FALSE)),"") | L32: =IFERROR(IF(VLOOKUP($C32,'ACS Price List'!$A$12:$P$180,H$1,FALSE)=0,"",VLOOKUP($C32,'ACS Price List'!$A$12:$P$180,H$1,FALSE)),"") | O32: =IFERROR(IF(VLOOKUP($D32,'ACS Price List'!$A$12:$P$180,G$1,FALSE)=0,"",VLOOKUP($D32,'ACS Price List'!$A$12:$P$180,G$1,FALSE)),"") -> CFNMDUALU | P32: =IFERROR(IF(VLOOKUP($D32,'ACS Price List'!$A$12:$P$180,H$1,FALSE)=0,"",VLOOKUP($D32,'ACS Price List'!$A$12:$P$180,H$1,FALSE)),"") -> CFNMDUALS
B33: 144 | D33: 159-CF | F33: =VLOOKUP(B33,'ACS Price List'!$A$12:$P$180,2,FALSE) -> Install new meter (Type 5 and 6) – Polyphase – Primary | G33: =IF(VLOOKUP($B33,'ACS Price List'!$A$12:$P$180,G$1,FALSE)=0,"",VLOOKUP($B33,'ACS Price List'!$A$12:$P$180,G$1,FALSE)) -> NMPPU | H33: =IF(VLOOKUP($B33,'ACS Price List'!$A$12:$P$180,H$1,FALSE)=0,"",VLOOKUP($B33,'ACS Price List'!$A$12:$P$180,H$1,FALSE)) -> NMPPS | K33: =IFERROR(IF(VLOOKUP($C33,'ACS Price List'!$A$12:$P$180,G$1,FALSE)=0,"",VLOOKUP($C33,'ACS Price List'!$A$12:$P$180,G$1,FALSE)),"") | L33: =IFERROR(IF(VLOOKUP($C33,'ACS Price List'!$A$12:$P$180,H$1,FALSE)=0,"",VLOOKUP($C33,'ACS Price List'!$A$12:$P$180,H$1,FALSE)),"") | O33: =IFERROR(IF(VLOOKUP($D33,'ACS Price List'!$A$12:$P$180,G$1,FALSE)=0,"",VLOOKUP($D33,'ACS Price List'!$A$12:$P$180,G$1,FALSE)),"") -> CFNMTHREU | P33: =IFERROR(IF(VLOOKUP($D33,'ACS Price List'!$A$12:$P$180,H$1,FALSE)=0,"",VLOOKUP($D33,'ACS Price List'!$A$12:$P$180,H$1,FALSE)),"") -> CFNMTHRES
B34: 145 | D34: 159-CF | F34: =VLOOKUP(B34,'ACS Price List'!$A$12:$P$180,2,FALSE) -> Install new meter (Type 5 and 6) – Polyphase – Primary plus embedded generation | G34: =IF(VLOOKUP($B34,'ACS Price List'!$A$12:$P$180,G$1,FALSE)=0,"",VLOOKUP($B34,'ACS Price List'!$A$12:$P$180,G$1,FALSE)) -> NMPPEGU | H34: =IF(VLOOKUP($B34,'ACS Price List'!$A$12:$P$180,H$1,FALSE)=0,"",VLOOKUP($B34,'ACS Price List'!$A$12:$P$180,H$1,FALSE)) -> NMPPEGS | K34: =IFERROR(IF(VLOOKUP($C34,'ACS Price List'!$A$12:$P$180,G$1,FALSE)=0,"",VLOOKUP($C34,'ACS Price List'!$A$12:$P$180,G$1,FALSE)),"") | L34: =IFERROR(IF(VLOOKUP($C34,'ACS Price List'!$A$12:$P$180,H$1,FALSE)=0,"",VLOOKUP($C34,'ACS Price List'!$A$12:$P$180,H$1,FALSE)),"") | O34: =IFERROR(IF(VLOOKUP($D34,'ACS Price List'!$A$12:$P$180,G$1,FALSE)=0,"",VLOOKUP($D34,'ACS Price List'!$A$12:$P$180,G$1,FALSE)),"") -> CFNMTHREU | P34: =IFERROR(IF(VLOOKUP($D34,'ACS Price List'!$A$12:$P$180,H$1,FALSE)=0,"",VLOOKUP($D34,'ACS Price List'!$A$12:$P$180,H$1,FALSE)),"") -> CFNMTHRES
B35: 146 | D35: 160-CF | F35: =VLOOKUP(B35,'ACS Price List'!$A$12:$P$180,2,FALSE) -> Install new meter (CT) – Primary | G35: =IF(VLOOKUP($B35,'ACS Price List'!$A$12:$P$180,G$1,FALSE)=0,"",VLOOKUP($B35,'ACS Price List'!$A$12:$P$180,G$1,FALSE)) -> NMCTPU | H35: =IF(VLOOKUP($B35,'ACS Price List'!$A$12:$P$180,H$1,FALSE)=0,"",VLOOKUP($B35,'ACS Price List'!$A$12:$P$180,H$1,FALSE)) -> NMCTPS | K35: =IFERROR(IF(VLOOKUP($C35,'ACS Price List'!$A$12:$P$180,G$1,FALSE)=0,"",VLOOKUP($C35,'ACS Price List'!$A$12:$P$180,G$1,FALSE)),"") | L35: =IFERROR(IF(VLOOKUP($C35,'ACS Price List'!$A$12:$P$180,H$1,FALSE)=0,"",VLOOKUP($C35,'ACS Price List'!$A$12:$P$180,H$1,FALSE)),"") | O35: =IFERROR(IF(VLOOKUP($D35,'ACS Price List'!$A$12:$P$180,G$1,FALSE)=0,"",VLOOKUP($D35,'ACS Price List'!$A$12:$P$180,G$1,FALSE)),"") -> CFNMCTU | P35: =IFERROR(IF(VLOOKUP($D35,'ACS Price List'!$A$12:$P$180,H$1,FALSE)=0,"",VLOOKUP($D35,'ACS Price List'!$A$12:$P$180,H$1,FALSE)),"") -> CFNMCTS
B36: 147 | D36: 160-CF | F36: =VLOOKUP(B36,'ACS Price List'!$A$12:$P$180,2,FALSE) -> Install new meter (CT) – Primary plus embedded generation | G36: =IF(VLOOKUP($B36,'ACS Price List'!$A$12:$P$180,G$1,FALSE)=0,"",VLOOKUP($B36,'ACS Price List'!$A$12:$P$180,G$1,FALSE)) -> NMCTPEGU | H36: =IF(VLOOKUP($B36,'ACS Price List'!$A$12:$P$180,H$1,FALSE)=0,"",VLOOKUP($B36,'ACS Price List'!$A$12:$P$180,H$1,FALSE)) -> NMCTPEGS | K36: =IFERROR(IF(VLOOKUP($C36,'ACS Price List'!$A$12:$P$180,G$1,FALSE)=0,"",VLOOKUP($C36,'ACS Price List'!$A$12:$P$180,G$1,FALSE)),"") | L36: =IFERROR(IF(VLOOKUP($C36,'ACS Price List'!$A$12:$P$180,H$1,FALSE)=0,"",VLOOKUP($C36,'ACS Price List'!$A$12:$P$180,H$1,FALSE)),"") | O36: =IFERROR(IF(VLOOKUP($D36,'ACS Price List'!$A$12:$P$180,G$1,FALSE)=0,"",VLOOKUP($D36,'ACS Price List'!$A$12:$P$180,G$1,FALSE)),"") -> CFNMCTU | P36: =IFERROR(IF(VLOOKUP($D36,'ACS Price List'!$A$12:$P$180,H$1,FALSE)=0,"",VLOOKUP($D36,'ACS Price List'!$A$12:$P$180,H$1,FALSE)),"") -> CFNMCTS
... B45: 156 | D45: 160-CF | F45: =VLOOKUP(B45,'ACS Price List'!$A$12:$P$180,2,FALSE) -> Install new meter (CT) to accommodate embedded generation installation | G45: =IF(VLOOKUP($B45,'ACS Price List'!$A$12:$P$180,G$1,FALSE)=0,"",VLOOKUP($B45,'ACS Price List'!$A$12:$P$180,G$1,FALSE)) -> NCTAEGU | H45: =IF(VLOOKUP($B45,'ACS Price List'!$A$12:$P$180,H$1,FALSE)=0,"",VLOOKUP($B45,'ACS Price List'!$A$12:$P$180,H$1,FALSE)) -> NCTAEGS | K45: =IFERROR(IF(VLOOKUP($C45,'ACS Price List'!$A$12:$P$180,G$1,FALSE)=0,"",VLOOKUP($C45,'ACS Price List'!$A$12:$P$180,G$1,FALSE)),"") | L45: =IFERROR(IF(VLOOKUP($C45,'ACS Price List'!$A$12:$P$180,H$1,FALSE)=0,"",VLOOKUP($C45,'ACS Price List'!$A$12:$P$180,H$1,FALSE)),"") | O45: =IFERROR(IF(VLOOKUP($D45,'ACS Price List'!$A$12:$P$180,G$1,FALSE)=0,"",VLOOKUP($D45,'ACS Price List'!$A$12:$P$180,G$1,FALSE)),"") -> CFNMCTU | P45: =IFERROR(IF(VLOOKUP($D45,'ACS Price List'!$A$12:$P$180,H$1,FALSE)=0,"",VLOOKUP($D45,'ACS Price List'!$A$12:$P$180,H$1,FALSE)),"") -> CFNMCTS
B46: 1 | E46: Fee based services (long rural/isolated) | F46: =VLOOKUP(B46,'ACS Price List'!$A$12:$P$180,2,FALSE) -> Application fee - Basic or standard connection | G46: =IF(VLOOKUP($B46,'ACS Price List'!$A$12:$P$180,G$1,FALSE)=0,"",VLOOKUP($B46,'ACS Price List'!$A$12:$P$180,G$1,FALSE)) -> APFSAC | H46: =IF(VLOOKUP($B46,'ACS Price List'!$A$12:$P$180,J$1,FALSE)=0,"",VLOOKUP($B46,'ACS Price List'!$A$12:$P$180,J$1,FALSE)) | K46: =IFERROR(IF(VLOOKUP($C46,'ACS Price List'!$A$12:$P$180,I$1,FALSE)=0,"",VLOOKUP($C46,'ACS Price List'!$A$12:$P$180,I$1,FALSE)),"") | L46: =IFERROR(IF(VLOOKUP($C46,'ACS Price List'!$A$12:$P$180,J$1,FALSE)=0,"",VLOOKUP($C46,'ACS Price List'!$A$12:$P$180,J$1,FALSE)),"") | U46: =COUNTA(G46:G80,H51:H58,H60:H80,K51:K53,L51:L53,O51:O58,P51:P58,O60:O80,P60:P80) -> 128
B47: 2 | F47: =VLOOKUP(B47,'ACS Price List'!$A$12:$P$180,2,FALSE) -> Application fee - Basic or standard connection - Micro-embedded generators | G47: =IF(VLOOKUP($B47,'ACS Price List'!$A$12:$P$180,G$1,FALSE)=0,"",VLOOKUP($B47,'ACS Price List'!$A$12:$P$180,G$1,FALSE)) -> APFMEG | H47: =IF(VLOOKUP($B47,'ACS Price List'!$A$12:$P$180,J$1,FALSE)=0,"",VLOOKUP($B47,'ACS Price List'!$A$12:$P$180,J$1,FALSE)) | K47: =IFERROR(IF(VLOOKUP($C47,'ACS Price List'!$A$12:$P$180,I$1,FALSE)=0,"",VLOOKUP($C47,'ACS Price List'!$A$12:$P$180,I$1,FALSE)),"") | L47: =IFERROR(IF(VLOOKUP($C47,'ACS Price List'!$A$12:$P$180,J$1,FALSE)=0,"",VLOOKUP($C47,'ACS Price List'!$A$12:$P$180,J$1,FALSE)),"")
B48: 3 | F48: =VLOOKUP(B48,'ACS Price List'!$A$12:$P$180,2,FALSE) -> Application fee - Basic or standard connection - Micro-embedded generators - Technical assessment required | G48: =IF(VLOOKUP($B48,'ACS Price List'!$A$12:$P$180,G$1,FALSE)=0,"",VLOOKUP($B48,'ACS Price List'!$A$12:$P$180,G$1,FALSE)) -> APFMTA | H48: =IF(VLOOKUP($B48,'ACS Price List'!$A$12:$P$180,J$1,FALSE)=0,"",VLOOKUP($B48,'ACS Price List'!$A$12:$P$180,J$1,FALSE)) | K48: =IFERROR(IF(VLOOKUP($C48,'ACS Price List'!$A$12:$P$180,I$1,FALSE)=0,"",VLOOKUP($C48,'ACS Price List'!$A$12:$P$180,I$1,FALSE)),"") | L48: =IFERROR(IF(VLOOKUP($C48,'ACS Price List'!$A$12:$P$180,J$1,FALSE)=0,"",VLOOKUP($C48,'ACS Price List'!$A$12:$P$180,J$1,FALSE)),"")
B49: 4 | F49: =VLOOKUP(B49,'ACS Price List'!$A$12:$P$180,2,FALSE) -> Application fee - Real estate development connection | G49: =IF(VLOOKUP($B49,'ACS Price List'!$A$12:$P$180,G$1,FALSE)=0,"",VLOOKUP($B49,'ACS Price List'!$A$12:$P$180,G$1,FALSE)) -> APFRED | H49: =IF(VLOOKUP($B49,'ACS Price List'!$A$12:$P$180,J$1,FALSE)=0,"",VLOOKUP($B49,'ACS Price List'!$A$12:$P$180,J$1,FALSE)) | K49: =IFERROR(IF(VLOOKUP($C49,'ACS Price List'!$A$12:$P$180,I$1,FALSE)=0,"",VLOOKUP($C49,'ACS Price List'!$A$12:$P$180,I$1,FALSE)),"") | L49: =IFERROR(IF(VLOOKUP($C49,'ACS Price List'!$A$12:$P$180,J$1,FALSE)=0,"",VLOOKUP($C49,'ACS Price List'!$A$12:$P$180,J$1,FALSE)),"")
B50: 5 | F50: =VLOOKUP(B50,'ACS Price List'!$A$12:$P$180,2,FALSE) -> Protection and Power Quality assessment prior to connection | G50: =IF(VLOOKUP($B50,'ACS Price List'!$A$12:$P$180,G$1,FALSE)=0,"",VLOOKUP($B50,'ACS Price List'!$A$12:$P$180,G$1,FALSE)) -> PPQA | H50: =IF(VLOOKUP($B50,'ACS Price List'!$A$12:$P$180,J$1,FALSE)=0,"",VLOOKUP($B50,'ACS Price List'!$A$12:$P$180,J$1,FALSE)) | K50: =IFERROR(IF(VLOOKUP($C50,'ACS Price List'!$A$12:$P$180,I$1,FALSE)=0,"",VLOOKUP($C50,'ACS Price List'!$A$12:$P$180,I$1,FALSE)),"") | L50: =IFERROR(IF(VLOOKUP($C50,'ACS Price List'!$A$12:$P$180,J$1,FALSE)=0,"",VLOOKUP($C50,'ACS Price List'!$A$12:$P$180,J$1,FALSE)),"")
B51: 7 | C51: 161-M | D51: 7-CF | F51: =VLOOKUP(B51,'ACS Price List'!$A$12:$P$180,2,FALSE) -> Temporary connection, not in permanent position - single phase metered - long rural/isolated feeders | G51: =IF(VLOOKUP($B51,'ACS Price List'!$A$12:$P$180,I$1,FALSE)=0,"",VLOOKUP($B51,'ACS Price List'!$A$12:$P$180,I$1,FALSE)) -> TBSSPL | H51: =IF(VLOOKUP($B51,'ACS Price List'!$A$12:$P$180,J$1,FALSE)=0,"",VLOOKUP($B51,'ACS Price List'!$A$12:$P$180,J$1,FALSE)) -> TBSSPI | K51: =IFERROR(IF(VLOOKUP($C51,'ACS Price List'!$A$12:$P$180,I$1,FALSE)=0,"",VLOOKUP($C51,'ACS Price List'!$A$12:$P$180,I$1,FALSE)),"") -> MTBSL | L51: =IFERROR(IF(VLOOKUP($C51,'ACS Price List'!$A$12:$P$180,J$1,FALSE)=0,"",VLOOKUP($C51,'ACS Price List'!$A$12:$P$180,J$1,FALSE)),"") -> MTBSI | O51: =IFERROR(IF(VLOOKUP($D51,'ACS Price List'!$A$12:$P$180,I$1,FALSE)=0,"",VLOOKUP($D51,'ACS Price List'!$A$12:$P$180,I$1,FALSE)),"") -> CFTBSSPL | P51: =IFERROR(IF(VLOOKUP($D51,'ACS Price List'!$A$12:$P$180,J$1,FALSE)=0,"",VLOOKUP($D51,'ACS Price List'!$A$12:$P$180,J$1,FALSE)),"") -> CFTBSSPI
B52: 9 | C52: 161-M | D52: 9-CF | F52: =VLOOKUP(B52,'ACS Price List'!$A$12:$P$180,2,FALSE) -> Temporary connection, not in permanent position - multi phase metered - long rural/isolated feeders | G52: =IF(VLOOKUP($B52,'ACS Price List'!$A$12:$P$180,I$1,FALSE)=0,"",VLOOKUP($B52,'ACS Price List'!$A$12:$P$180,I$1,FALSE)) -> TBSMPL | H52: =IF(VLOOKUP($B52,'ACS Price List'!$A$12:$P$180,J$1,FALSE)=0,"",VLOOKUP($B52,'ACS Price List'!$A$12:$P$180,J$1,FALSE)) -> TBSMPI | K52: =IFERROR(IF(VLOOKUP($C52,'ACS Price List'!$A$12:$P$180,I$1,FALSE)=0,"",VLOOKUP($C52,'ACS Price List'!$A$12:$P$180,I$1,FALSE)),"") -> MTBSL | L52: =IFERROR(IF(VLOOKUP($C52,'ACS Price List'!$A$12:$P$180,J$1,FALSE)=0,"",VLOOKUP($C52,'ACS Price List'!$A$12:$P$180,J$1,FALSE)),"") -> MTBSI | O52: =IFERROR(IF(VLOOKUP($D52,'ACS Price List'!$A$12:$P$180,I$1,FALSE)=0,"",VLOOKUP($D52,'ACS Price List'!$A$12:$P$180,I$1,FALSE)),"") -> CFTBSMPL | P52: =IFERROR(IF(VLOOKUP($D52,'ACS Price List'!$A$12:$P$180,J$1,FALSE)=0,"",VLOOKUP($D52,'ACS Price List'!$A$12:$P$180,J$1,FALSE)),"") -> CFTBSMPI
...

Sheet Rates by ProdCode
J2: Total Unique Prod Codes | K2: =COUNTA('ACS Price List'!D16:G180)+COUNTA('ACS Tariff classes & tariffs'!F160,'ACS Tariff classes & tariffs'!F161) -> 362
D3: Ergon Energy Corporation Limited | J3: No. Prod Codes in this sheet | K3: =COUNTA(C11:C558,O11:O45) -> 362 | L3: =IF(K3=K2,"OK","CHECK") -> OK
D4: 2017-18 ACS tariff rates by product code
I5: revised price or new prod code from 1 December
C8: Table 1: ACS tariffs billed per service | O8: Table 2: ACS tariffs billed as network tariff component
B10: Ref# | C10: Product Code | D10: Feeder Category | E10: Tariff | F10: Ellipse Cost Code | G10: Billing unit | H10: GST Exclusive Rate (effective 1 Jul 2017) | I10: GST Exclusive Rate (effective 1 Dec 2017) | O10: Product Code | P10: Tariff | Q10: Ellipse Cost Code | R10: Billing unit | S10: GST Exclusive Rate (effective 1 Jul 2017) | T10: GST Exclusive Rate (effective 1 Dec 2017)
B11: 1 | C11: APFSAC | D11: N/A | E11: Application fee - Basic or standard connection | F11: =VLOOKUP(B11,'ACS Price List'!$16:$180,8,FALSE) -> 8000 | G11: dollars ($) | H11: 888.4 | I11: =IFERROR(IF(D11="LR",VLOOKUP(B11,'ACS Price List'!$16:$180,11,FALSE),IF(D11="IS",VLOOKUP(B11,'ACS Price List'!$16:$180,11,FALSE),VLOOKUP(B11,'ACS Price List'!$16:$180,9,FALSE))),"POA") -> 888.4 | K11: =IFERROR(IF(I11="POA","OK",IF(I11-H11=0,"OK","CHANGE")),"CHECK") -> OK | N11: 100 | O11: ACSMNCC | P11: Default Metering Services: Primary service - Non-capital | Q11: =VLOOKUP(N11,'ACS Price List'!$16:$180,8,FALSE) -> 8120 | R11: dollars per day per meter ($/day/meter) | T11: =VLOOKUP(N11,'ACS Price List'!$16:$180,9,FALSE) -> 0.1121
B12: 2 | C12: APFMEG | D12: N/A | E12: Application fee - Basic or standard connection - Micro-embedded generators | F12: =VLOOKUP(B12,'ACS Price List'!$16:$180,8,FALSE) -> 8001 | G12: dollars ($) | H12: 48.6 | I12: =IFERROR(IF(D12="LR",VLOOKUP(B12,'ACS Price List'!$16:$180,11,FALSE),IF(D12="IS",VLOOKUP(B12,'ACS Price List'!$16:$180,11,FALSE),VLOOKUP(B12,'ACS Price List'!$16:$180,9,FALSE))),"POA") -> 48.6 | K12: =IFERROR(IF(I12="POA","OK",IF(I12-H12=0,"OK","CHANGE")),"CHECK") -> OK | N12: 101 | O12: ACSMCC | P12: Default Metering Services: Primary service - Capital | Q12: =VLOOKUP(N12,'ACS Price List'!$16:$180,8,FALSE) -> 8121 | R12: dollars per day per meter ($/day/meter) | T12: =VLOOKUP(N12,'ACS Price List'!$16:$180,9,FALSE) -> 0.03128
B13: 3 | C13: APFMTA | D13: N/A | E13: Application fee - Basic or standard connection - Micro-embedded generators - Technical assessment required | F13: =VLOOKUP(B13,'ACS Price List'!$16:$180,8,FALSE) -> 8002 | G13: dollars ($) | H13: 220.7 | I13: =IFERROR(IF(D13="LR",VLOOKUP(B13,'ACS Price List'!$16:$180,11,FALSE),IF(D13="IS",VLOOKUP(B13,'ACS Price List'!$16:$180,11,FALSE),VLOOKUP(B13,'ACS Price List'!$16:$180,9,FALSE))),"POA") -> 220.7 | K13: =IFERROR(IF(I13="POA","OK",IF(I13-H13=0,"OK","CHANGE")),"CHECK") -> OK | N13: 102 | O13: ACSMNCC | P13: Default Metering Services: Controlled load - Non-capital | Q13: =VLOOKUP(N13,'ACS Price List'!$16:$180,8,FALSE) -> 8122 | R13: dollars per day per meter ($/day/meter) | T13: =VLOOKUP(N13,'ACS Price List'!$16:$180,9,FALSE) -> 0.04121
B14: 4 | C14: APFRED | D14: N/A | E14: Application fee - Real estate development connection | F14: =VLOOKUP(B14,'ACS Price List'!$16:$180,8,FALSE) -> 8003 | G14: dollars ($) | H14: 930.2 | I14: =IFERROR(IF(D14="LR",VLOOKUP(B14,'ACS Price List'!$16:$180,11,FALSE),IF(D14="IS",VLOOKUP(B14,'ACS Price List'!$16:$180,11,FALSE),VLOOKUP(B14,'ACS Price List'!$16:$180,9,FALSE))),"POA") -> 930.2 | K14: =IFERROR(IF(I14="POA","OK",IF(I14-H14=0,"OK","CHANGE")),"CHECK") -> OK | N14: 103 | O14: ACSMCC | P14: Default Metering Services: Controlled load - Capital | Q14: =VLOOKUP(N14,'ACS Price List'!$16:$180,8,FALSE) -> 8123 | R14: dollars per day per meter ($/day/meter) | T14: =VLOOKUP(N14,'ACS Price List'!$16:$180,9,FALSE) -> 0.0115
B15: 5 | C15: PPQA | D15: N/A | E15: Protection and Power Quality assessment prior to connection | F15: =VLOOKUP(B15,'ACS Price List'!$16:$180,8,FALSE) -> 8004 | G15: dollars ($) | H15: 1376.7 | I15: =IFERROR(IF(D15="LR",VLOOKUP(B15,'ACS Price List'!$16:$180,11,FALSE),IF(D15="IS",VLOOKUP(B15,'ACS Price List'!$16:$180,11,FALSE),VLOOKUP(B15,'ACS Price List'!$16:$180,9,FALSE))),"POA") -> 1376.7 | K15: =IFERROR(IF(I15="POA","OK",IF(I15-H15=0,"OK","CHANGE")),"CHECK") -> OK | N15: 104 | O15: ACSMNCC | P15: Default Metering Services: Embedded generation - Non-capital | Q15: =VLOOKUP(N15,'ACS Price List'!$16:$180,8,FALSE) -> 8124 | R15: dollars per day per meter ($/day/meter) | T15: =VLOOKUP(N15,'ACS Price List'!$16:$180,9,FALSE) -> 0.02787
B16: 6 | C16: TBSSPU | D16: UR | E16: Temporary connection, not in permanent position - single phase metered - urban/short rural feeders | F16: =VLOOKUP(B16,'ACS Price List'!$16:$180,8,FALSE) -> 8020 | G16: dollars ($) | H16: 412.7 | I16: =IFERROR(IF(D16="LR",VLOOKUP(B16,'ACS Price List'!$16:$180,11,FALSE),IF(D16="IS",VLOOKUP(B16,'ACS Price List'!$16:$180,11,FALSE),VLOOKUP(B16,'ACS Price List'!$16:$180,9,FALSE))),"POA") -> 330.2 | K16: =IFERROR(IF(I16="POA","OK",IF(I16-H16=0,"OK","CHANGE")),"CHECK") -> CHANGE | N16: 105 | O16: ACSMCC | P16: Default Metering Services: Embedded generation - Capital | Q16: =VLOOKUP(N16,'ACS Price List'!$16:$180,8,FALSE) -> 8125 | R16: dollars per day per meter ($/day/meter) | T16: =VLOOKUP(N16,'ACS Price List'!$16:$180,9,FALSE) -> 0.00778
B17: 8 | C17: TBSMPU | D17: UR | E17: Temporary connection, not in permanent position - multi phase metered - urban/short rural feeders | F17: =VLOOKUP(B17,'ACS Price List'!$16:$180,8,FALSE) -> 8024 | G17: dollars ($) | H17: 412.7 | I17: =IFERROR(IF(D17="LR",VLOOKUP(B17,'ACS Price List'!$16:$180,11,FALSE),IF(D17="IS",VLOOKUP(B17,'ACS Price List'!$16:$180,11,FALSE),VLOOKUP(B17,'ACS Price List'!$16:$180,9,FALSE))),"POA") -> 330.2 | K17: =IFERROR(IF(I17="POA","OK",IF(I17-H17=0,"OK","CHANGE")),"CHECK") -> CHANGE | N17: 130 | O17: ACSEOOMA | P17: Public Lighting Services: EO&O - Major | Q17: =VLOOKUP(N17,'ACS Price List'!$16:$180,8,FALSE) -> 8130 | R17: dollars per day per light ($/day/light) | T17: =VLOOKUP(N17,'ACS Price List'!$16:$180,9,FALSE) -> 1.1558
