Workbook
Name aggregatetrialthreshold: #REF!
Name cancelfutureyear1: #REF!
Name cancelfutureyear2: #REF!
Name cancelfutureyear3: #REF!
Name cancelfutureyear4: #REF!
Name cancelfutureyear5: #REF!
Name cents: #REF!
Name consmultiplier: #REF!
Name consoutputs: #REF!
Name consprofile: #REF!
Name consprofilemultiplier: #REF!
Name currentyear: #REF!
Name day: #REF!
Name daysperhighsn: #REF!
Name daysperhighsn_currentyear: #REF!
Name daysperhighsn_previousyear: #REF!
Name daysperlowsn: #REF!
Name daysperlowsn_currentyear: #REF!
Name daysperlowsn_previousyear: #REF!
Name daysperossn: #REF!
Name daysperossn_currentyear: #REF!
Name daysperossn_previousyear: #REF!
Name daysperyear: #REF!
Name daysperyear_currentyear: #REF!
Name daysperyear_previousyear: #REF!
Name DNSP: #REF!
Name dollars: #REF!
Name DuosTariffs: #REF!
Name Forecastinflation: #REF!
Name forecastyear: #REF!
Name highsn: #REF!
Name IndicativePricesICYr1: #REF!
Name IndicativePricesICYr2: #REF!
Name IndicativePricesICYr3: #REF!
Name IndicativePricesICYr4: #REF!
Name IndicativePricesICYr5: #REF!
Name IndicativePricesSCSYr1: #REF!
Name IndicativePricesSCSYr2: #REF!
Name IndicativePricesSCSYr3: #REF!
Name IndicativePricesSCSYr4: #REF!
Name IndicativePricesSCSYr5: #REF!
Name individualtrialthreshold: #REF!
Name JSTariffs: #REF!
Name lowsn: #REF!
Name materialitythreshold: #REF!
Name millions: #REF!
Name month: #REF!
Name ossn: #REF!
Name outputsmultiplier: #REF!
Name outputtableunits: #REF!
Name previousyear: #REF!
Name RCP_firstyear: #REF!
Name RCP_fourthyear: #REF!
Name RCP_lastyear: #REF!
Name RCP_secondyear: #REF!
Name RCP_thirdyear: #REF!
Name RCPminus1: #REF!
Name RCPminus2: #REF!
Name RCPminus3: #REF!
Name RCPminus4: #REF!

Sheet Network 2026-27
B2: Network tariff schedule
B3: Date of Application - 1 July 2026 | G3: Fixed | H3: Anytime | I3: Block 1 | J3: Block 2 | K3: Peak | L3: Shoulder | M3: Summer peak | N3: Summer shoulder | O3: Winter peak | P3: Off-peak | Q3: Dedicated | R3: Solar soak | S3: Export charge | T3: Export reward | U3: Capacity | V3: Critical peak | W3: Monthly peak | X3: Monthly off-peak
B5: Tariff class | C5: Tariff code | D5: Tariff Structure | E5: Description | F5: Closed to New Entrants | G5: Standing charge | H5: Anytime | I5: Block 1 | J5: Block 2 | K5: Peak | L5: Shoulder all year | M5: Summer peak | N5: Summer shoulder | O5: Winter peak | P5: Off Peak | Q5: Dedicated circuit | R5: Solar soak | S5: Export charge^ | T5: Export reward | U5: Capacity | V5: Critical peak demand | W5: Monthly peak kW demand | X5: Monthly off peak kW demand
G6: $/year | H6: c/kWh | I6: c/kWh | J6: c/kWh | K6: c/kWh | L6: c/kWh | M6: c/kWh | N6: c/kWh | O6: c/kWh | P6: c/kWh | Q6: c/kWh | R6: c/kWh | S6: c/kWh | T6: c/kWh | U6: $/kVA/yr | V6: $/kVA/yr | W6: $/kW/mth | X6: $/kW/mth
B7: Residential | C7: NEE11 | D7: 1 | E7: Small single rate | F7: No | G7: =IF(SUM('Distribution 2026-27:Jurisdictional 2026-27'!G7)=0,"",SUM('Distribution 2026-27:Jurisdictional 2026-27'!G7)) -> 145.30522 | H7: =IF(SUM('Distribution 2026-27:Jurisdictional 2026-27'!H7)=0,"",SUM('Distribution 2026-27:Jurisdictional 2026-27'!H7)) | I7: =IF(SUM('Distribution 2026-27:Jurisdictional 2026-27'!I7)=0,"",SUM('Distribution 2026-27:Jurisdictional 2026-27'!I7)) -> 13.429652 | J7: =IF(SUM('Distribution 2026-27:Jurisdictional 2026-27'!J7)=0,"",SUM('Distribution 2026-27:Jurisdictional 2026-27'!J7)) -> 13.429652 | K7: =IF(SUM('Distribution 2026-27:Jurisdictional 2026-27'!K7)=0,"",SUM('Distribution 2026-27:Jurisdictional 2026-27'!K7)) | L7: =IF(SUM('Distribution 2026-27:Jurisdictional 2026-27'!L7)=0,"",SUM('Distribution 2026-27:Jurisdictional 2026-27'!L7)) | M7: =IF(SUM('Distribution 2026-27:Jurisdictional 2026-27'!M7)=0,"",SUM('Distribution 2026-27:Jurisdictional 2026-27'!M7)) | N7: =IF(SUM('Distribution 2026-27:Jurisdictional 2026-27'!N7)=0,"",SUM('Distribution 2026-27:Jurisdictional 2026-27'!N7)) | ... X7: =IF(SUM('Distribution 2026-27:Jurisdictional 2026-27'!X7)=0,"",SUM('Distribution 2026-27:Jurisdictional 2026-27'!X7))
C8: NEE11S | D8: 1 | E8: Small single rate standard feed in | F8: No | G8: =IF(SUM('Distribution 2026-27:Jurisdictional 2026-27'!G8)=0,"",SUM('Distribution 2026-27:Jurisdictional 2026-27'!G8)) -> 145.30522 | H8: =IF(SUM('Distribution 2026-27:Jurisdictional 2026-27'!H8)=0,"",SUM('Distribution 2026-27:Jurisdictional 2026-27'!H8)) | I8: =IF(SUM('Distribution 2026-27:Jurisdictional 2026-27'!I8)=0,"",SUM('Distribution 2026-27:Jurisdictional 2026-27'!I8)) -> 13.429652 | J8: =IF(SUM('Distribution 2026-27:Jurisdictional 2026-27'!J8)=0,"",SUM('Distribution 2026-27:Jurisdictional 2026-27'!J8)) -> 13.429652 | K8: =IF(SUM('Distribution 2026-27:Jurisdictional 2026-27'!K8)=0,"",SUM('Distribution 2026-27:Jurisdictional 2026-27'!K8)) | L8: =IF(SUM('Distribution 2026-27:Jurisdictional 2026-27'!L8)=0,"",SUM('Distribution 2026-27:Jurisdictional 2026-27'!L8)) | M8: =IF(SUM('Distribution 2026-27:Jurisdictional 2026-27'!M8)=0,"",SUM('Distribution 2026-27:Jurisdictional 2026-27'!M8)) | N8: =IF(SUM('Distribution 2026-27:Jurisdictional 2026-27'!N8)=0,"",SUM('Distribution 2026-27:Jurisdictional 2026-27'!N8)) | ... X8: =IF(SUM('Distribution 2026-27:Jurisdictional 2026-27'!X8)=0,"",SUM('Distribution 2026-27:Jurisdictional 2026-27'!X8))
C9: NEE19 | D9: 1 & 19 | E9: Small single rate & dedicated circuit 24 hour | F9: No | G9: =IF(SUM('Distribution 2026-27:Jurisdictional 2026-27'!G9)=0,"",SUM('Distribution 2026-27:Jurisdictional 2026-27'!G9)) -> 145.30522 | H9: =IF(SUM('Distribution 2026-27:Jurisdictional 2026-27'!H9)=0,"",SUM('Distribution 2026-27:Jurisdictional 2026-27'!H9)) | I9: =IF(SUM('Distribution 2026-27:Jurisdictional 2026-27'!I9)=0,"",SUM('Distribution 2026-27:Jurisdictional 2026-27'!I9)) -> 13.429652 | J9: =IF(SUM('Distribution 2026-27:Jurisdictional 2026-27'!J9)=0,"",SUM('Distribution 2026-27:Jurisdictional 2026-27'!J9)) -> 13.429652 | K9: =IF(SUM('Distribution 2026-27:Jurisdictional 2026-27'!K9)=0,"",SUM('Distribution 2026-27:Jurisdictional 2026-27'!K9)) | L9: =IF(SUM('Distribution 2026-27:Jurisdictional 2026-27'!L9)=0,"",SUM('Distribution 2026-27:Jurisdictional 2026-27'!L9)) | M9: =IF(SUM('Distribution 2026-27:Jurisdictional 2026-27'!M9)=0,"",SUM('Distribution 2026-27:Jurisdictional 2026-27'!M9)) | N9: =IF(SUM('Distribution 2026-27:Jurisdictional 2026-27'!N9)=0,"",SUM('Distribution 2026-27:Jurisdictional 2026-27'!N9)) | ... X9: =IF(SUM('Distribution 2026-27:Jurisdictional 2026-27'!X9)=0,"",SUM('Distribution 2026-27:Jurisdictional 2026-27'!X9))
C10: NASS11 | D10: 21 | E10: Small residential time of use | F10: No | G10: =IF(SUM('Distribution 2026-27:Jurisdictional 2026-27'!G10)=0,"",SUM('Distribution 2026-27:Jurisdictional 2026-27'!G10)) -> 145.30522 | H10: =IF(SUM('Distribution 2026-27:Jurisdictional 2026-27'!H10)=0,"",SUM('Distribution 2026-27:Jurisdictional 2026-27'!H10)) | I10: =IF(SUM('Distribution 2026-27:Jurisdictional 2026-27'!I10)=0,"",SUM('Distribution 2026-27:Jurisdictional 2026-27'!I10)) | J10: =IF(SUM('Distribution 2026-27:Jurisdictional 2026-27'!J10)=0,"",SUM('Distribution 2026-27:Jurisdictional 2026-27'!J10)) | K10: =IF(SUM('Distribution 2026-27:Jurisdictional 2026-27'!K10)=0,"",SUM('Distribution 2026-27:Jurisdictional 2026-27'!K10)) -> 26.955621 | L10: =IF(SUM('Distribution 2026-27:Jurisdictional 2026-27'!L10)=0,"",SUM('Distribution 2026-27:Jurisdictional 2026-27'!L10)) | M10: =IF(SUM('Distribution 2026-27:Jurisdictional 2026-27'!M10)=0,"",SUM('Distribution 2026-27:Jurisdictional 2026-27'!M10)) | N10: =IF(SUM('Distribution 2026-27:Jurisdictional 2026-27'!N10)=0,"",SUM('Distribution 2026-27:Jurisdictional 2026-27'!N10)) | ... X10: =IF(SUM('Distribution 2026-27:Jurisdictional 2026-27'!X10)=0,"",SUM('Distribution 2026-27:Jurisdictional 2026-27'!X10)) | AB10: NAST11
C11: NASS11S | D11: 21 | E11: Small residential time of use standard feed in | F11: No | G11: =IF(SUM('Distribution 2026-27:Jurisdictional 2026-27'!G11)=0,"",SUM('Distribution 2026-27:Jurisdictional 2026-27'!G11)) -> 145.30522 | H11: =IF(SUM('Distribution 2026-27:Jurisdictional 2026-27'!H11)=0,"",SUM('Distribution 2026-27:Jurisdictional 2026-27'!H11)) | I11: =IF(SUM('Distribution 2026-27:Jurisdictional 2026-27'!I11)=0,"",SUM('Distribution 2026-27:Jurisdictional 2026-27'!I11)) | J11: =IF(SUM('Distribution 2026-27:Jurisdictional 2026-27'!J11)=0,"",SUM('Distribution 2026-27:Jurisdictional 2026-27'!J11)) | K11: =IF(SUM('Distribution 2026-27:Jurisdictional 2026-27'!K11)=0,"",SUM('Distribution 2026-27:Jurisdictional 2026-27'!K11)) -> 26.955621 | L11: =IF(SUM('Distribution 2026-27:Jurisdictional 2026-27'!L11)=0,"",SUM('Distribution 2026-27:Jurisdictional 2026-27'!L11)) | M11: =IF(SUM('Distribution 2026-27:Jurisdictional 2026-27'!M11)=0,"",SUM('Distribution 2026-27:Jurisdictional 2026-27'!M11)) | N11: =IF(SUM('Distribution 2026-27:Jurisdictional 2026-27'!N11)=0,"",SUM('Distribution 2026-27:Jurisdictional 2026-27'!N11)) | ... X11: =IF(SUM('Distribution 2026-27:Jurisdictional 2026-27'!X11)=0,"",SUM('Distribution 2026-27:Jurisdictional 2026-27'!X11)) | AB11: NAST11S
C12: NAST17 | D12: 19 & 21 | E12: Small residential time of use & dedicated circuit 24 hour | F12: No | G12: =IF(SUM('Distribution 2026-27:Jurisdictional 2026-27'!G12)=0,"",SUM('Distribution 2026-27:Jurisdictional 2026-27'!G12)) -> 145.30522 | H12: =IF(SUM('Distribution 2026-27:Jurisdictional 2026-27'!H12)=0,"",SUM('Distribution 2026-27:Jurisdictional 2026-27'!H12)) | I12: =IF(SUM('Distribution 2026-27:Jurisdictional 2026-27'!I12)=0,"",SUM('Distribution 2026-27:Jurisdictional 2026-27'!I12)) | J12: =IF(SUM('Distribution 2026-27:Jurisdictional 2026-27'!J12)=0,"",SUM('Distribution 2026-27:Jurisdictional 2026-27'!J12)) | K12: =IF(SUM('Distribution 2026-27:Jurisdictional 2026-27'!K12)=0,"",SUM('Distribution 2026-27:Jurisdictional 2026-27'!K12)) -> 26.955621 | L12: =IF(SUM('Distribution 2026-27:Jurisdictional 2026-27'!L12)=0,"",SUM('Distribution 2026-27:Jurisdictional 2026-27'!L12)) | M12: =IF(SUM('Distribution 2026-27:Jurisdictional 2026-27'!M12)=0,"",SUM('Distribution 2026-27:Jurisdictional 2026-27'!M12)) | N12: =IF(SUM('Distribution 2026-27:Jurisdictional 2026-27'!N12)=0,"",SUM('Distribution 2026-27:Jurisdictional 2026-27'!N12)) | ... X12: =IF(SUM('Distribution 2026-27:Jurisdictional 2026-27'!X12)=0,"",SUM('Distribution 2026-27:Jurisdictional 2026-27'!X12))
C13: NEE24 | D13: 4 | E13: Small two rate 8:00 to 8:00* | F13: Yes | G13: =IF(SUM('Distribution 2026-27:Jurisdictional 2026-27'!G13)=0,"",SUM('Distribution 2026-27:Jurisdictional 2026-27'!G13)) -> 145.30522 | H13: =IF(SUM('Distribution 2026-27:Jurisdictional 2026-27'!H13)=0,"",SUM('Distribution 2026-27:Jurisdictional 2026-27'!H13)) | I13: =IF(SUM('Distribution 2026-27:Jurisdictional 2026-27'!I13)=0,"",SUM('Distribution 2026-27:Jurisdictional 2026-27'!I13)) | J13: =IF(SUM('Distribution 2026-27:Jurisdictional 2026-27'!J13)=0,"",SUM('Distribution 2026-27:Jurisdictional 2026-27'!J13)) | K13: =IF(SUM('Distribution 2026-27:Jurisdictional 2026-27'!K13)=0,"",SUM('Distribution 2026-27:Jurisdictional 2026-27'!K13)) -> 12.053444 | L13: =IF(SUM('Distribution 2026-27:Jurisdictional 2026-27'!L13)=0,"",SUM('Distribution 2026-27:Jurisdictional 2026-27'!L13)) | M13: =IF(SUM('Distribution 2026-27:Jurisdictional 2026-27'!M13)=0,"",SUM('Distribution 2026-27:Jurisdictional 2026-27'!M13)) | N13: =IF(SUM('Distribution 2026-27:Jurisdictional 2026-27'!N13)=0,"",SUM('Distribution 2026-27:Jurisdictional 2026-27'!N13)) | ... X13: =IF(SUM('Distribution 2026-27:Jurisdictional 2026-27'!X13)=0,"",SUM('Distribution 2026-27:Jurisdictional 2026-27'!X13))
C14: NSP20 | D14: 7 | E14: Small interval meter time of use | F14: Yes | G14: =IF(SUM('Distribution 2026-27:Jurisdictional 2026-27'!G14)=0,"",SUM('Distribution 2026-27:Jurisdictional 2026-27'!G14)) -> 145.30522 | H14: =IF(SUM('Distribution 2026-27:Jurisdictional 2026-27'!H14)=0,"",SUM('Distribution 2026-27:Jurisdictional 2026-27'!H14)) | I14: =IF(SUM('Distribution 2026-27:Jurisdictional 2026-27'!I14)=0,"",SUM('Distribution 2026-27:Jurisdictional 2026-27'!I14)) | J14: =IF(SUM('Distribution 2026-27:Jurisdictional 2026-27'!J14)=0,"",SUM('Distribution 2026-27:Jurisdictional 2026-27'!J14)) | K14: =IF(SUM('Distribution 2026-27:Jurisdictional 2026-27'!K14)=0,"",SUM('Distribution 2026-27:Jurisdictional 2026-27'!K14)) | L14: =IF(SUM('Distribution 2026-27:Jurisdictional 2026-27'!L14)=0,"",SUM('Distribution 2026-27:Jurisdictional 2026-27'!L14)) | M14: =IF(SUM('Distribution 2026-27:Jurisdictional 2026-27'!M14)=0,"",SUM('Distribution 2026-27:Jurisdictional 2026-27'!M14)) -> 47.802974 | N14: =IF(SUM('Distribution 2026-27:Jurisdictional 2026-27'!N14)=0,"",SUM('Distribution 2026-27:Jurisdictional 2026-27'!N14)) -> 42.259581 | ... X14: =IF(SUM('Distribution 2026-27:Jurisdictional 2026-27'!X14)=0,"",SUM('Distribution 2026-27:Jurisdictional 2026-27'!X14))
C15: NSP23 | D15: 7 | E15: Small interval meter time of use solar installation standard feed in | F15: Yes | G15: =IF(SUM('Distribution 2026-27:Jurisdictional 2026-27'!G15)=0,"",SUM('Distribution 2026-27:Jurisdictional 2026-27'!G15)) -> 145.30522 | H15: =IF(SUM('Distribution 2026-27:Jurisdictional 2026-27'!H15)=0,"",SUM('Distribution 2026-27:Jurisdictional 2026-27'!H15)) | I15: =IF(SUM('Distribution 2026-27:Jurisdictional 2026-27'!I15)=0,"",SUM('Distribution 2026-27:Jurisdictional 2026-27'!I15)) | J15: =IF(SUM('Distribution 2026-27:Jurisdictional 2026-27'!J15)=0,"",SUM('Distribution 2026-27:Jurisdictional 2026-27'!J15)) | K15: =IF(SUM('Distribution 2026-27:Jurisdictional 2026-27'!K15)=0,"",SUM('Distribution 2026-27:Jurisdictional 2026-27'!K15)) | L15: =IF(SUM('Distribution 2026-27:Jurisdictional 2026-27'!L15)=0,"",SUM('Distribution 2026-27:Jurisdictional 2026-27'!L15)) | M15: =IF(SUM('Distribution 2026-27:Jurisdictional 2026-27'!M15)=0,"",SUM('Distribution 2026-27:Jurisdictional 2026-27'!M15)) -> 47.802974 | N15: =IF(SUM('Distribution 2026-27:Jurisdictional 2026-27'!N15)=0,"",SUM('Distribution 2026-27:Jurisdictional 2026-27'!N15)) -> 42.259581 | ... X15: =IF(SUM('Distribution 2026-27:Jurisdictional 2026-27'!X15)=0,"",SUM('Distribution 2026-27:Jurisdictional 2026-27'!X15))
C16: NEE30 | D16: 9 | E16: Small dedicated circuit | F16: Yes | G16: =IF(SUM('Distribution 2026-27:Jurisdictional 2026-27'!G16)=0,"",SUM('Distribution 2026-27:Jurisdictional 2026-27'!G16)) | H16: =IF(SUM('Distribution 2026-27:Jurisdictional 2026-27'!H16)=0,"",SUM('Distribution 2026-27:Jurisdictional 2026-27'!H16)) | I16: =IF(SUM('Distribution 2026-27:Jurisdictional 2026-27'!I16)=0,"",SUM('Distribution 2026-27:Jurisdictional 2026-27'!I16)) | J16: =IF(SUM('Distribution 2026-27:Jurisdictional 2026-27'!J16)=0,"",SUM('Distribution 2026-27:Jurisdictional 2026-27'!J16)) | K16: =IF(SUM('Distribution 2026-27:Jurisdictional 2026-27'!K16)=0,"",SUM('Distribution 2026-27:Jurisdictional 2026-27'!K16)) | L16: =IF(SUM('Distribution 2026-27:Jurisdictional 2026-27'!L16)=0,"",SUM('Distribution 2026-27:Jurisdictional 2026-27'!L16)) | M16: =IF(SUM('Distribution 2026-27:Jurisdictional 2026-27'!M16)=0,"",SUM('Distribution 2026-27:Jurisdictional 2026-27'!M16)) | N16: =IF(SUM('Distribution 2026-27:Jurisdictional 2026-27'!N16)=0,"",SUM('Distribution 2026-27:Jurisdictional 2026-27'!N16)) | ... X16: =IF(SUM('Distribution 2026-27:Jurisdictional 2026-27'!X16)=0,"",SUM('Distribution 2026-27:Jurisdictional 2026-27'!X16))
C17: NEE31 | D17: 10 | E17: Small dedicated circuit with afternoon boost | F17: Yes | G17: =IF(SUM('Distribution 2026-27:Jurisdictional 2026-27'!G17)=0,"",SUM('Distribution 2026-27:Jurisdictional 2026-27'!G17)) | H17: =IF(SUM('Distribution 2026-27:Jurisdictional 2026-27'!H17)=0,"",SUM('Distribution 2026-27:Jurisdictional 2026-27'!H17)) | I17: =IF(SUM('Distribution 2026-27:Jurisdictional 2026-27'!I17)=0,"",SUM('Distribution 2026-27:Jurisdictional 2026-27'!I17)) | J17: =IF(SUM('Distribution 2026-27:Jurisdictional 2026-27'!J17)=0,"",SUM('Distribution 2026-27:Jurisdictional 2026-27'!J17)) | K17: =IF(SUM('Distribution 2026-27:Jurisdictional 2026-27'!K17)=0,"",SUM('Distribution 2026-27:Jurisdictional 2026-27'!K17)) | L17: =IF(SUM('Distribution 2026-27:Jurisdictional 2026-27'!L17)=0,"",SUM('Distribution 2026-27:Jurisdictional 2026-27'!L17)) | M17: =IF(SUM('Distribution 2026-27:Jurisdictional 2026-27'!M17)=0,"",SUM('Distribution 2026-27:Jurisdictional 2026-27'!M17)) | N17: =IF(SUM('Distribution 2026-27:Jurisdictional 2026-27'!N17)=0,"",SUM('Distribution 2026-27:Jurisdictional 2026-27'!N17)) | ... X17: =IF(SUM('Distribution 2026-27:Jurisdictional 2026-27'!X17)=0,"",SUM('Distribution 2026-27:Jurisdictional 2026-27'!X17))
C18: NEE32 | D18: 11 | E18: Small dedicated circuit 8:00 to 8:00 | F18: Yes | G18: =IF(SUM('Distribution 2026-27:Jurisdictional 2026-27'!G18)=0,"",SUM('Distribution 2026-27:Jurisdictional 2026-27'!G18)) | H18: =IF(SUM('Distribution 2026-27:Jurisdictional 2026-27'!H18)=0,"",SUM('Distribution 2026-27:Jurisdictional 2026-27'!H18)) | I18: =IF(SUM('Distribution 2026-27:Jurisdictional 2026-27'!I18)=0,"",SUM('Distribution 2026-27:Jurisdictional 2026-27'!I18)) | J18: =IF(SUM('Distribution 2026-27:Jurisdictional 2026-27'!J18)=0,"",SUM('Distribution 2026-27:Jurisdictional 2026-27'!J18)) | K18: =IF(SUM('Distribution 2026-27:Jurisdictional 2026-27'!K18)=0,"",SUM('Distribution 2026-27:Jurisdictional 2026-27'!K18)) | L18: =IF(SUM('Distribution 2026-27:Jurisdictional 2026-27'!L18)=0,"",SUM('Distribution 2026-27:Jurisdictional 2026-27'!L18)) | M18: =IF(SUM('Distribution 2026-27:Jurisdictional 2026-27'!M18)=0,"",SUM('Distribution 2026-27:Jurisdictional 2026-27'!M18)) | N18: =IF(SUM('Distribution 2026-27:Jurisdictional 2026-27'!N18)=0,"",SUM('Distribution 2026-27:Jurisdictional 2026-27'!N18)) | ... X18: =IF(SUM('Distribution 2026-27:Jurisdictional 2026-27'!X18)=0,"",SUM('Distribution 2026-27:Jurisdictional 2026-27'!X18))
C19: NEE33 | D19: 19 | E19: Small dedicated circuit 24 hour | F19: Yes | G19: =IF(SUM('Distribution 2026-27:Jurisdictional 2026-27'!G19)=0,"",SUM('Distribution 2026-27:Jurisdictional 2026-27'!G19)) | H19: =IF(SUM('Distribution 2026-27:Jurisdictional 2026-27'!H19)=0,"",SUM('Distribution 2026-27:Jurisdictional 2026-27'!H19)) | I19: =IF(SUM('Distribution 2026-27:Jurisdictional 2026-27'!I19)=0,"",SUM('Distribution 2026-27:Jurisdictional 2026-27'!I19)) | J19: =IF(SUM('Distribution 2026-27:Jurisdictional 2026-27'!J19)=0,"",SUM('Distribution 2026-27:Jurisdictional 2026-27'!J19)) | K19: =IF(SUM('Distribution 2026-27:Jurisdictional 2026-27'!K19)=0,"",SUM('Distribution 2026-27:Jurisdictional 2026-27'!K19)) | L19: =IF(SUM('Distribution 2026-27:Jurisdictional 2026-27'!L19)=0,"",SUM('Distribution 2026-27:Jurisdictional 2026-27'!L19)) | M19: =IF(SUM('Distribution 2026-27:Jurisdictional 2026-27'!M19)=0,"",SUM('Distribution 2026-27:Jurisdictional 2026-27'!M19)) | N19: =IF(SUM('Distribution 2026-27:Jurisdictional 2026-27'!N19)=0,"",SUM('Distribution 2026-27:Jurisdictional 2026-27'!N19)) | ... X19: =IF(SUM('Distribution 2026-27:Jurisdictional 2026-27'!X19)=0,"",SUM('Distribution 2026-27:Jurisdictional 2026-27'!X19))
C20: RCER11 | D20: 20 | E20: Residential CER | F20: No | G20: =IF(SUM('Distribution 2026-27:Jurisdictional 2026-27'!G20)=0,"",SUM('Distribution 2026-27:Jurisdictional 2026-27'!G20)) -> 145.30522 | H20: =IF(SUM('Distribution 2026-27:Jurisdictional 2026-27'!H20)=0,"",SUM('Distribution 2026-27:Jurisdictional 2026-27'!H20)) | I20: =IF(SUM('Distribution 2026-27:Jurisdictional 2026-27'!I20)=0,"",SUM('Distribution 2026-27:Jurisdictional 2026-27'!I20)) | J20: =IF(SUM('Distribution 2026-27:Jurisdictional 2026-27'!J20)=0,"",SUM('Distribution 2026-27:Jurisdictional 2026-27'!J20)) | K20: =IF(SUM('Distribution 2026-27:Jurisdictional 2026-27'!K20)=0,"",SUM('Distribution 2026-27:Jurisdictional 2026-27'!K20)) -> 26.955621 | L20: =IF(SUM('Distribution 2026-27:Jurisdictional 2026-27'!L20)=0,"",SUM('Distribution 2026-27:Jurisdictional 2026-27'!L20)) | M20: =IF(SUM('Distribution 2026-27:Jurisdictional 2026-27'!M20)=0,"",SUM('Distribution 2026-27:Jurisdictional 2026-27'!M20)) | N20: =IF(SUM('Distribution 2026-27:Jurisdictional 2026-27'!N20)=0,"",SUM('Distribution 2026-27:Jurisdictional 2026-27'!N20)) | ... X20: =IF(SUM('Distribution 2026-27:Jurisdictional 2026-27'!X20)=0,"",SUM('Distribution 2026-27:Jurisdictional 2026-27'!X20))
B22: * Available to customers in rural areas with heating requirement
B23: * Includes a BEL of 1 kWh per day
B25: Tariff class | C25: Tariff code | D25: Tariff Structure | E25: Description | F25: Closed to New Entrants | G25: Standing charge | H25: Anytime | I25: Block 1 | J25: Block 2 | K25: Peak | L25: Shoulder all year | M25: Summer peak | N25: Summer shoulder | O25: Winter peak | P25: Off Peak | Q25: Dedicated circuit | R25: Solar soak | S25: Export charge | T25: Export reward | U25: Capacity | V25: Critical peak demand | W25: Monthly peak kW demand | X25: Monthly off peak kW demand
G26: $/year | H26: c/kWh | I26: c/kWh | J26: c/kWh | K26: c/kWh | L26: c/kWh | M26: c/kWh | N26: c/kWh | O26: c/kWh | P26: c/kWh | Q26: c/kWh | R26: c/kWh | S26: c/kWh | T26: c/kWh | U26: $/kVA/yr | V26: $/kVA/yr | W26: $/kW/mth | X26: $/kW/mth
B27: Small industrial & commercial | C27: NEE12 | D27: 1 | E27: Small single rate | F27: No | G27: =IF(SUM('Distribution 2026-27:Jurisdictional 2026-27'!G27)=0,"",SUM('Distribution 2026-27:Jurisdictional 2026-27'!G27)) -> 148.93785 | H27: =IF(SUM('Distribution 2026-27:Jurisdictional 2026-27'!H27)=0,"",SUM('Distribution 2026-27:Jurisdictional 2026-27'!H27)) | I27: =IF(SUM('Distribution 2026-27:Jurisdictional 2026-27'!I27)=0,"",SUM('Distribution 2026-27:Jurisdictional 2026-27'!I27)) -> 17.607284 | J27: =IF(SUM('Distribution 2026-27:Jurisdictional 2026-27'!J27)=0,"",SUM('Distribution 2026-27:Jurisdictional 2026-27'!J27)) -> 17.607284 | K27: =IF(SUM('Distribution 2026-27:Jurisdictional 2026-27'!K27)=0,"",SUM('Distribution 2026-27:Jurisdictional 2026-27'!K27)) | L27: =IF(SUM('Distribution 2026-27:Jurisdictional 2026-27'!L27)=0,"",SUM('Distribution 2026-27:Jurisdictional 2026-27'!L27)) | M27: =IF(SUM('Distribution 2026-27:Jurisdictional 2026-27'!M27)=0,"",SUM('Distribution 2026-27:Jurisdictional 2026-27'!M27)) | N27: =IF(SUM('Distribution 2026-27:Jurisdictional 2026-27'!N27)=0,"",SUM('Distribution 2026-27:Jurisdictional 2026-27'!N27)) | ... X27: =IF(SUM('Distribution 2026-27:Jurisdictional 2026-27'!X27)=0,"",SUM('Distribution 2026-27:Jurisdictional 2026-27'!X27))
C28: NEE12S | D28: 1 | E28: Small single rate standard feed in | F28: No | G28: =IF(SUM('Distribution 2026-27:Jurisdictional 2026-27'!G28)=0,"",SUM('Distribution 2026-27:Jurisdictional 2026-27'!G28)) -> 148.93785 | H28: =IF(SUM('Distribution 2026-27:Jurisdictional 2026-27'!H28)=0,"",SUM('Distribution 2026-27:Jurisdictional 2026-27'!H28)) | I28: =IF(SUM('Distribution 2026-27:Jurisdictional 2026-27'!I28)=0,"",SUM('Distribution 2026-27:Jurisdictional 2026-27'!I28)) -> 17.607284 | J28: =IF(SUM('Distribution 2026-27:Jurisdictional 2026-27'!J28)=0,"",SUM('Distribution 2026-27:Jurisdictional 2026-27'!J28)) -> 17.607284 | K28: =IF(SUM('Distribution 2026-27:Jurisdictional 2026-27'!K28)=0,"",SUM('Distribution 2026-27:Jurisdictional 2026-27'!K28)) | L28: =IF(SUM('Distribution 2026-27:Jurisdictional 2026-27'!L28)=0,"",SUM('Distribution 2026-27:Jurisdictional 2026-27'!L28)) | M28: =IF(SUM('Distribution 2026-27:Jurisdictional 2026-27'!M28)=0,"",SUM('Distribution 2026-27:Jurisdictional 2026-27'!M28)) | N28: =IF(SUM('Distribution 2026-27:Jurisdictional 2026-27'!N28)=0,"",SUM('Distribution 2026-27:Jurisdictional 2026-27'!N28)) | ... X28: =IF(SUM('Distribution 2026-27:Jurisdictional 2026-27'!X28)=0,"",SUM('Distribution 2026-27:Jurisdictional 2026-27'!X28))
C29: NEE16 | D29: 1 & 9 | E29: Small single rate & dedicated circuit | F29: Yes | G29: =IF(SUM('Distribution 2026-27:Jurisdictional 2026-27'!G29)=0,"",SUM('Distribution 2026-27:Jurisdictional 2026-27'!G29)) -> 148.93785 | H29: =IF(SUM('Distribution 2026-27:Jurisdictional 2026-27'!H29)=0,"",SUM('Distribution 2026-27:Jurisdictional 2026-27'!H29)) | I29: =IF(SUM('Distribution 2026-27:Jurisdictional 2026-27'!I29)=0,"",SUM('Distribution 2026-27:Jurisdictional 2026-27'!I29)) -> 17.607284 | J29: =IF(SUM('Distribution 2026-27:Jurisdictional 2026-27'!J29)=0,"",SUM('Distribution 2026-27:Jurisdictional 2026-27'!J29)) -> 17.607284 | K29: =IF(SUM('Distribution 2026-27:Jurisdictional 2026-27'!K29)=0,"",SUM('Distribution 2026-27:Jurisdictional 2026-27'!K29)) | L29: =IF(SUM('Distribution 2026-27:Jurisdictional 2026-27'!L29)=0,"",SUM('Distribution 2026-27:Jurisdictional 2026-27'!L29)) | M29: =IF(SUM('Distribution 2026-27:Jurisdictional 2026-27'!M29)=0,"",SUM('Distribution 2026-27:Jurisdictional 2026-27'!M29)) | N29: =IF(SUM('Distribution 2026-27:Jurisdictional 2026-27'!N29)=0,"",SUM('Distribution 2026-27:Jurisdictional 2026-27'!N29)) | ... X29: =IF(SUM('Distribution 2026-27:Jurisdictional 2026-27'!X29)=0,"",SUM('Distribution 2026-27:Jurisdictional 2026-27'!X29))
C30: NEE17 | D30: 1 & 10 | E30: Small single rate & dedicated circuit with afternoon boost | F30: Yes | G30: =IF(SUM('Distribution 2026-27:Jurisdictional 2026-27'!G30)=0,"",SUM('Distribution 2026-27:Jurisdictional 2026-27'!G30)) -> 148.93785 | H30: =IF(SUM('Distribution 2026-27:Jurisdictional 2026-27'!H30)=0,"",SUM('Distribution 2026-27:Jurisdictional 2026-27'!H30)) | I30: =IF(SUM('Distribution 2026-27:Jurisdictional 2026-27'!I30)=0,"",SUM('Distribution 2026-27:Jurisdictional 2026-27'!I30)) -> 17.607284 | J30: =IF(SUM('Distribution 2026-27:Jurisdictional 2026-27'!J30)=0,"",SUM('Distribution 2026-27:Jurisdictional 2026-27'!J30)) -> 17.607284 | K30: =IF(SUM('Distribution 2026-27:Jurisdictional 2026-27'!K30)=0,"",SUM('Distribution 2026-27:Jurisdictional 2026-27'!K30)) | L30: =IF(SUM('Distribution 2026-27:Jurisdictional 2026-27'!L30)=0,"",SUM('Distribution 2026-27:Jurisdictional 2026-27'!L30)) | M30: =IF(SUM('Distribution 2026-27:Jurisdictional 2026-27'!M30)=0,"",SUM('Distribution 2026-27:Jurisdictional 2026-27'!M30)) | N30: =IF(SUM('Distribution 2026-27:Jurisdictional 2026-27'!N30)=0,"",SUM('Distribution 2026-27:Jurisdictional 2026-27'!N30)) | ... X30: =IF(SUM('Distribution 2026-27:Jurisdictional 2026-27'!X30)=0,"",SUM('Distribution 2026-27:Jurisdictional 2026-27'!X30))
C31: NEE18 | D31: 1 & 11 | E31: Small single rate & dedicated circuit 8:00 to 8:00 | F31: Yes | G31: =IF(SUM('Distribution 2026-27:Jurisdictional 2026-27'!G31)=0,"",SUM('Distribution 2026-27:Jurisdictional 2026-27'!G31)) -> 148.93785 | H31: =IF(SUM('Distribution 2026-27:Jurisdictional 2026-27'!H31)=0,"",SUM('Distribution 2026-27:Jurisdictional 2026-27'!H31)) | I31: =IF(SUM('Distribution 2026-27:Jurisdictional 2026-27'!I31)=0,"",SUM('Distribution 2026-27:Jurisdictional 2026-27'!I31)) -> 17.607284 | J31: =IF(SUM('Distribution 2026-27:Jurisdictional 2026-27'!J31)=0,"",SUM('Distribution 2026-27:Jurisdictional 2026-27'!J31)) -> 17.607284 | K31: =IF(SUM('Distribution 2026-27:Jurisdictional 2026-27'!K31)=0,"",SUM('Distribution 2026-27:Jurisdictional 2026-27'!K31)) | L31: =IF(SUM('Distribution 2026-27:Jurisdictional 2026-27'!L31)=0,"",SUM('Distribution 2026-27:Jurisdictional 2026-27'!L31)) | M31: =IF(SUM('Distribution 2026-27:Jurisdictional 2026-27'!M31)=0,"",SUM('Distribution 2026-27:Jurisdictional 2026-27'!M31)) | N31: =IF(SUM('Distribution 2026-27:Jurisdictional 2026-27'!N31)=0,"",SUM('Distribution 2026-27:Jurisdictional 2026-27'!N31)) | ... X31: =IF(SUM('Distribution 2026-27:Jurisdictional 2026-27'!X31)=0,"",SUM('Distribution 2026-27:Jurisdictional 2026-27'!X31))
C32: NAST12 | D32: 17 | E32: Small business time of use | F32: No | G32: =IF(SUM('Distribution 2026-27:Jurisdictional 2026-27'!G32)=0,"",SUM('Distribution 2026-27:Jurisdictional 2026-27'!G32)) -> 148.93785 | H32: =IF(SUM('Distribution 2026-27:Jurisdictional 2026-27'!H32)=0,"",SUM('Distribution 2026-27:Jurisdictional 2026-27'!H32)) | I32: =IF(SUM('Distribution 2026-27:Jurisdictional 2026-27'!I32)=0,"",SUM('Distribution 2026-27:Jurisdictional 2026-27'!I32)) | J32: =IF(SUM('Distribution 2026-27:Jurisdictional 2026-27'!J32)=0,"",SUM('Distribution 2026-27:Jurisdictional 2026-27'!J32)) | K32: =IF(SUM('Distribution 2026-27:Jurisdictional 2026-27'!K32)=0,"",SUM('Distribution 2026-27:Jurisdictional 2026-27'!K32)) -> 20.773124 | L32: =IF(SUM('Distribution 2026-27:Jurisdictional 2026-27'!L32)=0,"",SUM('Distribution 2026-27:Jurisdictional 2026-27'!L32)) | M32: =IF(SUM('Distribution 2026-27:Jurisdictional 2026-27'!M32)=0,"",SUM('Distribution 2026-27:Jurisdictional 2026-27'!M32)) | N32: =IF(SUM('Distribution 2026-27:Jurisdictional 2026-27'!N32)=0,"",SUM('Distribution 2026-27:Jurisdictional 2026-27'!N32)) | ... X32: =IF(SUM('Distribution 2026-27:Jurisdictional 2026-27'!X32)=0,"",SUM('Distribution 2026-27:Jurisdictional 2026-27'!X32))
C33: NAST12S | D33: 17 | E33: Small business time of use standard feed in | F33: No | G33: =IF(SUM('Distribution 2026-27:Jurisdictional 2026-27'!G33)=0,"",SUM('Distribution 2026-27:Jurisdictional 2026-27'!G33)) -> 148.93785 | H33: =IF(SUM('Distribution 2026-27:Jurisdictional 2026-27'!H33)=0,"",SUM('Distribution 2026-27:Jurisdictional 2026-27'!H33)) | I33: =IF(SUM('Distribution 2026-27:Jurisdictional 2026-27'!I33)=0,"",SUM('Distribution 2026-27:Jurisdictional 2026-27'!I33)) | J33: =IF(SUM('Distribution 2026-27:Jurisdictional 2026-27'!J33)=0,"",SUM('Distribution 2026-27:Jurisdictional 2026-27'!J33)) | K33: =IF(SUM('Distribution 2026-27:Jurisdictional 2026-27'!K33)=0,"",SUM('Distribution 2026-27:Jurisdictional 2026-27'!K33)) -> 20.773124 | L33: =IF(SUM('Distribution 2026-27:Jurisdictional 2026-27'!L33)=0,"",SUM('Distribution 2026-27:Jurisdictional 2026-27'!L33)) | M33: =IF(SUM('Distribution 2026-27:Jurisdictional 2026-27'!M33)=0,"",SUM('Distribution 2026-27:Jurisdictional 2026-27'!M33)) | N33: =IF(SUM('Distribution 2026-27:Jurisdictional 2026-27'!N33)=0,"",SUM('Distribution 2026-27:Jurisdictional 2026-27'!N33)) | ... X33: =IF(SUM('Distribution 2026-27:Jurisdictional 2026-27'!X33)=0,"",SUM('Distribution 2026-27:Jurisdictional 2026-27'!X33))
C34: NASN12 | D34: 15 | E34: Small business single rate demand | F34: No | G34: =IF(SUM('Distribution 2026-27:Jurisdictional 2026-27'!G34)=0,"",SUM('Distribution 2026-27:Jurisdictional 2026-27'!G34)) -> 148.93785 | H34: =IF(SUM('Distribution 2026-27:Jurisdictional 2026-27'!H34)=0,"",SUM('Distribution 2026-27:Jurisdictional 2026-27'!H34)) -> 16.795889 | I34: =IF(SUM('Distribution 2026-27:Jurisdictional 2026-27'!I34)=0,"",SUM('Distribution 2026-27:Jurisdictional 2026-27'!I34)) | J34: =IF(SUM('Distribution 2026-27:Jurisdictional 2026-27'!J34)=0,"",SUM('Distribution 2026-27:Jurisdictional 2026-27'!J34)) | K34: =IF(SUM('Distribution 2026-27:Jurisdictional 2026-27'!K34)=0,"",SUM('Distribution 2026-27:Jurisdictional 2026-27'!K34)) | L34: =IF(SUM('Distribution 2026-27:Jurisdictional 2026-27'!L34)=0,"",SUM('Distribution 2026-27:Jurisdictional 2026-27'!L34)) | M34: =IF(SUM('Distribution 2026-27:Jurisdictional 2026-27'!M34)=0,"",SUM('Distribution 2026-27:Jurisdictional 2026-27'!M34)) | N34: =IF(SUM('Distribution 2026-27:Jurisdictional 2026-27'!N34)=0,"",SUM('Distribution 2026-27:Jurisdictional 2026-27'!N34)) | ... X34: =IF(SUM('Distribution 2026-27:Jurisdictional 2026-27'!X34)=0,"",SUM('Distribution 2026-27:Jurisdictional 2026-27'!X34)) -> 2.8621947
C35: NASN12S | D35: 15 | E35: Small business single rate demand standard feed in | F35: No | G35: =IF(SUM('Distribution 2026-27:Jurisdictional 2026-27'!G35)=0,"",SUM('Distribution 2026-27:Jurisdictional 2026-27'!G35)) -> 148.93785 | H35: =IF(SUM('Distribution 2026-27:Jurisdictional 2026-27'!H35)=0,"",SUM('Distribution 2026-27:Jurisdictional 2026-27'!H35)) -> 16.795889 | I35: =IF(SUM('Distribution 2026-27:Jurisdictional 2026-27'!I35)=0,"",SUM('Distribution 2026-27:Jurisdictional 2026-27'!I35)) | J35: =IF(SUM('Distribution 2026-27:Jurisdictional 2026-27'!J35)=0,"",SUM('Distribution 2026-27:Jurisdictional 2026-27'!J35)) | K35: =IF(SUM('Distribution 2026-27:Jurisdictional 2026-27'!K35)=0,"",SUM('Distribution 2026-27:Jurisdictional 2026-27'!K35)) | L35: =IF(SUM('Distribution 2026-27:Jurisdictional 2026-27'!L35)=0,"",SUM('Distribution 2026-27:Jurisdictional 2026-27'!L35)) | M35: =IF(SUM('Distribution 2026-27:Jurisdictional 2026-27'!M35)=0,"",SUM('Distribution 2026-27:Jurisdictional 2026-27'!M35)) | N35: =IF(SUM('Distribution 2026-27:Jurisdictional 2026-27'!N35)=0,"",SUM('Distribution 2026-27:Jurisdictional 2026-27'!N35)) | ... X35: =IF(SUM('Distribution 2026-27:Jurisdictional 2026-27'!X35)=0,"",SUM('Distribution 2026-27:Jurisdictional 2026-27'!X35)) -> 2.8621947
C36: NASN19 | D36: 15 | E36: Business > 40 MWh single rate demand | F36: No | G36: =IF(SUM('Distribution 2026-27:Jurisdictional 2026-27'!G36)=0,"",SUM('Distribution 2026-27:Jurisdictional 2026-27'!G36)) -> 156.20311 | H36: =IF(SUM('Distribution 2026-27:Jurisdictional 2026-27'!H36)=0,"",SUM('Distribution 2026-27:Jurisdictional 2026-27'!H36)) -> 19.406068 | I36: =IF(SUM('Distribution 2026-27:Jurisdictional 2026-27'!I36)=0,"",SUM('Distribution 2026-27:Jurisdictional 2026-27'!I36)) | J36: =IF(SUM('Distribution 2026-27:Jurisdictional 2026-27'!J36)=0,"",SUM('Distribution 2026-27:Jurisdictional 2026-27'!J36)) | K36: =IF(SUM('Distribution 2026-27:Jurisdictional 2026-27'!K36)=0,"",SUM('Distribution 2026-27:Jurisdictional 2026-27'!K36)) | L36: =IF(SUM('Distribution 2026-27:Jurisdictional 2026-27'!L36)=0,"",SUM('Distribution 2026-27:Jurisdictional 2026-27'!L36)) | M36: =IF(SUM('Distribution 2026-27:Jurisdictional 2026-27'!M36)=0,"",SUM('Distribution 2026-27:Jurisdictional 2026-27'!M36)) | N36: =IF(SUM('Distribution 2026-27:Jurisdictional 2026-27'!N36)=0,"",SUM('Distribution 2026-27:Jurisdictional 2026-27'!N36)) | ... X36: =IF(SUM('Distribution 2026-27:Jurisdictional 2026-27'!X36)=0,"",SUM('Distribution 2026-27:Jurisdictional 2026-27'!X36)) -> 2.2935651
C37: NASN21 | D37: 2 | E37: Business > 40 MWh two rate demand | F37: No | G37: =IF(SUM('Distribution 2026-27:Jurisdictional 2026-27'!G37)=0,"",SUM('Distribution 2026-27:Jurisdictional 2026-27'!G37)) -> 156.20311 | H37: =IF(SUM('Distribution 2026-27:Jurisdictional 2026-27'!H37)=0,"",SUM('Distribution 2026-27:Jurisdictional 2026-27'!H37)) | I37: =IF(SUM('Distribution 2026-27:Jurisdictional 2026-27'!I37)=0,"",SUM('Distribution 2026-27:Jurisdictional 2026-27'!I37)) | J37: =IF(SUM('Distribution 2026-27:Jurisdictional 2026-27'!J37)=0,"",SUM('Distribution 2026-27:Jurisdictional 2026-27'!J37)) | K37: =IF(SUM('Distribution 2026-27:Jurisdictional 2026-27'!K37)=0,"",SUM('Distribution 2026-27:Jurisdictional 2026-27'!K37)) -> 19.380404 | L37: =IF(SUM('Distribution 2026-27:Jurisdictional 2026-27'!L37)=0,"",SUM('Distribution 2026-27:Jurisdictional 2026-27'!L37)) | M37: =IF(SUM('Distribution 2026-27:Jurisdictional 2026-27'!M37)=0,"",SUM('Distribution 2026-27:Jurisdictional 2026-27'!M37)) | N37: =IF(SUM('Distribution 2026-27:Jurisdictional 2026-27'!N37)=0,"",SUM('Distribution 2026-27:Jurisdictional 2026-27'!N37)) | ... X37: =IF(SUM('Distribution 2026-27:Jurisdictional 2026-27'!X37)=0,"",SUM('Distribution 2026-27:Jurisdictional 2026-27'!X37)) -> 2.2935651
C38: NASN2S | D38: 2 | E38: Business > 40 MWh two rate demand standard feed in | F38: No | G38: =IF(SUM('Distribution 2026-27:Jurisdictional 2026-27'!G38)=0,"",SUM('Distribution 2026-27:Jurisdictional 2026-27'!G38)) -> 156.20311 | H38: =IF(SUM('Distribution 2026-27:Jurisdictional 2026-27'!H38)=0,"",SUM('Distribution 2026-27:Jurisdictional 2026-27'!H38)) | I38: =IF(SUM('Distribution 2026-27:Jurisdictional 2026-27'!I38)=0,"",SUM('Distribution 2026-27:Jurisdictional 2026-27'!I38)) | J38: =IF(SUM('Distribution 2026-27:Jurisdictional 2026-27'!J38)=0,"",SUM('Distribution 2026-27:Jurisdictional 2026-27'!J38)) | K38: =IF(SUM('Distribution 2026-27:Jurisdictional 2026-27'!K38)=0,"",SUM('Distribution 2026-27:Jurisdictional 2026-27'!K38)) -> 19.380404 | L38: =IF(SUM('Distribution 2026-27:Jurisdictional 2026-27'!L38)=0,"",SUM('Distribution 2026-27:Jurisdictional 2026-27'!L38)) | M38: =IF(SUM('Distribution 2026-27:Jurisdictional 2026-27'!M38)=0,"",SUM('Distribution 2026-27:Jurisdictional 2026-27'!M38)) | N38: =IF(SUM('Distribution 2026-27:Jurisdictional 2026-27'!N38)=0,"",SUM('Distribution 2026-27:Jurisdictional 2026-27'!N38)) | ... X38: =IF(SUM('Distribution 2026-27:Jurisdictional 2026-27'!X38)=0,"",SUM('Distribution 2026-27:Jurisdictional 2026-27'!X38)) -> 2.2935651
C39: NSP21 | D39: 7 | E39: Small interval meter time of use | F39: Yes | G39: =IF(SUM('Distribution 2026-27:Jurisdictional 2026-27'!G39)=0,"",SUM('Distribution 2026-27:Jurisdictional 2026-27'!G39)) -> 148.93785 | H39: =IF(SUM('Distribution 2026-27:Jurisdictional 2026-27'!H39)=0,"",SUM('Distribution 2026-27:Jurisdictional 2026-27'!H39)) | I39: =IF(SUM('Distribution 2026-27:Jurisdictional 2026-27'!I39)=0,"",SUM('Distribution 2026-27:Jurisdictional 2026-27'!I39)) | J39: =IF(SUM('Distribution 2026-27:Jurisdictional 2026-27'!J39)=0,"",SUM('Distribution 2026-27:Jurisdictional 2026-27'!J39)) | K39: =IF(SUM('Distribution 2026-27:Jurisdictional 2026-27'!K39)=0,"",SUM('Distribution 2026-27:Jurisdictional 2026-27'!K39)) | L39: =IF(SUM('Distribution 2026-27:Jurisdictional 2026-27'!L39)=0,"",SUM('Distribution 2026-27:Jurisdictional 2026-27'!L39)) | M39: =IF(SUM('Distribution 2026-27:Jurisdictional 2026-27'!M39)=0,"",SUM('Distribution 2026-27:Jurisdictional 2026-27'!M39)) -> 50.36794 | N39: =IF(SUM('Distribution 2026-27:Jurisdictional 2026-27'!N39)=0,"",SUM('Distribution 2026-27:Jurisdictional 2026-27'!N39)) -> 44.504023 | ... X39: =IF(SUM('Distribution 2026-27:Jurisdictional 2026-27'!X39)=0,"",SUM('Distribution 2026-27:Jurisdictional 2026-27'!X39))
C40: NSP27 | D40: 7 | E40: Small interval meter low peak time of use | F40: Yes | G40: =IF(SUM('Distribution 2026-27:Jurisdictional 2026-27'!G40)=0,"",SUM('Distribution 2026-27:Jurisdictional 2026-27'!G40)) -> 148.93785 | H40: =IF(SUM('Distribution 2026-27:Jurisdictional 2026-27'!H40)=0,"",SUM('Distribution 2026-27:Jurisdictional 2026-27'!H40)) | I40: =IF(SUM('Distribution 2026-27:Jurisdictional 2026-27'!I40)=0,"",SUM('Distribution 2026-27:Jurisdictional 2026-27'!I40)) | J40: =IF(SUM('Distribution 2026-27:Jurisdictional 2026-27'!J40)=0,"",SUM('Distribution 2026-27:Jurisdictional 2026-27'!J40)) | K40: =IF(SUM('Distribution 2026-27:Jurisdictional 2026-27'!K40)=0,"",SUM('Distribution 2026-27:Jurisdictional 2026-27'!K40)) | L40: =IF(SUM('Distribution 2026-27:Jurisdictional 2026-27'!L40)=0,"",SUM('Distribution 2026-27:Jurisdictional 2026-27'!L40)) | M40: =IF(SUM('Distribution 2026-27:Jurisdictional 2026-27'!M40)=0,"",SUM('Distribution 2026-27:Jurisdictional 2026-27'!M40)) -> 29.808896 | N40: =IF(SUM('Distribution 2026-27:Jurisdictional 2026-27'!N40)=0,"",SUM('Distribution 2026-27:Jurisdictional 2026-27'!N40)) -> 26.55536 | ... X40: =IF(SUM('Distribution 2026-27:Jurisdictional 2026-27'!X40)=0,"",SUM('Distribution 2026-27:Jurisdictional 2026-27'!X40))
C41: SSP27 | D41: 7 | E41: Small interval meter time of use solar installation standard feed in | F41: Yes | G41: =IF(SUM('Distribution 2026-27:Jurisdictional 2026-27'!G41)=0,"",SUM('Distribution 2026-27:Jurisdictional 2026-27'!G41)) -> 148.93785 | H41: =IF(SUM('Distribution 2026-27:Jurisdictional 2026-27'!H41)=0,"",SUM('Distribution 2026-27:Jurisdictional 2026-27'!H41)) | I41: =IF(SUM('Distribution 2026-27:Jurisdictional 2026-27'!I41)=0,"",SUM('Distribution 2026-27:Jurisdictional 2026-27'!I41)) | J41: =IF(SUM('Distribution 2026-27:Jurisdictional 2026-27'!J41)=0,"",SUM('Distribution 2026-27:Jurisdictional 2026-27'!J41)) | K41: =IF(SUM('Distribution 2026-27:Jurisdictional 2026-27'!K41)=0,"",SUM('Distribution 2026-27:Jurisdictional 2026-27'!K41)) | L41: =IF(SUM('Distribution 2026-27:Jurisdictional 2026-27'!L41)=0,"",SUM('Distribution 2026-27:Jurisdictional 2026-27'!L41)) | M41: =IF(SUM('Distribution 2026-27:Jurisdictional 2026-27'!M41)=0,"",SUM('Distribution 2026-27:Jurisdictional 2026-27'!M41)) -> 29.808896 | N41: =IF(SUM('Distribution 2026-27:Jurisdictional 2026-27'!N41)=0,"",SUM('Distribution 2026-27:Jurisdictional 2026-27'!N41)) -> 26.55536 | ... X41: =IF(SUM('Distribution 2026-27:Jurisdictional 2026-27'!X41)=0,"",SUM('Distribution 2026-27:Jurisdictional 2026-27'!X41))
B45: Tariff class | C45: Tariff code | D45: Tariff Structure | E45: Description | F45: Closed to New Entrants | G45: Standing charge | H45: Anytime | I45: Block 1 | J45: Block 2 | K45: Peak | L45: Shoulder all year | M45: Summer peak | N45: Summer shoulder | O45: Winter peak | P45: Off Peak | Q45: Dedicated circuit | R45: Solar soak | S45: Export charge | T45: Export reward | U45: Capacity | V45: Critical peak demand | W45: Monthly peak kW demand | X45: Monthly off peak kW demand
G46: $/year | H46: c/kWh | I46: c/kWh | J46: c/kWh | K46: c/kWh | L46: c/kWh | M46: c/kWh | N46: c/kWh | O46: c/kWh | P46: c/kWh | Q46: c/kWh | R46: c/kWh | S46: c/kWh | T46: c/kWh | U46: $/kVA/yr | V46: $/kVA/yr | W46: $/kW/mth | X46: $/kW/mth
B47: Medium industrial & commercial | C47: NEE52 | D47: 3 | E47: Medium unmetered | F47: No | G47: =IF(SUM('Distribution 2026-27:Jurisdictional 2026-27'!G47)=0,"",SUM('Distribution 2026-27:Jurisdictional 2026-27'!G47)) | H47: =IF(SUM('Distribution 2026-27:Jurisdictional 2026-27'!H47)=0,"",SUM('Distribution 2026-27:Jurisdictional 2026-27'!H47)) | I47: =IF(SUM('Distribution 2026-27:Jurisdictional 2026-27'!I47)=0,"",SUM('Distribution 2026-27:Jurisdictional 2026-27'!I47)) | J47: =IF(SUM('Distribution 2026-27:Jurisdictional 2026-27'!J47)=0,"",SUM('Distribution 2026-27:Jurisdictional 2026-27'!J47)) | K47: =IF(SUM('Distribution 2026-27:Jurisdictional 2026-27'!K47)=0,"",SUM('Distribution 2026-27:Jurisdictional 2026-27'!K47)) -> 24.833368 | L47: =IF(SUM('Distribution 2026-27:Jurisdictional 2026-27'!L47)=0,"",SUM('Distribution 2026-27:Jurisdictional 2026-27'!L47)) | M47: =IF(SUM('Distribution 2026-27:Jurisdictional 2026-27'!M47)=0,"",SUM('Distribution 2026-27:Jurisdictional 2026-27'!M47)) | N47: =IF(SUM('Distribution 2026-27:Jurisdictional 2026-27'!N47)=0,"",SUM('Distribution 2026-27:Jurisdictional 2026-27'!N47)) | ... X47: =IF(SUM('Distribution 2026-27:Jurisdictional 2026-27'!X47)=0,"",SUM('Distribution 2026-27:Jurisdictional 2026-27'!X47))
...

Sheet Distribution 2026-27
B2: Distribution tariff schedule
B3: Date of Application - 1 July 2026 | G3: Fixed | H3: Anytime | I3: Block 1 | J3: Block 2 | K3: Peak | L3: Shoulder | M3: Summer peak | N3: Summer shoulder | O3: Winter peak | P3: Off-peak | Q3: Dedicated | R3: Solar soak | S3: Export charge | T3: Export reward | U3: Capacity | V3: Critical peak | W3: Monthly peak | X3: Monthly off-peak
B5: Tariff class | C5: Tariff code | D5: Tariff Structure | E5: Description | F5: Closed to New Entrants | G5: Standing charge | H5: Anytime | I5: Block 1 | J5: Block 2 | K5: Peak | L5: Shoulder all year | M5: Summer peak | N5: Summer shoulder | O5: Winter peak | P5: Off Peak | Q5: Dedicated circuit | R5: Solar soak | S5: Export charge^ | T5: Export reward | U5: Capacity | V5: Critical peak demand | W5: Monthly peak kW demand | X5: Monthly off peak kW demand
G6: $/year | H6: c/kWh | I6: c/kWh | J6: c/kWh | K6: c/kWh | L6: c/kWh | M6: c/kWh | N6: c/kWh | O6: c/kWh | P6: c/kWh | Q6: c/kWh | R6: c/kWh | S6: c/kWh | T6: c/kWh | U6: $/kVA/yr | V6: $/kVA/yr | W6: $/kW/mth | X6: $/kW/mth
B7: Residential | C7: NEE11 | D7: 1 | E7: Small single rate | F7: No | G7: 145.30522 | I7: 9.987278 | J7: 9.987278
C8: NEE11S | D8: 1 | E8: Small single rate standard feed in | F8: No | G8: 145.30522 | I8: 9.987278 | J8: 9.987278
C9: NEE19 | D9: 1 & 19 | E9: Small single rate & dedicated circuit 24 hour | F9: No | G9: 145.30522 | I9: 9.987278 | J9: 9.987278 | Q9: 3.845656
C10: NASS11 | D10: 21 | E10: Small residential time of use | F10: No | G10: 145.30522 | K10: 23.513247 | P10: 4.2751359 | R10: 1 | AB10: NAST11
C11: NASS11S | D11: 21 | E11: Small residential time of use standard feed in | F11: No | G11: 145.30522 | K11: 23.513247 | P11: 4.2751359 | R11: 1 | AB11: NAST11S
C12: NAST17 | D12: 19 & 21 | E12: Small residential time of use & dedicated circuit 24 hour | F12: No | G12: 145.30522 | K12: 23.513247 | P12: 4.2751359 | Q12: 3.845656 | R12: 1
C13: NEE24 | D13: 4 | E13: Small two rate 8:00 to 8:00* | F13: Yes | G13: 145.30522 | K13: 8.6110701 | P13: 3.626499
C14: NSP20 | D14: 7 | E14: Small interval meter time of use | F14: Yes | G14: 145.30522 | M14: 44.360601 | N14: 38.817208 | O14: 33.972483 | P14: 3.7835514
C15: NSP23 | D15: 7 | E15: Small interval meter time of use solar installation standard feed in | F15: Yes | G15: 145.30522 | M15: 44.360601 | N15: 38.817208 | O15: 33.972483 | P15: 3.7835514
C16: NEE30 | D16: 9 | E16: Small dedicated circuit | F16: Yes | Q16: 3.845656
C17: NEE31 | D17: 10 | E17: Small dedicated circuit with afternoon boost | F17: Yes | Q17: 3.845656
C18: NEE32 | D18: 11 | E18: Small dedicated circuit 8:00 to 8:00 | F18: Yes | Q18: 3.845656
C19: NEE33 | D19: 19 | E19: Small dedicated circuit 24 hour | F19: Yes | Q19: 3.845656
C20: RCER11 | D20: 20 | E20: Residential CER | F20: No | G20: 145.30522 | K20: 23.513247 | P20: 4.2751359 | R20: 1 | S20: 1 | T20: -10
B22: * Available to customers in rural areas with heating requirement
B23: * Includes a BEL of 1 kWh per day
B25: Tariff class | C25: Tariff code | D25: Tariff Structure | E25: Description | F25: Closed to New Entrants | G25: Standing charge | H25: Anytime | I25: Block 1 | J25: Block 2 | K25: Peak | L25: Shoulder all year | M25: Summer peak | N25: Summer shoulder | O25: Winter peak | P25: Off Peak | Q25: Dedicated circuit | R25: Solar soak | S25: Export charge | T25: Export reward | U25: Capacity | V25: Critical peak demand | W25: Monthly peak kW demand | X25: Monthly off peak kW demand
G26: $/year | H26: c/kWh | I26: c/kWh | J26: c/kWh | K26: c/kWh | L26: c/kWh | M26: c/kWh | N26: c/kWh | O26: c/kWh | P26: c/kWh | Q26: c/kWh | R26: c/kWh | S26: c/kWh | T26: c/kWh | U26: $/kVA/yr | V26: $/kVA/yr | W26: $/kW/mth | X26: $/kW/mth
B27: Small industrial & commercial | C27: NEE12 | D27: 1 | E27: Small single rate | F27: No | G27: 148.93785 | I27: 14.16491 | J27: 14.16491
C28: NEE12S | D28: 1 | E28: Small single rate standard feed in | F28: No | G28: 148.93785 | I28: 14.16491 | J28: 14.16491
C29: NEE16 | D29: 1 & 9 | E29: Small single rate & dedicated circuit | F29: Yes | G29: 148.93785 | I29: 14.16491 | J29: 14.16491 | Q29: 3.8344139
C30: NEE17 | D30: 1 & 10 | E30: Small single rate & dedicated circuit with afternoon boost | F30: Yes | G30: 148.93785 | I30: 14.16491 | J30: 14.16491 | Q30: 3.8344139
C31: NEE18 | D31: 1 & 11 | E31: Small single rate & dedicated circuit 8:00 to 8:00 | F31: Yes | G31: 148.93785 | I31: 14.16491 | J31: 14.16491 | Q31: 3.8344139
C32: NAST12 | D32: 17 | E32: Small business time of use | F32: No | G32: 148.93785 | K32: 17.33075 | P32: 3.8243222
C33: NAST12S | D33: 17 | E33: Small business time of use standard feed in | F33: No | G33: 148.93785 | K33: 17.33075 | P33: 3.8243222
C34: NASN12 | D34: 15 | E34: Small business single rate demand | F34: No | G34: 148.93785 | H34: 13.353515 | W34: 11.472532 | X34: 2.8621947
C35: NASN12S | D35: 15 | E35: Small business single rate demand standard feed in | F35: No | G35: 148.93785 | H35: 13.353515 | W35: 11.472532 | X35: 2.8621947
C36: NASN19 | D36: 15 | E36: Business > 40 MWh single rate demand | F36: No | G36: 156.20311 | H36: 15.963694 | W36: 9.193294 | X36: 2.2935651
C37: NASN21 | D37: 2 | E37: Business > 40 MWh two rate demand | F37: No | G37: 156.20311 | K37: 15.93803 | P37: 3.6692965 | W37: 9.193294 | X37: 2.2935651
C38: NASN2S | D38: 2 | E38: Business > 40 MWh two rate demand standard feed in | F38: No | G38: 156.20311 | K38: 15.93803 | P38: 3.6692965 | W38: 9.193294 | X38: 2.2935651
C39: NSP21 | D39: 7 | E39: Small interval meter time of use | F39: Yes | G39: 148.93785 | M39: 46.925566 | N39: 41.06165 | O39: 35.936799 | P39: 4.0023194
C40: NSP27 | D40: 7 | E40: Small interval meter low peak time of use | F40: Yes | G40: 148.93785 | M40: 26.366522 | N40: 23.112986 | O40: 20.27121 | P40: 7.2383557
C41: SSP27 | D41: 7 | E41: Small interval meter time of use solar installation standard feed in | F41: Yes | G41: 148.93785 | M41: 26.366522 | N41: 23.112986 | O41: 20.27121 | P41: 7.2383557
B45: Tariff class | C45: Tariff code | D45: Tariff Structure | E45: Description | F45: Closed to New Entrants | G45: Standing charge | H45: Anytime | I45: Block 1 | J45: Block 2 | K45: Peak | L45: Shoulder all year | M45: Summer peak | N45: Summer shoulder | O45: Winter peak | P45: Off Peak | Q45: Dedicated circuit | R45: Solar soak | S45: Export charge | T45: Export reward | U45: Capacity | V45: Critical peak demand | W45: Monthly peak kW demand | X45: Monthly off peak kW demand
G46: $/year | H46: c/kWh | I46: c/kWh | J46: c/kWh | K46: c/kWh | L46: c/kWh | M46: c/kWh | N46: c/kWh | O46: c/kWh | P46: c/kWh | Q46: c/kWh | R46: c/kWh | S46: c/kWh | T46: c/kWh | U46: $/kVA/yr | V46: $/kVA/yr | W46: $/kW/mth | X46: $/kW/mth
B47: Medium industrial & commercial | C47: NEE52 | D47: 3 | E47: Medium unmetered | F47: No | K47: 21.390994 | P47: 10.84489
...

Sheet Transmission 2026-27
B2: Transmission tariff schedule
B3: Date of Application - 1 July 2026 | G3: Fixed | H3: Anytime | I3: Block 1 | J3: Block 2 | K3: Peak | L3: Shoulder | M3: Summer peak | N3: Summer shoulder | O3: Winter peak | P3: Off-peak | Q3: Dedicated | R3: Solar soak | S3: Export charge | T3: Export reward | U3: Capacity | V3: Critical peak | W3: Monthly peak | X3: Monthly off-peak
B5: Tariff class | C5: Tariff code | D5: Tariff Structure | E5: Description | F5: Closed to New Entrants | G5: Standing charge | H5: Anytime | I5: Block 1 | J5: Block 2 | K5: Peak | L5: Shoulder all year | M5: Summer peak | N5: Summer shoulder | O5: Winter peak | P5: Off Peak | Q5: Dedicated circuit | R5: Solar soak | S5: Export charge^ | T5: Export reward | U5: Capacity | V5: Critical peak demand | W5: Monthly peak kW demand | X5: Monthly off peak kW demand
G6: $/year | H6: c/kWh | I6: c/kWh | J6: c/kWh | K6: c/kWh | L6: c/kWh | M6: c/kWh | N6: c/kWh | O6: c/kWh | P6: c/kWh | Q6: c/kWh | R6: c/kWh | S6: c/kWh | T6: c/kWh | U6: $/kVA/yr | V6: $/kVA/yr | W6: $/kW/mth | X6: $/kW/mth
B7: Residential | C7: NEE11 | D7: 1 | E7: Small single rate | F7: No | I7: 3.2733435 | J7: 3.2733435
C8: NEE11S | D8: 1 | E8: Small single rate standard feed in | F8: No | I8: 3.2733435 | J8: 3.2733435
C9: NEE19 | D9: 1 & 19 | E9: Small single rate & dedicated circuit 24 hour | F9: No | I9: 3.2733435 | J9: 3.2733435 | Q9: 0.91290615
C10: NASS11 | D10: 21 | E10: Small residential time of use | F10: No | K10: 3.2733435 | P10: 0.91290615 | AB10: NAST11
C11: NASS11S | D11: 21 | E11: Small residential time of use standard feed in | F11: No | K11: 3.2733435 | P11: 0.91290615 | AB11: NAST11S
C12: NAST17 | D12: 19 & 21 | E12: Small residential time of use & dedicated circuit 24 hour | F12: No | K12: 3.2733435 | P12: 0.91290615 | Q12: 0.91290615
C13: NEE24 | D13: 4 | E13: Small two rate 8:00 to 8:00* | F13: Yes | K13: 3.2733435 | P13: 0.91290615
C14: NSP20 | D14: 7 | E14: Small interval meter time of use | F14: Yes | M14: 3.2733435 | N14: 3.2733435 | O14: 3.2733435 | P14: 0.91290615
C15: NSP23 | D15: 7 | E15: Small interval meter time of use solar installation standard feed in | F15: Yes | M15: 3.2733435 | N15: 3.2733435 | O15: 3.2733435 | P15: 0.91290615
C16: NEE30 | D16: 9 | E16: Small dedicated circuit | F16: Yes | Q16: 0.91290615
C17: NEE31 | D17: 10 | E17: Small dedicated circuit with afternoon boost | F17: Yes | Q17: 0.91290615
C18: NEE32 | D18: 11 | E18: Small dedicated circuit 8:00 to 8:00 | F18: Yes | Q18: 0.91290615
C19: NEE33 | D19: 19 | E19: Small dedicated circuit 24 hour | F19: Yes | Q19: 0.91290615
C20: RCER11 | D20: 20 | E20: Residential CER | F20: No | K20: 3.2733435 | P20: 0.91290615
B22: * Available to customers in rural areas with heating requirement
B23: * Includes a BEL of 1 kWh per day
B25: Tariff class | C25: Tariff code | D25: Tariff Structure | E25: Description | F25: Closed to New Entrants | G25: Standing charge | H25: Anytime | I25: Block 1 | J25: Block 2 | K25: Peak | L25: Shoulder all year | M25: Summer peak | N25: Summer shoulder | O25: Winter peak | P25: Off Peak | Q25: Dedicated circuit | R25: Solar soak | S25: Export charge | T25: Export reward | U25: Capacity | V25: Critical peak demand | W25: Monthly peak kW demand | X25: Monthly off peak kW demand
G26: $/year | H26: c/kWh | I26: c/kWh | J26: c/kWh | K26: c/kWh | L26: c/kWh | M26: c/kWh | N26: c/kWh | O26: c/kWh | P26: c/kWh | Q26: c/kWh | R26: c/kWh | S26: c/kWh | T26: c/kWh | U26: $/kVA/yr | V26: $/kVA/yr | W26: $/kW/mth | X26: $/kW/mth
B27: Small industrial & commercial | C27: NEE12 | D27: 1 | E27: Small single rate | F27: No | I27: 3.2733435 | J27: 3.2733435
C28: NEE12S | D28: 1 | E28: Small single rate standard feed in | F28: No | I28: 3.2733435 | J28: 3.2733435
C29: NEE16 | D29: 1 & 9 | E29: Small single rate & dedicated circuit | F29: Yes | I29: 3.2733435 | J29: 3.2733435 | Q29: 0.91290615
C30: NEE17 | D30: 1 & 10 | E30: Small single rate & dedicated circuit with afternoon boost | F30: Yes | I30: 3.2733435 | J30: 3.2733435 | Q30: 0.91290615
C31: NEE18 | D31: 1 & 11 | E31: Small single rate & dedicated circuit 8:00 to 8:00 | F31: Yes | I31: 3.2733435 | J31: 3.2733435 | Q31: 0.91290615
C32: NAST12 | D32: 17 | E32: Small business time of use | F32: No | K32: 3.2733435 | P32: 0.91290615
C33: NAST12S | D33: 17 | E33: Small business time of use standard feed in | F33: No | K33: 3.2733435 | P33: 0.91290615
C34: NASN12 | D34: 15 | E34: Small business single rate demand | F34: No | H34: 3.2733435
C35: NASN12S | D35: 15 | E35: Small business single rate demand standard feed in | F35: No | H35: 3.2733435
C36: NASN19 | D36: 15 | E36: Business > 40 MWh single rate demand | F36: No | H36: 3.2733435
C37: NASN21 | D37: 2 | E37: Business > 40 MWh two rate demand | F37: No | K37: 3.2733435 | P37: 0.91290615
C38: NASN2S | D38: 2 | E38: Business > 40 MWh two rate demand standard feed in | F38: No | K38: 3.2733435 | P38: 0.91290615
C39: NSP21 | D39: 7 | E39: Small interval meter time of use | F39: Yes | M39: 3.2733435 | N39: 3.2733435 | O39: 3.2733435 | P39: 0.91290615
C40: NSP27 | D40: 7 | E40: Small interval meter low peak time of use | F40: Yes | M40: 3.2733435 | N40: 3.2733435 | O40: 3.2733435 | P40: 0.91290615
C41: SSP27 | D41: 7 | E41: Small interval meter time of use solar installation standard feed in | F41: Yes | M41: 3.2733435 | N41: 3.2733435 | O41: 3.2733435 | P41: 0.91290615
B45: Tariff class | C45: Tariff code | D45: Tariff Structure | E45: Description | F45: Closed to New Entrants | G45: Standing charge | H45: Anytime | I45: Block 1 | J45: Block 2 | K45: Peak | L45: Shoulder all year | M45: Summer peak | N45: Summer shoulder | O45: Winter peak | P45: Off Peak | Q45: Dedicated circuit | R45: Solar soak | S45: Export charge | T45: Export reward | U45: Capacity | V45: Critical peak demand | W45: Monthly peak kW demand | X45: Monthly off peak kW demand
G46: $/year | H46: c/kWh | I46: c/kWh | J46: c/kWh | K46: c/kWh | L46: c/kWh | M46: c/kWh | N46: c/kWh | O46: c/kWh | P46: c/kWh | Q46: c/kWh | R46: c/kWh | S46: c/kWh | T46: c/kWh | U46: $/kVA/yr | V46: $/kVA/yr | W46: $/kW/mth | X46: $/kW/mth
B47: Medium industrial & commercial | C47: NEE52 | D47: 3 | E47: Medium unmetered | F47: No | K47: 3.2733435 | P47: 0.91290615
...

Sheet Jurisdictional 2026-27
B2: Jurisdictional scheme tariff schedule
B3: Date of Application - 1 July 2026 | G3: Fixed | H3: Anytime | I3: Block 1 | J3: Block 2 | K3: Peak | L3: Shoulder | M3: Summer peak | N3: Summer shoulder | O3: Winter peak | P3: Off-peak | Q3: Dedicated | R3: Solar soak | S3: Export charge | T3: Export reward | U3: Capacity | V3: Critical peak | W3: Monthly peak | X3: Monthly off-peak
B5: Tariff class | C5: Tariff code | D5: Tariff Structure | E5: Description | F5: Closed to New Entrants | G5: Standing charge | H5: Anytime | I5: Block 1 | J5: Block 2 | K5: Peak | L5: Shoulder all year | M5: Summer peak | N5: Summer shoulder | O5: Winter peak | P5: Off Peak | Q5: Dedicated circuit | R5: Solar soak | S5: Export charge^ | T5: Export reward | U5: Capacity | V5: Critical peak demand | W5: Monthly peak kW demand | X5: Monthly off peak kW demand
G6: $/year | H6: c/kWh | I6: c/kWh | J6: c/kWh | K6: c/kWh | L6: c/kWh | M6: c/kWh | N6: c/kWh | O6: c/kWh | P6: c/kWh | Q6: c/kWh | R6: c/kWh | S6: c/kWh | T6: c/kWh | U6: $/kVA/yr | V6: $/kVA/yr | W6: $/kW/mth | X6: $/kW/mth
B7: Residential | C7: NEE11 | D7: 1 | E7: Small single rate | F7: No | I7: 0.16903018 | J7: 0.16903018
C8: NEE11S | D8: 1 | E8: Small single rate standard feed in | F8: No | I8: 0.16903018 | J8: 0.16903018
C9: NEE19 | D9: 1 & 19 | E9: Small single rate & dedicated circuit 24 hour | F9: No | I9: 0.16903018 | J9: 0.16903018 | Q9: 0.14190188
C10: NASS11 | D10: 21 | E10: Small residential time of use | F10: No | K10: 0.16903018 | P10: 0.14190188 | AB10: NAST11
C11: NASS11S | D11: 21 | E11: Small residential time of use standard feed in | F11: No | K11: 0.16903018 | P11: 0.14190188 | AB11: NAST11S
C12: NAST17 | D12: 19 & 21 | E12: Small residential time of use & dedicated circuit 24 hour | F12: No | K12: 0.16903018 | P12: 0.14190188 | Q12: 0.14190188
C13: NEE24 | D13: 4 | E13: Small two rate 8:00 to 8:00* | F13: Yes | K13: 0.16903018 | P13: 0.14190188
C14: NSP20 | D14: 7 | E14: Small interval meter time of use | F14: Yes | M14: 0.16903018 | N14: 0.16903018 | O14: 0.16903018 | P14: 0.14190188
C15: NSP23 | D15: 7 | E15: Small interval meter time of use solar installation standard feed in | F15: Yes | M15: 0.16903018 | N15: 0.16903018 | O15: 0.16903018 | P15: 0.14190188
C16: NEE30 | D16: 9 | E16: Small dedicated circuit | F16: Yes | Q16: 0.14190188
C17: NEE31 | D17: 10 | E17: Small dedicated circuit with afternoon boost | F17: Yes | Q17: 0.14190188
C18: NEE32 | D18: 11 | E18: Small dedicated circuit 8:00 to 8:00 | F18: Yes | Q18: 0.14190188
C19: NEE33 | D19: 19 | E19: Small dedicated circuit 24 hour | F19: Yes | Q19: 0.14190188
C20: RCER11 | D20: 20 | E20: Residential CER | F20: No | K20: 0.16903018 | P20: 0.14190188
B22: * Available to customers in rural areas with heating requirement
B23: * Includes a BEL of 1 kWh per day
B25: Tariff class | C25: Tariff code | D25: Tariff Structure | E25: Description | F25: Closed to New Entrants | G25: Standing charge | H25: Anytime | I25: Block 1 | J25: Block 2 | K25: Peak | L25: Shoulder all year | M25: Summer peak | N25: Summer shoulder | O25: Winter peak | P25: Off Peak | Q25: Dedicated circuit | R25: Solar soak | S25: Export charge | T25: Export reward | U25: Capacity | V25: Critical peak demand | W25: Monthly peak kW demand | X25: Monthly off peak kW demand
G26: $/year | H26: c/kWh | I26: c/kWh | J26: c/kWh | K26: c/kWh | L26: c/kWh | M26: c/kWh | N26: c/kWh | O26: c/kWh | P26: c/kWh | Q26: c/kWh | R26: c/kWh | S26: c/kWh | T26: c/kWh | U26: $/kVA/yr | V26: $/kVA/yr | W26: $/kW/mth | X26: $/kW/mth
B27: Small industrial & commercial | C27: NEE12 | D27: 1 | E27: Small single rate | F27: No | I27: 0.16903018 | J27: 0.16903018
C28: NEE12S | D28: 1 | E28: Small single rate standard feed in | F28: No | I28: 0.16903018 | J28: 0.16903018
C29: NEE16 | D29: 1 & 9 | E29: Small single rate & dedicated circuit | F29: Yes | I29: 0.16903018 | J29: 0.16903018 | Q29: 0.14190188
C30: NEE17 | D30: 1 & 10 | E30: Small single rate & dedicated circuit with afternoon boost | F30: Yes | I30: 0.16903018 | J30: 0.16903018 | Q30: 0.14190188
C31: NEE18 | D31: 1 & 11 | E31: Small single rate & dedicated circuit 8:00 to 8:00 | F31: Yes | I31: 0.16903018 | J31: 0.16903018 | Q31: 0.14190188
C32: NAST12 | D32: 17 | E32: Small business time of use | F32: No | K32: 0.16903018 | P32: 0.14190188
C33: NAST12S | D33: 17 | E33: Small business time of use standard feed in | F33: No | K33: 0.16903018 | P33: 0.14190188
C34: NASN12 | D34: 15 | E34: Small business single rate demand | F34: No | H34: 0.16903018
C35: NASN12S | D35: 15 | E35: Small business single rate demand standard feed in | F35: No | H35: 0.16903018
C36: NASN19 | D36: 15 | E36: Business > 40 MWh single rate demand | F36: No | H36: 0.16903018
