Workbook
Name Base_Year: Lookup!$E$11
Name Cents_to_Dollars: Lookup!$D$33
Name Days_In_Wk: Lookup!$D$30
Name Days_In_Yr: Lookup!$D$31
Name Dollars: Lookup!$D$47
Name Dollars_to_Thousands: Lookup!$D$34
Name End_year: Lookup!$F$81
Name Error: Lookup!$D$37
Name Factor: Lookup!$D$50
Name Half: Lookup!$D$32
Name Kilometres: Lookup!$D$65
Name LU_Basis: Lookup!$D$70:$D$75
Name LU_Fee_Based_Services: Lookup!$D$102:$D$128
Name LU_Metering_Services: Lookup!$D$95:$D$97
Name LU_Quoted_Services: Lookup!$D$133:$D$148
Name LU_Revenue_Input: Lookup!$D$86:$D$88
Name LU_Service_Categories: Lookup!$D$153:$D$159
Name LU_Timing: Lookup!$D$79:$D$82
Name LU_Timing_Value: Lookup!$E$79:$E$82
Name LU_Units: Lookup!$D$46:$D$66
Name Mid_year: Lookup!$D$80
Name Millions: Lookup!$D$48
Name Model_Name: Cover!$B$3
Name Model_Start_Date: Lookup!$E$10
Name Mths_In_Mth: Lookup!$D$26
Name Mths_In_Qtr: Lookup!$D$27
Name Mths_In_Yr: Lookup!$D$29
Name NA: Lookup!$D$36
Name No: Lookup!$D$42
Name No_Input: Lookup!$D$88
Name Nominal: Lookup!$D$75
Name Number: Lookup!$D$51
Name Ok: Lookup!$D$35
Name Percent: Lookup!$D$46
Name Qtrs_In_Yr: Lookup!$D$28
Name Real2018: Lookup!$D$70
Name Real2019: Lookup!$D$71
Name Real2020: Lookup!$D$72
Name Start_year: Lookup!$D$79
Name Thousands: Lookup!$D$49
Name Title_Msg: Checks!$H$10
Name Yes: Lookup!$D$41
Name Yes_No: Lookup!$D$41:$D$42

Sheet Cover
B3: ACS Pricing Model - Power and Water Corporation
C11: Model Developer: | F11: Power and Water Corporation
C13: Purpose of the Model:
C14: The purpose of this model is to assesses tariffs for alternative control services (ACS) applicable to Power and Water Corporation customers and demonstrate compliance with AER requirements.
C16: Model Legend:
D19: Assumptions | F19: Cells containing assumptions intended to be manipulated by model users
D20: Drop Down | F20: Cells containing a drop down list for users to select inputs
D21: Input | F21: Cells containing input texts/numbers NOT intended to be changed by model users
D22: Output | F22: Cells containing formulae NOT intended to be changed by model users
D23: Heading 1 | F23: Level 1 heading NOT intended to be changed by model users
D24: Heading 2 | F24: Level 2 heading NOT intended to be changed by model users
F25: Cells where inputs or outputs are not applicable
D26: Hyperlink | F26: Cells containing a hyperlink to another part of the workbook
D27: Error | F27: Cells representing there is an error in the nominated area of the workbook
D28: Ok | F28: Cells representing there are no errors in the nominated area of the workbook
F29: Cells containing a link from external workbooks
C32: Disclaimer:
C33: This model is confidential information of, and is owned by, Power and Water Corporation ABN 15 947 352 360 (PWC). It may not be disclosed to, or used or relied on by, any person without the consent of PWC. PWC has not verified the inputs or the outputs of this model and makes no representation or warranty as to the completeness, accuracy, reliability or appropriateness of the model, its inputs and outputs (including any forward looking statements) or how it functions. To the extent permitted by law, any person using or relying on this model or its outputs does so at their own risk and agrees that PWC will not be liable to any person for any loss or damage of any kind arising out of or in any way connected with the use of this model (including negligence). The references to PWC in this disclaimer includes their respective directors, officers, employees, contractors, advisers or agents.

Sheet TOC
B1: Table of Contents
B2: =Title_Msg -> No Errors Found
B3: Go to Cover Sheet
B4: =Model_Name -> ACS Pricing Model - Power and Water Corporation
B6: =B1 -> Table of Contents
C8: Inputs
D10: =Inputs_Prices!$B$1 -> Inputs - Prices
C12: Calculations
D14: =Calculations_Price_Caps!$B$1 -> Calculation - Price Caps
C16: Outputs
D18: =Output_Compliance!$B$1 -> Output - Compliance
D19: =Output_Pricing_Proposal!B1 -> Output - Pricing Proposal
C21: Appendix
D23: =Lookup!B1 -> Model Lookups
D24: =Checks!B1 -> Checks
B26: End

Sheet Diagram
A1: =IF(SUM($A6:$A50)>0,1,0) -> 0 | B1: Model Diagram
B2: =Title_Msg -> No Errors Found
B3: =TOC!B1 -> Table of Contents
B4: =Model_Name -> ACS Pricing Model - Power and Water Corporation
B6: =B1 -> Model Diagram
B50: End

Sheet Inputs_Prices
A1: =IF(SUM($A11:$A261)>0,1,0) -> 0 | B1: Inputs - Prices
B2: =Title_Msg -> No Errors Found
B3: =TOC!B1 -> Table of Contents
B4: =Model_Name -> ACS Pricing Model - Power and Water Corporation
B5: =Lookup!B15 -> Period Start Date | M5: =Lookup!M15 -> 42917 | N5: =Lookup!N15 -> 43282 | O5: =Lookup!O15 -> 43647 | P5: =Lookup!P15 -> 44013 | Q5: =Lookup!Q15 -> 44378 | R5: =Lookup!R15 -> 44743 | S5: =Lookup!S15 -> 45108
B6: =Lookup!B16 -> Period End Date | M6: =Lookup!M16 -> 43281 | N6: =Lookup!N16 -> 43646 | O6: =Lookup!O16 -> 44012 | P6: =Lookup!P16 -> 44377 | Q6: =Lookup!Q16 -> 44742 | R6: =Lookup!R16 -> 45107 | S6: =Lookup!S16 -> 45473
B7: =Lookup!B17 -> Period Counter | M7: =Lookup!M17 -> 4 | N7: =Lookup!N17 -> 5 | O7: =Lookup!O17 -> 6 | P7: =Lookup!P17 -> 7 | Q7: =Lookup!Q17 -> 8 | R7: =Lookup!R17 -> 9 | S7: =Lookup!S17 -> 10
B8: =Lookup!B18 -> Year | M8: =Lookup!M18 -> 2018 | N8: =Lookup!N18 -> 2019 | O8: =Lookup!O18 -> 2020 | P8: =Lookup!P18 -> 2021 | Q8: =Lookup!Q18 -> 2022 | R8: =Lookup!R18 -> 2023 | S8: =Lookup!S18 -> 2024
B9: =Lookup!B19 -> Days In Year | M9: =Lookup!M19 -> 365 | N9: =Lookup!N19 -> 365 | O9: =Lookup!O19 -> 366 | P9: =Lookup!P19 -> 365 | Q9: =Lookup!Q19 -> 365 | R9: =Lookup!R19 -> 365 | S9: =Lookup!S19 -> 366
B10: =Lookup!B20 -> FY | D10: Tariff | E10: Service Category | H10: Source | I10: Unit | J10: =Lookup!G20 -> Basis | M10: =Lookup!M20 -> FY18 | N10: =Lookup!N20 -> FY19 | O10: =Lookup!O20 -> FY20 | P10: =Lookup!P20 -> FY21 | Q10: =Lookup!Q20 -> FY22 | R10: =Lookup!R20 -> FY23 | S10: =Lookup!S20 -> FY24
B12: Inputs
D14: This sheet inputs the proposed prices for each ACS service along with the data used to calculate the price caps included within the AER's revenue determination for the 2019-24 period.
B17: PWC Inputs (Years 2 to 5)
D19: This section inputs values provided by PWC. The first sub-section inputs the proposed prices for years 2 to 5 of the regulatory period. The second sub-section inputs any proposed annual adjustments (e.g. to cover pass-throughs).
D20: As per the AER's determination, annual adjustments are only allowed for ACS metering and ACS fee based services.
C23: Prices (Years 2 to 5)
D26: Service | E26: =E$10 -> Service Category | H26: =H$10 -> Source | I26: =I$10 -> Unit | J26: =J$10 -> Basis | P26: =P$10 -> FY21 | Q26: =Q$10 -> FY22 | R26: =R$10 -> FY23 | S26: =S$10 -> FY24
D28: Metering Services (Types 1 to 6)
D29: {=LU_Metering_Services} -> 1 Phase Meters (including Prepayment) | H29: PWC | I29: $/Year/Meter | J29: Nominal | P29: 64.66 | Q29: 68.39 | R29: 72.34 | S29: 76.52 | U29: Note: proposed prices are rounded to 2 decimal places
D30: 3 Phase Meters | H30: PWC | I30: $/Year/Meter | J30: Nominal | P30: 71.19 | Q30: 75.3 | R30: 79.65 | S30: 84.25
D31: Dedicated CT and VT meters | H31: PWC | I31: $/Year/Meter | J31: Nominal | P31: 120.58 | Q31: 127.54 | R31: 134.9 | S31: 142.69
D33: Fee Based Services
D34: {=LU_Fee_Based_Services} -> Disconnection (and final read) | E34: Connection Services | H34: PWC | I34: $/Request | J34: Nominal | P34: 65.35 | Q34: 64 | R34: 62.64 | S34: 61.24
D35: Reconnection | E35: Connection Services | H35: PWC | I35: $/Request | J35: Nominal | P35: 65.35 | Q35: 64 | R35: 62.64 | S35: 61.24
D36: Reconnection - after hours | E36: Connection Services | H36: PWC | I36: $/Request | J36: Nominal | P36: 121.39 | Q36: 118.88 | R36: 116.35 | S36: 113.75
D37: Temporary disconnection and reconnection - physical dismantling | E37: Connection Services | H37: PWC | I37: $/Request | J37: Nominal | P37: 755.16 | Q37: 779.8 | R37: 806.48 | S37: 834
D38: Provision of 3 phase service | E38: Connection Services | H38: PWC | I38: $/Request | J38: Nominal | P38: 1434.81 | Q38: 1481.63 | R38: 1532.31 | S38: 1584.6
D39: Standard temporary builder’s connection | E39: Connection Services | H39: PWC | I39: $/Request | J39: Nominal | P39: 673.61 | Q39: 695.59 | R39: 719.39 | S39: 743.94
D40: Temporary disconnection and reconnection - no dismantling | E40: De-energisation / Re-energisation | H40: PWC | I40: $/Request | J40: Nominal | P40: 293 | Q40: 302.56 | R40: 312.91 | S40: 323.59
D41: Complex disconnection | E41: De-energisation / Re-energisation | H41: PWC | I41: $/Request | J41: Nominal | P41: 320.19 | Q41: 330.64 | R41: 341.95 | S41: 353.62
D42: Wasted visit fee | E42: Connection Services | H42: PWC | I42: $/Request | J42: Nominal | P42: 157.07 | Q42: 162.2 | R42: 167.75 | S42: 173.47
D43: Special meter test | E43: Meter Servicing (Fee based) | H43: PWC | I43: $/Request | J43: Nominal | P43: 306.6 | Q43: 316.61 | R43: 327.44 | S43: 338.61
D44: Exchange or replace meter – three phase | E44: Meter Servicing (Fee based) | H44: PWC | I44: $/Request | J44: Nominal | P44: 676.38 | Q44: 698.45 | R44: 722.34 | S44: 746.99
D45: Exchange or replace meter - single phase | E45: Meter Servicing (Fee based) | H45: PWC | I45: $/Request | J45: Nominal | P45: 566.26 | Q45: 584.74 | R45: 604.74 | S45: 625.38
D46: Relocation of meter | E46: Meter Servicing (Fee based) | H46: PWC | I46: $/Request | J46: Nominal | P46: 320.19 | Q46: 330.64 | R46: 341.95 | S46: 353.62
... D60: Class 1 & 2 PV service | E60: Connection Services | H60: PWC | I60: $/Request | J60: Nominal | P60: 89.3 | Q60: 92.21 | R60: 95.36 | S60: 98.61
D62: Quoted Services | Labour Component
D63: {=LU_Quoted_Services} -> Design related services | E63: Not Applicable | H63: PWC | I63: $/Hour | J63: Nominal | P63: 159.39 | Q63: 164.59 | R63: 170.22 | S63: 176.03
D64: Connection applications | E64: Not Applicable | H64: PWC | I64: $/Hour | J64: Nominal | P64: 159.39 | Q64: 164.59 | R64: 170.22 | S64: 176.03
D65: Access permits, oversights and facilitation | E65: Not Applicable | H65: PWC | I65: $/Hour | J65: Nominal | P65: 159.39 | Q65: 164.59 | R65: 170.22 | S65: 176.03
...

Sheet Calculations_Price_Caps
A1: =IF(SUM($A11:$A114)>0,1,0) -> 0 | B1: Calculation - Price Caps
B2: =Title_Msg -> No Errors Found
B3: =TOC!B1 -> Table of Contents
B4: =Model_Name -> ACS Pricing Model - Power and Water Corporation
B5: =Lookup!B15 -> Period Start Date | O5: =Lookup!O15 -> 43647 | P5: =Lookup!P15 -> 44013 | Q5: =Lookup!Q15 -> 44378 | R5: =Lookup!R15 -> 44743 | S5: =Lookup!S15 -> 45108
B6: =Lookup!B16 -> Period End Date | O6: =Lookup!O16 -> 44012 | P6: =Lookup!P16 -> 44377 | Q6: =Lookup!Q16 -> 44742 | R6: =Lookup!R16 -> 45107 | S6: =Lookup!S16 -> 45473
B7: =Lookup!B17 -> Period Counter | O7: =Lookup!O17 -> 6 | P7: =Lookup!P17 -> 7 | Q7: =Lookup!Q17 -> 8 | R7: =Lookup!R17 -> 9 | S7: =Lookup!S17 -> 10
B8: =Lookup!B18 -> Year | O8: =Lookup!O18 -> 2020 | P8: =Lookup!P18 -> 2021 | Q8: =Lookup!Q18 -> 2022 | R8: =Lookup!R18 -> 2023 | S8: =Lookup!S18 -> 2024
B9: =Lookup!B19 -> Days In Year | O9: =Lookup!O19 -> 366 | P9: =Lookup!P19 -> 365 | Q9: =Lookup!Q19 -> 365 | R9: =Lookup!R19 -> 365 | S9: =Lookup!S19 -> 366
B10: =Lookup!B20 -> FY | D10: Tariff | E10: Service Category | H10: Source | I10: Unit | J10: =Lookup!G20 -> Basis | M10: =Lookup!M20 -> FY18 | N10: =Lookup!N20 -> FY19 | O10: =Lookup!O20 -> FY20 | P10: =Lookup!P20 -> FY21 | Q10: =Lookup!Q20 -> FY22 | R10: =Lookup!R20 -> FY23 | S10: =Lookup!S20 -> FY24
B12: Price Caps by Service
D14: This sheet calculates the price caps for each alternative control service, split between metering services (types 1 to 6), fee based services and quoted services.
D15: The price caps are calculated as per the formulas included in Attachment 13 of the Australian Energy Regulator's draft revenue determination for the 2019-24 period (repeated below), which were adopted in the final determination.
D16: Only the price cap of the labour component for quoted services is calculated. The contractor services and materials components are simply included at cost at the time a service is quoted.
C55: Price Caps
D58: Service | H58: =Lookup!E$20 -> Source | I58: =Lookup!F$20 -> Unit | J58: =Lookup!G$20 -> Basis | O58: =O$10 -> FY20 | P58: =P$10 -> FY21 | Q58: =Q$10 -> FY22 | R58: =R$10 -> FY23 | S58: =S$10 -> FY24
D60: Metering Services (Types 1 to 6)
D61: {=LU_Metering_Services} -> 1 Phase Meters (including Prepayment) | H61: Calculated | I61: $/Year/Meter | J61: Nominal | O61: =Inputs_Prices!O149 -> 61.48 | P61: =ROUND(O61*(1+Inputs_Prices!P$139)*(1-Inputs_Prices!P208)+Inputs_Prices!P88,2) -> 64.66 | Q61: =ROUND(P61*(1+Inputs_Prices!Q$139)*(1-Inputs_Prices!Q208)+Inputs_Prices!Q88,2) -> 68.39 | R61: =ROUND(Q61*(1+Inputs_Prices!R$139)*(1-Inputs_Prices!R208)+Inputs_Prices!R88,2) -> 72.34 | S61: =ROUND(R61*(1+Inputs_Prices!S$139)*(1-Inputs_Prices!S208)+Inputs_Prices!S88,2) -> 76.52 | T61: Note: price caps are rounded to 2 decimal places
D62: 3 Phase Meters | H62: Calculated | I62: $/Year/Meter | J62: Nominal | O62: =Inputs_Prices!O150 -> 67.69 | P62: =ROUND(O62*(1+Inputs_Prices!P$139)*(1-Inputs_Prices!P209)+Inputs_Prices!P89,2) -> 71.19 | Q62: =ROUND(P62*(1+Inputs_Prices!Q$139)*(1-Inputs_Prices!Q209)+Inputs_Prices!Q89,2) -> 75.3 | R62: =ROUND(Q62*(1+Inputs_Prices!R$139)*(1-Inputs_Prices!R209)+Inputs_Prices!R89,2) -> 79.65 | S62: =ROUND(R62*(1+Inputs_Prices!S$139)*(1-Inputs_Prices!S209)+Inputs_Prices!S89,2) -> 84.25
D63: Dedicated CT and VT meters | H63: Calculated | I63: $/Year/Meter | J63: Nominal | O63: =Inputs_Prices!O151 -> 114.65 | P63: =ROUND(O63*(1+Inputs_Prices!P$139)*(1-Inputs_Prices!P210)+Inputs_Prices!P90,2) -> 120.58 | Q63: =ROUND(P63*(1+Inputs_Prices!Q$139)*(1-Inputs_Prices!Q210)+Inputs_Prices!Q90,2) -> 127.54 | R63: =ROUND(Q63*(1+Inputs_Prices!R$139)*(1-Inputs_Prices!R210)+Inputs_Prices!R90,2) -> 134.9 | S63: =ROUND(R63*(1+Inputs_Prices!S$139)*(1-Inputs_Prices!S210)+Inputs_Prices!S90,2) -> 142.69
D65: Fee Based Services
D66: {=LU_Fee_Based_Services} -> Disconnection (and final read) | H66: Calculated | I66: $/Request | J66: Nominal | O66: =Inputs_Prices!O154 -> 66.99 | P66: =ROUND(O66*(1+Inputs_Prices!P$139)*(1-Inputs_Prices!P213)+Inputs_Prices!P93,2) -> 65.35 | Q66: =ROUND(P66*(1+Inputs_Prices!Q$139)*(1-Inputs_Prices!Q213)+Inputs_Prices!Q93,2) -> 64 | R66: =ROUND(Q66*(1+Inputs_Prices!R$139)*(1-Inputs_Prices!R213)+Inputs_Prices!R93,2) -> 62.64 | S66: =ROUND(R66*(1+Inputs_Prices!S$139)*(1-Inputs_Prices!S213)+Inputs_Prices!S93,2) -> 61.24
D67: Reconnection | H67: Calculated | I67: $/Request | J67: Nominal | O67: =Inputs_Prices!O155 -> 66.99 | P67: =ROUND(O67*(1+Inputs_Prices!P$139)*(1-Inputs_Prices!P214)+Inputs_Prices!P94,2) -> 65.35 | Q67: =ROUND(P67*(1+Inputs_Prices!Q$139)*(1-Inputs_Prices!Q214)+Inputs_Prices!Q94,2) -> 64 | R67: =ROUND(Q67*(1+Inputs_Prices!R$139)*(1-Inputs_Prices!R214)+Inputs_Prices!R94,2) -> 62.64 | S67: =ROUND(R67*(1+Inputs_Prices!S$139)*(1-Inputs_Prices!S214)+Inputs_Prices!S94,2) -> 61.24
D68: Reconnection - after hours | H68: Calculated | I68: $/Request | J68: Nominal | O68: =Inputs_Prices!O156 -> 124.43 | P68: =ROUND(O68*(1+Inputs_Prices!P$139)*(1-Inputs_Prices!P215)+Inputs_Prices!P95,2) -> 121.39 | Q68: =ROUND(P68*(1+Inputs_Prices!Q$139)*(1-Inputs_Prices!Q215)+Inputs_Prices!Q95,2) -> 118.88 | R68: =ROUND(Q68*(1+Inputs_Prices!R$139)*(1-Inputs_Prices!R215)+Inputs_Prices!R95,2) -> 116.35 | S68: =ROUND(R68*(1+Inputs_Prices!S$139)*(1-Inputs_Prices!S215)+Inputs_Prices!S95,2) -> 113.75
D69: Temporary disconnection and reconnection - physical dismantling | H69: Calculated | I69: $/Request | J69: Nominal | O69: =Inputs_Prices!O157 -> 737.3 | P69: =ROUND(O69*(1+Inputs_Prices!P$139)*(1-Inputs_Prices!P216)+Inputs_Prices!P96,2) -> 755.16 | Q69: =ROUND(P69*(1+Inputs_Prices!Q$139)*(1-Inputs_Prices!Q216)+Inputs_Prices!Q96,2) -> 779.8 | R69: =ROUND(Q69*(1+Inputs_Prices!R$139)*(1-Inputs_Prices!R216)+Inputs_Prices!R96,2) -> 806.48 | S69: =ROUND(R69*(1+Inputs_Prices!S$139)*(1-Inputs_Prices!S216)+Inputs_Prices!S96,2) -> 834
D70: Provision of 3 phase service | H70: Calculated | I70: $/Request | J70: Nominal | O70: =Inputs_Prices!O158 -> 1400.88 | P70: =ROUND(O70*(1+Inputs_Prices!P$139)*(1-Inputs_Prices!P217)+Inputs_Prices!P97,2) -> 1434.81 | Q70: =ROUND(P70*(1+Inputs_Prices!Q$139)*(1-Inputs_Prices!Q217)+Inputs_Prices!Q97,2) -> 1481.63 | R70: =ROUND(Q70*(1+Inputs_Prices!R$139)*(1-Inputs_Prices!R217)+Inputs_Prices!R97,2) -> 1532.31 | S70: =ROUND(R70*(1+Inputs_Prices!S$139)*(1-Inputs_Prices!S217)+Inputs_Prices!S97,2) -> 1584.6
D71: Standard temporary builder’s connection | H71: Calculated | I71: $/Request | J71: Nominal | O71: =Inputs_Prices!O159 -> 657.68 | P71: =ROUND(O71*(1+Inputs_Prices!P$139)*(1-Inputs_Prices!P218)+Inputs_Prices!P98,2) -> 673.61 | Q71: =ROUND(P71*(1+Inputs_Prices!Q$139)*(1-Inputs_Prices!Q218)+Inputs_Prices!Q98,2) -> 695.59 | R71: =ROUND(Q71*(1+Inputs_Prices!R$139)*(1-Inputs_Prices!R218)+Inputs_Prices!R98,2) -> 719.39 | S71: =ROUND(R71*(1+Inputs_Prices!S$139)*(1-Inputs_Prices!S218)+Inputs_Prices!S98,2) -> 743.94
D72: Temporary disconnection and reconnection - no dismantling | H72: Calculated | I72: $/Request | J72: Nominal | O72: =Inputs_Prices!O160 -> 286.07 | P72: =ROUND(O72*(1+Inputs_Prices!P$139)*(1-Inputs_Prices!P219)+Inputs_Prices!P99,2) -> 293 | Q72: =ROUND(P72*(1+Inputs_Prices!Q$139)*(1-Inputs_Prices!Q219)+Inputs_Prices!Q99,2) -> 302.56 | R72: =ROUND(Q72*(1+Inputs_Prices!R$139)*(1-Inputs_Prices!R219)+Inputs_Prices!R99,2) -> 312.91 | S72: =ROUND(R72*(1+Inputs_Prices!S$139)*(1-Inputs_Prices!S219)+Inputs_Prices!S99,2) -> 323.59
D73: Complex disconnection | H73: Calculated | I73: $/Request | J73: Nominal | O73: =Inputs_Prices!O161 -> 312.62 | P73: =ROUND(O73*(1+Inputs_Prices!P$139)*(1-Inputs_Prices!P220)+Inputs_Prices!P100,2) -> 320.19 | Q73: =ROUND(P73*(1+Inputs_Prices!Q$139)*(1-Inputs_Prices!Q220)+Inputs_Prices!Q100,2) -> 330.64 | R73: =ROUND(Q73*(1+Inputs_Prices!R$139)*(1-Inputs_Prices!R220)+Inputs_Prices!R100,2) -> 341.95 | S73: =ROUND(R73*(1+Inputs_Prices!S$139)*(1-Inputs_Prices!S220)+Inputs_Prices!S100,2) -> 353.62
D74: Wasted visit fee | H74: Calculated | I74: $/Request | J74: Nominal | O74: =Inputs_Prices!O162 -> 153.36 | P74: =ROUND(O74*(1+Inputs_Prices!P$139)*(1-Inputs_Prices!P221)+Inputs_Prices!P101,2) -> 157.07 | Q74: =ROUND(P74*(1+Inputs_Prices!Q$139)*(1-Inputs_Prices!Q221)+Inputs_Prices!Q101,2) -> 162.2 | R74: =ROUND(Q74*(1+Inputs_Prices!R$139)*(1-Inputs_Prices!R221)+Inputs_Prices!R101,2) -> 167.75 | S74: =ROUND(R74*(1+Inputs_Prices!S$139)*(1-Inputs_Prices!S221)+Inputs_Prices!S101,2) -> 173.47
D75: Special meter test | H75: Calculated | I75: $/Request | J75: Nominal | O75: =Inputs_Prices!O163 -> 299.35 | P75: =ROUND(O75*(1+Inputs_Prices!P$139)*(1-Inputs_Prices!P222)+Inputs_Prices!P102,2) -> 306.6 | Q75: =ROUND(P75*(1+Inputs_Prices!Q$139)*(1-Inputs_Prices!Q222)+Inputs_Prices!Q102,2) -> 316.61 | R75: =ROUND(Q75*(1+Inputs_Prices!R$139)*(1-Inputs_Prices!R222)+Inputs_Prices!R102,2) -> 327.44 | S75: =ROUND(R75*(1+Inputs_Prices!S$139)*(1-Inputs_Prices!S222)+Inputs_Prices!S102,2) -> 338.61
D76: Exchange or replace meter – three phase | H76: Calculated | I76: $/Request | J76: Nominal | O76: =Inputs_Prices!O164 -> 660.39 | P76: =ROUND(O76*(1+Inputs_Prices!P$139)*(1-Inputs_Prices!P223)+Inputs_Prices!P103,2) -> 676.38 | Q76: =ROUND(P76*(1+Inputs_Prices!Q$139)*(1-Inputs_Prices!Q223)+Inputs_Prices!Q103,2) -> 698.45 | R76: =ROUND(Q76*(1+Inputs_Prices!R$139)*(1-Inputs_Prices!R223)+Inputs_Prices!R103,2) -> 722.34 | S76: =ROUND(R76*(1+Inputs_Prices!S$139)*(1-Inputs_Prices!S223)+Inputs_Prices!S103,2) -> 746.99
D77: Exchange or replace meter - single phase | H77: Calculated | I77: $/Request | J77: Nominal | O77: =Inputs_Prices!O165 -> 552.87 | P77: =ROUND(O77*(1+Inputs_Prices!P$139)*(1-Inputs_Prices!P224)+Inputs_Prices!P104,2) -> 566.26 | Q77: =ROUND(P77*(1+Inputs_Prices!Q$139)*(1-Inputs_Prices!Q224)+Inputs_Prices!Q104,2) -> 584.74 | R77: =ROUND(Q77*(1+Inputs_Prices!R$139)*(1-Inputs_Prices!R224)+Inputs_Prices!R104,2) -> 604.74 | S77: =ROUND(R77*(1+Inputs_Prices!S$139)*(1-Inputs_Prices!S224)+Inputs_Prices!S104,2) -> 625.38
D78: Relocation of meter | H78: Calculated | I78: $/Request | J78: Nominal | O78: =Inputs_Prices!O166 -> 312.62 | P78: =ROUND(O78*(1+Inputs_Prices!P$139)*(1-Inputs_Prices!P225)+Inputs_Prices!P105,2) -> 320.19 | Q78: =ROUND(P78*(1+Inputs_Prices!Q$139)*(1-Inputs_Prices!Q225)+Inputs_Prices!Q105,2) -> 330.64 | R78: =ROUND(Q78*(1+Inputs_Prices!R$139)*(1-Inputs_Prices!R225)+Inputs_Prices!R105,2) -> 341.95 | S78: =ROUND(R78*(1+Inputs_Prices!S$139)*(1-Inputs_Prices!S225)+Inputs_Prices!S105,2) -> 353.62
... D92: Class 1 & 2 PV service | H92: Calculated | I92: $/Request | J92: Nominal | O92: =Inputs_Prices!O180 -> 87.19 | P92: =ROUND(O92*(1+Inputs_Prices!P$139)*(1-Inputs_Prices!P239)+Inputs_Prices!P119,2) -> 89.3 | Q92: =ROUND(P92*(1+Inputs_Prices!Q$139)*(1-Inputs_Prices!Q239)+Inputs_Prices!Q119,2) -> 92.21 | R92: =ROUND(Q92*(1+Inputs_Prices!R$139)*(1-Inputs_Prices!R239)+Inputs_Prices!R119,2) -> 95.36 | S92: =ROUND(R92*(1+Inputs_Prices!S$139)*(1-Inputs_Prices!S239)+Inputs_Prices!S119,2) -> 98.61
D94: Quoted Services | Labour Component
D95: {=LU_Quoted_Services} -> Design related services | H95: Calculated | I95: $/Hour | J95: Nominal | O95: =Inputs_Prices!O183 -> 155.62 | P95: =ROUND(O95*(1+Inputs_Prices!P$139)*(1-Inputs_Prices!P242),2) -> 159.39 | Q95: =ROUND(P95*(1+Inputs_Prices!Q$139)*(1-Inputs_Prices!Q242),2) -> 164.59 | R95: =ROUND(Q95*(1+Inputs_Prices!R$139)*(1-Inputs_Prices!R242),2) -> 170.22 | S95: =ROUND(R95*(1+Inputs_Prices!S$139)*(1-Inputs_Prices!S242),2) -> 176.03
D96: Connection applications | H96: Calculated | I96: $/Hour | J96: Nominal | O96: =Inputs_Prices!O184 -> 155.62 | P96: =ROUND(O96*(1+Inputs_Prices!P$139)*(1-Inputs_Prices!P243),2) -> 159.39 | Q96: =ROUND(P96*(1+Inputs_Prices!Q$139)*(1-Inputs_Prices!Q243),2) -> 164.59 | R96: =ROUND(Q96*(1+Inputs_Prices!R$139)*(1-Inputs_Prices!R243),2) -> 170.22 | S96: =ROUND(R96*(1+Inputs_Prices!S$139)*(1-Inputs_Prices!S243),2) -> 176.03
D97: Access permits, oversights and facilitation | H97: Calculated | I97: $/Hour | J97: Nominal | O97: =Inputs_Prices!O185 -> 155.62 | P97: =ROUND(O97*(1+Inputs_Prices!P$139)*(1-Inputs_Prices!P244),2) -> 159.39 | Q97: =ROUND(P97*(1+Inputs_Prices!Q$139)*(1-Inputs_Prices!Q244),2) -> 164.59 | R97: =ROUND(Q97*(1+Inputs_Prices!R$139)*(1-Inputs_Prices!R244),2) -> 170.22 | S97: =ROUND(R97*(1+Inputs_Prices!S$139)*(1-Inputs_Prices!S244),2) -> 176.03
D98: Notices of arrangement and completion notices | H98: Calculated | I98: $/Hour | J98: Nominal | O98: =Inputs_Prices!O186 -> 87.19 | P98: =ROUND(O98*(1+Inputs_Prices!P$139)*(1-Inputs_Prices!P245),2) -> 89.3 | Q98: =ROUND(P98*(1+Inputs_Prices!Q$139)*(1-Inputs_Prices!Q245),2) -> 92.21 | R98: =ROUND(Q98*(1+Inputs_Prices!R$139)*(1-Inputs_Prices!R245),2) -> 95.36 | S98: =ROUND(R98*(1+Inputs_Prices!S$139)*(1-Inputs_Prices!S245),2) -> 98.61
...

Sheet Output_Compliance
A1: =IF(SUM($A11:$A84)>0,1,0) -> 0 | B1: Output - Compliance
B2: =Title_Msg -> No Errors Found
B3: =TOC!B1 -> Table of Contents
B4: =Model_Name -> ACS Pricing Model - Power and Water Corporation
B5: =Lookup!B15 -> Period Start Date | M5: =Lookup!M15 -> 42917 | N5: =Lookup!N15 -> 43282 | O5: =Lookup!O15 -> 43647 | P5: =Lookup!P15 -> 44013 | Q5: =Lookup!Q15 -> 44378 | R5: =Lookup!R15 -> 44743 | S5: =Lookup!S15 -> 45108
B6: =Lookup!B16 -> Period End Date | M6: =Lookup!M16 -> 43281 | N6: =Lookup!N16 -> 43646 | O6: =Lookup!O16 -> 44012 | P6: =Lookup!P16 -> 44377 | Q6: =Lookup!Q16 -> 44742 | R6: =Lookup!R16 -> 45107 | S6: =Lookup!S16 -> 45473
B7: =Lookup!B17 -> Period Counter | M7: =Lookup!M17 -> 4 | N7: =Lookup!N17 -> 5 | O7: =Lookup!O17 -> 6 | P7: =Lookup!P17 -> 7 | Q7: =Lookup!Q17 -> 8 | R7: =Lookup!R17 -> 9 | S7: =Lookup!S17 -> 10
B8: =Lookup!B18 -> Year | M8: =Lookup!M18 -> 2018 | N8: =Lookup!N18 -> 2019 | O8: =Lookup!O18 -> 2020 | P8: =Lookup!P18 -> 2021 | Q8: =Lookup!Q18 -> 2022 | R8: =Lookup!R18 -> 2023 | S8: =Lookup!S18 -> 2024
B9: =Lookup!B19 -> Days In Year | M9: =Lookup!M19 -> 365 | N9: =Lookup!N19 -> 365 | O9: =Lookup!O19 -> 366 | P9: =Lookup!P19 -> 365 | Q9: =Lookup!Q19 -> 365 | R9: =Lookup!R19 -> 365 | S9: =Lookup!S19 -> 366
B10: =Lookup!B20 -> FY | D10: Tariff Class | H10: =Lookup!E20 -> Source | I10: =Lookup!F20 -> Unit | J10: =Lookup!G20 -> Basis | M10: =Lookup!M20 -> FY18 | N10: =Lookup!N20 -> FY19 | O10: =Lookup!O20 -> FY20 | P10: =Lookup!P20 -> FY21 | Q10: =Lookup!Q20 -> FY22 | R10: =Lookup!R20 -> FY23 | S10: =Lookup!S20 -> FY24
B12: Compliance Checks
D14: This sheet tests whether the proposed prices fall within the calculated price caps. The checks are
D16: Tariff Compliance Year: | H16: FY21 | I16: ="Note: years prior to "&H16&" are ignored from the checks" -> Note: years prior to FY21 are ignored from the checks
D18: Summary
D19: Metering Services (Types 1 to 6) | H19: =IF(COUNTIF(OFFSET($P$31:$P$33,0,MATCH($H$16,$P$10:$S$10)-1,COUNTA($P$31:$P$33),COUNTA($P$10:$S$10)-MATCH($H$16,$P$10:$S$10)+1),"Fail")>0,"Fail","Pass") -> Pass
D20: Fee Based Services | H20: =IF(COUNTIF(OFFSET($P$36:$P$62,0,MATCH($H$16,$P$10:$S$10)-1,COUNTA($P$36:$P$62),COUNTA($P$10:$S$10)-MATCH($H$16,$P$10:$S$10)+1),"Fail")>0,"Fail","Pass") -> Pass
D21: Quoted Services (Labour Component Only) | H21: =IF(COUNTIF(OFFSET($P$65:$P$80,0,MATCH($H$16,$P$10:$S$10)-1,COUNTA($P$65:$P$80),COUNTA($P$10:$S$10)-MATCH($H$16,$P$10:$S$10)+1),"Fail")>0,"Fail","Pass") -> Pass | I21: =IF(H21="NA","Note: The side constraint only applies from year 2 of the regulatory period","")
A23: =IF(SUM($H23)=0,0,1) -> 0 | D23: Check for errors | H23: =COUNTIF(H19:H21,"Fail") -> 0
C25: Price Caps
D28: Service | H28: =Lookup!E$20 -> Source | I28: =Lookup!F$20 -> Unit | J28: =Lookup!G$20 -> Basis | P28: =P$10 -> FY21 | Q28: =Q$10 -> FY22 | R28: =R$10 -> FY23 | S28: =S$10 -> FY24
D30: Metering Services (Types 1 to 6)
D31: {=LU_Metering_Services} -> 1 Phase Meters (including Prepayment) | H31: Calculated | I31: $/Year/Meter | J31: Nominal | P31: =IF(Inputs_Prices!P29>Calculations_Price_Caps!P61,"Fail","Pass") -> Pass | Q31: =IF(Inputs_Prices!Q29>Calculations_Price_Caps!Q61,"Fail","Pass") -> Pass | R31: =IF(Inputs_Prices!R29>Calculations_Price_Caps!R61,"Fail","Pass") -> Pass | S31: =IF(Inputs_Prices!S29>Calculations_Price_Caps!S61,"Fail","Pass") -> Pass
D32: 3 Phase Meters | H32: Calculated | I32: $/Year/Meter | J32: Nominal | P32: =IF(Inputs_Prices!P30>Calculations_Price_Caps!P62,"Fail","Pass") -> Pass | Q32: =IF(Inputs_Prices!Q30>Calculations_Price_Caps!Q62,"Fail","Pass") -> Pass | R32: =IF(Inputs_Prices!R30>Calculations_Price_Caps!R62,"Fail","Pass") -> Pass | S32: =IF(Inputs_Prices!S30>Calculations_Price_Caps!S62,"Fail","Pass") -> Pass
D33: Dedicated CT and VT meters | H33: Calculated | I33: $/Year/Meter | J33: Nominal | P33: =IF(Inputs_Prices!P31>Calculations_Price_Caps!P63,"Fail","Pass") -> Pass | Q33: =IF(Inputs_Prices!Q31>Calculations_Price_Caps!Q63,"Fail","Pass") -> Pass | R33: =IF(Inputs_Prices!R31>Calculations_Price_Caps!R63,"Fail","Pass") -> Pass | S33: =IF(Inputs_Prices!S31>Calculations_Price_Caps!S63,"Fail","Pass") -> Pass
D35: Fee Based Services
D36: {=LU_Fee_Based_Services} -> Disconnection (and final read) | H36: Calculated | I36: $/Request | J36: Nominal | P36: =IF(Inputs_Prices!P34>Calculations_Price_Caps!P66,"Fail","Pass") -> Pass | Q36: =IF(Inputs_Prices!Q34>Calculations_Price_Caps!Q66,"Fail","Pass") -> Pass | R36: =IF(Inputs_Prices!R34>Calculations_Price_Caps!R66,"Fail","Pass") -> Pass | S36: =IF(Inputs_Prices!S34>Calculations_Price_Caps!S66,"Fail","Pass") -> Pass
D37: Reconnection | H37: Calculated | I37: $/Request | J37: Nominal | P37: =IF(Inputs_Prices!P35>Calculations_Price_Caps!P67,"Fail","Pass") -> Pass | Q37: =IF(Inputs_Prices!Q35>Calculations_Price_Caps!Q67,"Fail","Pass") -> Pass | R37: =IF(Inputs_Prices!R35>Calculations_Price_Caps!R67,"Fail","Pass") -> Pass | S37: =IF(Inputs_Prices!S35>Calculations_Price_Caps!S67,"Fail","Pass") -> Pass
D38: Reconnection - after hours | H38: Calculated | I38: $/Request | J38: Nominal | P38: =IF(Inputs_Prices!P36>Calculations_Price_Caps!P68,"Fail","Pass") -> Pass | Q38: =IF(Inputs_Prices!Q36>Calculations_Price_Caps!Q68,"Fail","Pass") -> Pass | R38: =IF(Inputs_Prices!R36>Calculations_Price_Caps!R68,"Fail","Pass") -> Pass | S38: =IF(Inputs_Prices!S36>Calculations_Price_Caps!S68,"Fail","Pass") -> Pass
D39: Temporary disconnection and reconnection - physical dismantling | H39: Calculated | I39: $/Request | J39: Nominal | P39: =IF(Inputs_Prices!P37>Calculations_Price_Caps!P69,"Fail","Pass") -> Pass | Q39: =IF(Inputs_Prices!Q37>Calculations_Price_Caps!Q69,"Fail","Pass") -> Pass | R39: =IF(Inputs_Prices!R37>Calculations_Price_Caps!R69,"Fail","Pass") -> Pass | S39: =IF(Inputs_Prices!S37>Calculations_Price_Caps!S69,"Fail","Pass") -> Pass
D40: Provision of 3 phase service | H40: Calculated | I40: $/Request | J40: Nominal | P40: =IF(Inputs_Prices!P38>Calculations_Price_Caps!P70,"Fail","Pass") -> Pass | Q40: =IF(Inputs_Prices!Q38>Calculations_Price_Caps!Q70,"Fail","Pass") -> Pass | R40: =IF(Inputs_Prices!R38>Calculations_Price_Caps!R70,"Fail","Pass") -> Pass | S40: =IF(Inputs_Prices!S38>Calculations_Price_Caps!S70,"Fail","Pass") -> Pass
D41: Standard temporary builder’s connection | H41: Calculated | I41: $/Request | J41: Nominal | P41: =IF(Inputs_Prices!P39>Calculations_Price_Caps!P71,"Fail","Pass") -> Pass | Q41: =IF(Inputs_Prices!Q39>Calculations_Price_Caps!Q71,"Fail","Pass") -> Pass | R41: =IF(Inputs_Prices!R39>Calculations_Price_Caps!R71,"Fail","Pass") -> Pass | S41: =IF(Inputs_Prices!S39>Calculations_Price_Caps!S71,"Fail","Pass") -> Pass
D42: Temporary disconnection and reconnection - no dismantling | H42: Calculated | I42: $/Request | J42: Nominal | P42: =IF(Inputs_Prices!P40>Calculations_Price_Caps!P72,"Fail","Pass") -> Pass | Q42: =IF(Inputs_Prices!Q40>Calculations_Price_Caps!Q72,"Fail","Pass") -> Pass | R42: =IF(Inputs_Prices!R40>Calculations_Price_Caps!R72,"Fail","Pass") -> Pass | S42: =IF(Inputs_Prices!S40>Calculations_Price_Caps!S72,"Fail","Pass") -> Pass
D43: Complex disconnection | H43: Calculated | I43: $/Request | J43: Nominal | P43: =IF(Inputs_Prices!P41>Calculations_Price_Caps!P73,"Fail","Pass") -> Pass | Q43: =IF(Inputs_Prices!Q41>Calculations_Price_Caps!Q73,"Fail","Pass") -> Pass | R43: =IF(Inputs_Prices!R41>Calculations_Price_Caps!R73,"Fail","Pass") -> Pass | S43: =IF(Inputs_Prices!S41>Calculations_Price_Caps!S73,"Fail","Pass") -> Pass
D44: Wasted visit fee | H44: Calculated | I44: $/Request | J44: Nominal | P44: =IF(Inputs_Prices!P42>Calculations_Price_Caps!P74,"Fail","Pass") -> Pass | Q44: =IF(Inputs_Prices!Q42>Calculations_Price_Caps!Q74,"Fail","Pass") -> Pass | R44: =IF(Inputs_Prices!R42>Calculations_Price_Caps!R74,"Fail","Pass") -> Pass | S44: =IF(Inputs_Prices!S42>Calculations_Price_Caps!S74,"Fail","Pass") -> Pass
D45: Special meter test | H45: Calculated | I45: $/Request | J45: Nominal | P45: =IF(Inputs_Prices!P43>Calculations_Price_Caps!P75,"Fail","Pass") -> Pass | Q45: =IF(Inputs_Prices!Q43>Calculations_Price_Caps!Q75,"Fail","Pass") -> Pass | R45: =IF(Inputs_Prices!R43>Calculations_Price_Caps!R75,"Fail","Pass") -> Pass | S45: =IF(Inputs_Prices!S43>Calculations_Price_Caps!S75,"Fail","Pass") -> Pass
D46: Exchange or replace meter – three phase | H46: Calculated | I46: $/Request | J46: Nominal | P46: =IF(Inputs_Prices!P44>Calculations_Price_Caps!P76,"Fail","Pass") -> Pass | Q46: =IF(Inputs_Prices!Q44>Calculations_Price_Caps!Q76,"Fail","Pass") -> Pass | R46: =IF(Inputs_Prices!R44>Calculations_Price_Caps!R76,"Fail","Pass") -> Pass | S46: =IF(Inputs_Prices!S44>Calculations_Price_Caps!S76,"Fail","Pass") -> Pass
D47: Exchange or replace meter - single phase | H47: Calculated | I47: $/Request | J47: Nominal | P47: =IF(Inputs_Prices!P45>Calculations_Price_Caps!P77,"Fail","Pass") -> Pass | Q47: =IF(Inputs_Prices!Q45>Calculations_Price_Caps!Q77,"Fail","Pass") -> Pass | R47: =IF(Inputs_Prices!R45>Calculations_Price_Caps!R77,"Fail","Pass") -> Pass | S47: =IF(Inputs_Prices!S45>Calculations_Price_Caps!S77,"Fail","Pass") -> Pass
D48: Relocation of meter | H48: Calculated | I48: $/Request | J48: Nominal | P48: =IF(Inputs_Prices!P46>Calculations_Price_Caps!P78,"Fail","Pass") -> Pass | Q48: =IF(Inputs_Prices!Q46>Calculations_Price_Caps!Q78,"Fail","Pass") -> Pass | R48: =IF(Inputs_Prices!R46>Calculations_Price_Caps!R78,"Fail","Pass") -> Pass | S48: =IF(Inputs_Prices!S46>Calculations_Price_Caps!S78,"Fail","Pass") -> Pass
... D62: Class 1 & 2 PV service | H62: Calculated | I62: $/Request | J62: Nominal | P62: =IF(Inputs_Prices!P60>Calculations_Price_Caps!P92,"Fail","Pass") -> Pass | Q62: =IF(Inputs_Prices!Q60>Calculations_Price_Caps!Q92,"Fail","Pass") -> Pass | R62: =IF(Inputs_Prices!R60>Calculations_Price_Caps!R92,"Fail","Pass") -> Pass | S62: =IF(Inputs_Prices!S60>Calculations_Price_Caps!S92,"Fail","Pass") -> Pass
D64: Quoted Services | Labour Component
...

Sheet Output_Pricing_Proposal
A1: =IF(SUM($A23:$A152)>0,1,0) -> 0 | B1: Output - Pricing Proposal
B2: No Errors Found
B3: Go to Cover Sheet
B4: =Model_Name -> ACS Pricing Model - Power and Water Corporation
B6: Tariff Year
D8: This sheet outputs tables for the pricing proposal. The prices reflect the tariff year selected below.
D10: Tariff Year: | H10: FY21 | I10: ← Nominate year
D11: Days In Year: | H11: =INDEX(Lookup!$P$19:$S$19,MATCH($H$10,Lookup!$P$20:$S$20,0)) -> 365
B14: ACS pricing parameters
D16: Terms | E16: Input | F16: Source
D17: Inflation update | E17: =INDEX(Inputs_Prices!O139:S139,MATCH($H$10,Lookup!$O$20:$S$20,0)) -> 0.018404908 | F17: Consistent with AER prescribed method we have updated inflation forecasts for 2020-21 to reflect the December 2019 ABS updates. Note this is consistent with SCS.
D18: X-factor for metering services (Type 1 to 6) | E18: =INDEX(Inputs_Prices!P208:S208,MATCH($H$10,Lookup!$P$20:$S$20,0)) -> -0.0327 | F18: Consistent with AER final decision on page 21 of Attachment 15 (Table 15.7)
D19: X-factor re-connection, disconnection and final read | E19: =INDEX(Inputs_Prices!P213:S213,MATCH($H$10,Lookup!$P$20:$S$20,0)) -> 0.042045 | F19: Consistent with AER final decision on page 20 of Attachment 15 (Table 15.6)
D20: X-factor for all other services to apply to 2020-21 | E20: =INDEX(Inputs_Prices!P216:S216,MATCH($H$10,Lookup!$P$20:$S$20,0)) -> -0.005708 | F20: Consistent with AER final decision on page on page 20 of Attachment 15 (Table 15.6)
B23: ACS Metering Services Pricing Parameters
F25: Excluding GST
D26: Metering service provision charges (for Types 1 – 6 meters) | E26: Basis of charging | F26: Price | G26: Annual Charge
D27: 1 Phase Meters (including Prepayment) | E27: $/day/meter | F27: =G27/$H$11 -> 0.17715068 | G27: =INDEX(Inputs_Prices!P29:S29,MATCH($H$10,Lookup!$P$20:$S$20,0)) -> 64.66
D28: 3 Phase Meters | E28: $/day/meter | F28: =G28/$H$11 -> 0.1950411 | G28: =INDEX(Inputs_Prices!P30:S30,MATCH($H$10,Lookup!$P$20:$S$20,0)) -> 71.19
D29: Dedicated CT and VT meters | E29: $/day/meter | F29: =G29/$H$11 -> 0.33035616 | G29: =INDEX(Inputs_Prices!P31:S31,MATCH($H$10,Lookup!$P$20:$S$20,0)) -> 120.58 | H29: Note: Consistent with the process used for FY20 tariffs, the annual metering charges have been converted to daily charges by dividing them by the number of days in the year.
B32: ACS Quoted Services Pricing Parameters (Labour Component Only)
F34: Price | K34: GST Adjustment | L34: 1.1
D35: Quoted services provision charges | E35: Basis of charging | F35: Excluding GST | G35: Including GST
D36: {=LU_Quoted_Services} -> Design related services | E36: $/hour | F36: =INDEX(Inputs_Prices!$P63:$S63,MATCH($H$10,Lookup!$P$20:$S$20,0)) -> 159.39 | G36: =F36*$L$34 -> 175.329
D37: Connection applications | E37: $/hour | F37: =INDEX(Inputs_Prices!$P64:$S64,MATCH($H$10,Lookup!$P$20:$S$20,0)) -> 159.39 | G37: =F37*$L$34 -> 175.329
D38: Access permits, oversights and facilitation | E38: $/hour | F38: =INDEX(Inputs_Prices!$P65:$S65,MATCH($H$10,Lookup!$P$20:$S$20,0)) -> 159.39 | G38: =F38*$L$34 -> 175.329
D39: Notices of arrangement and completion notices | E39: $/hour | F39: =INDEX(Inputs_Prices!$P66:$S66,MATCH($H$10,Lookup!$P$20:$S$20,0)) -> 89.3 | G39: =F39*$L$34 -> 98.23
D40: Network related property services | E40: $/hour | F40: =INDEX(Inputs_Prices!$P67:$S67,MATCH($H$10,Lookup!$P$20:$S$20,0)) -> 89.3 | G40: =F40*$L$34 -> 98.23
D41: Site establishment services | E41: $/hour | F41: =INDEX(Inputs_Prices!$P68:$S68,MATCH($H$10,Lookup!$P$20:$S$20,0)) -> 89.3 | G41: =F41*$L$34 -> 98.23
D42: Network safety services | E42: $/hour | F42: =INDEX(Inputs_Prices!$P69:$S69,MATCH($H$10,Lookup!$P$20:$S$20,0)) -> 135.92 | G42: =F42*$L$34 -> 149.512
D43: Network tariff change request | E43: $/hour | F43: =INDEX(Inputs_Prices!$P70:$S70,MATCH($H$10,Lookup!$P$20:$S$20,0)) -> 89.3 | G43: =F43*$L$34 -> 98.23
D44: Planned interruption - customer request | E44: $/hour | F44: =INDEX(Inputs_Prices!$P71:$S71,MATCH($H$10,Lookup!$P$20:$S$20,0)) -> 135.92 | G44: =F44*$L$34 -> 149.512
D45: Performance of a statutory right (access prevented) | E45: $/hour | F45: =INDEX(Inputs_Prices!$P72:$S72,MATCH($H$10,Lookup!$P$20:$S$20,0)) -> 135.92 | G45: =F45*$L$34 -> 149.512
D46: Provision of network related training to third parties | E46: $/hour | F46: =INDEX(Inputs_Prices!$P73:$S73,MATCH($H$10,Lookup!$P$20:$S$20,0)) -> 89.3 | G46: =F46*$L$34 -> 98.23
D47: Non-standard reporting services | E47: $/hour | F47: =INDEX(Inputs_Prices!$P74:$S74,MATCH($H$10,Lookup!$P$20:$S$20,0)) -> 89.3 | G47: =F47*$L$34 -> 98.23
D48: Services provided for retailer of last resort event | E48: $/hour | F48: =INDEX(Inputs_Prices!$P75:$S75,MATCH($H$10,Lookup!$P$20:$S$20,0)) -> 89.3 | G48: =F48*$L$34 -> 98.23
... D51: Annual prepayment meter licensing fee * | E51: $/hour | F51: =INDEX(Inputs_Prices!$P78:$S78,MATCH($H$10,Lookup!$P$20:$S$20,0)) -> 89.3 | G51: =F51*$L$34 -> 98.23
D52: * Cost of Prepayment meter software will be on charged according to customer requirements. Admin rate to be used to process cost recovery.
B54: ACS Fee Based Services Pricing Parameters
F56: Price
...

Sheet Lookup
A1: =IF(SUM($A6:$A162)>0,1,0) -> 0 | B1: Model Lookups
B2: =Title_Msg -> No Errors Found
B3: =TOC!B1 -> Table of Contents
B4: =Model_Name -> ACS Pricing Model - Power and Water Corporation
B6: Model Settings
C8: Periodicity Inputs
D10: Model Start Date | E10: 41821
D11: Base Year | E11: 2018
C13: Time Series Headings
B15: Period Start Date | J15: =IF(J17=1,Model_Start_Date,I16+1) -> 41821 | K15: =IF(K17=1,Model_Start_Date,J16+1) -> 42186 | L15: =IF(L17=1,Model_Start_Date,K16+1) -> 42552 | M15: =IF(M17=1,Model_Start_Date,L16+1) -> 42917 | N15: =IF(N17=1,Model_Start_Date,M16+1) -> 43282 | O15: =IF(O17=1,Model_Start_Date,N16+1) -> 43647 | P15: =IF(P17=1,Model_Start_Date,O16+1) -> 44013 | Q15: =IF(Q17=1,Model_Start_Date,P16+1) -> 44378 | ... S15: =IF(S17=1,Model_Start_Date,R16+1) -> 45108
B16: Period End Date | J16: =EOMONTH(J15,Mths_In_Yr-1) -> 42185 | K16: =EOMONTH(K15,Mths_In_Yr-1) -> 42551 | L16: =EOMONTH(L15,Mths_In_Yr-1) -> 42916 | M16: =EOMONTH(M15,Mths_In_Yr-1) -> 43281 | N16: =EOMONTH(N15,Mths_In_Yr-1) -> 43646 | O16: =EOMONTH(O15,Mths_In_Yr-1) -> 44012 | P16: =EOMONTH(P15,Mths_In_Yr-1) -> 44377 | Q16: =EOMONTH(Q15,Mths_In_Yr-1) -> 44742 | ... S16: =EOMONTH(S15,Mths_In_Yr-1) -> 45473
B17: Period Counter | J17: =N(I17)+1 -> 1 | K17: =N(J17)+1 -> 2 | L17: =N(K17)+1 -> 3 | M17: =N(L17)+1 -> 4 | N17: =N(M17)+1 -> 5 | O17: =N(N17)+1 -> 6 | P17: =N(O17)+1 -> 7 | Q17: =N(P17)+1 -> 8 | ... S17: =N(R17)+1 -> 10
B18: Year | J18: =YEAR(J16) -> 2015 | K18: =YEAR(K16) -> 2016 | L18: =YEAR(L16) -> 2017 | M18: =YEAR(M16) -> 2018 | N18: =YEAR(N16) -> 2019 | O18: =YEAR(O16) -> 2020 | P18: =YEAR(P16) -> 2021 | Q18: =YEAR(Q16) -> 2022 | ... S18: =YEAR(S16) -> 2024
B19: Days In Year | J19: =J16-J15+1 -> 365 | K19: =K16-K15+1 -> 366 | L19: =L16-L15+1 -> 365 | M19: =M16-M15+1 -> 365 | N19: =N16-N15+1 -> 365 | O19: =O16-O15+1 -> 366 | P19: =P16-P15+1 -> 365 | Q19: =Q16-Q15+1 -> 365 | ... S19: =S16-S15+1 -> 366
B20: FY | E20: Source | F20: Unit | G20: Basis | H20: Timing | J20: ="FY"&RIGHT(J18,2) -> FY15 | K20: ="FY"&RIGHT(K18,2) -> FY16 | L20: ="FY"&RIGHT(L18,2) -> FY17 | M20: ="FY"&RIGHT(M18,2) -> FY18 | N20: ="FY"&RIGHT(N18,2) -> FY19 | O20: ="FY"&RIGHT(O18,2) -> FY20 | P20: ="FY"&RIGHT(P18,2) -> FY21 | Q20: ="FY"&RIGHT(Q18,2) -> FY22 | ... S20: ="FY"&RIGHT(S18,2) -> FY24
B22: Model Lookups
C24: General Model Constant | E24: Name
D26: 1 | E26: Mths_In_Mth
D27: 3 | E27: Mths_In_Qtr
D28: 4 | E28: Qtrs_In_Yr
D29: 12 | E29: Mths_In_Yr
D30: 7 | E30: Days_In_Wk
D31: 365 | E31: Days_In_Yr
D32: 0.5 | E32: Half
D33: 0.01 | E33: Cents_to_Dollars
D34: 0.001 | E34: Dollars_to_Thousands
D35: Ok | E35: Ok
D36: N/A | E36: NA
D37: Error | E37: Error
C39: General Model Constant | E39: Name
E40: Yes_No
D41: Yes | E41: Yes
D42: No | E42: No
C44: Units | E44: Name
E45: LU_Units
D46: Percent | E46: Percent
D47: Dollars | E47: Dollars
D48: $Millions | E48: Millions
D49: $000's | E49: Thousands
D50: Factor | E50: Factor
...

Sheet Checks
B1: Checks
B2: =Title_Msg -> No Errors Found
B3: =TOC!B1 -> Table of Contents
B4: =Model_Name -> ACS Pricing Model - Power and Water Corporation
B6: Model Title Message
D8: Error Message | H8: =IF(H21=0,"No Errors Found","Errors Found") -> No Errors Found
D9: Alert Message
D10: Model Message | H10: =H8&IF(H9="","",", " &H9) -> No Errors Found
B12: Model Checks
C14: Error Checks
D16: =Inputs_Prices!$B$1 -> Inputs - Prices | H16: =Inputs_Prices!$A$1 -> 0
D17: =Calculations_Price_Caps!$B$1 -> Calculation - Price Caps | H17: =Calculations_Price_Caps!$A$1 -> 0
D18: =Output_Compliance!$B$1 -> Output - Compliance | H18: =Output_Compliance!$A$1 -> 0
D19: =Output_Pricing_Proposal!$B$1 -> Output - Pricing Proposal | H19: =Output_Pricing_Proposal!$A$1 -> 0
C21: Total Errors | H21: =IF(SUM($H$16:$H$19)>0,1,0) -> 0
B23: End
